[Mon Sep 08 13:44:26.524204 2014] [:info] [pid 11596] [client 127.0.0.1:48682] mod_wsgi (pid=11596, process='', application='visched.local'): Loading WSGI script '/var/www/visched/app/visched.wsgi'.
[Mon Sep 08 13:44:26.593768 2014] [:error] [pid 11596] [client 127.0.0.1:48682] mod_wsgi (pid=11596): Target WSGI script '/var/www/visched/app/visched.wsgi' cannot be loaded as Python module.
[Mon Sep 08 13:44:26.593816 2014] [:error] [pid 11596] [client 127.0.0.1:48682] mod_wsgi (pid=11596): Exception occurred processing WSGI script '/var/www/visched/app/visched.wsgi'.
[Mon Sep 08 13:44:26.593835 2014] [:error] [pid 11596] [client 127.0.0.1:48682] Traceback (most recent call last):
[Mon Sep 08 13:44:26.593858 2014] [:error] [pid 11596] [client 127.0.0.1:48682]   File "/var/www/visched/app/visched.wsgi", line 5, in <module>
[Mon Sep 08 13:44:26.593921 2014] [:error] [pid 11596] [client 127.0.0.1:48682]     from beaker.middleware import SessionMiddleware
[Mon Sep 08 13:44:26.593937 2014] [:error] [pid 11596] [client 127.0.0.1:48682] ImportError: No module named beaker.middleware
[Mon Sep 08 13:47:42.806795 2014] [:info] [pid 11598] [client 127.0.0.1:48726] mod_wsgi (pid=11598, process='', application='visched.local'): Loading WSGI script '/var/www/visched/app/visched.wsgi'.
[Mon Sep 08 13:47:43.255232 2014] [:error] [pid 11598] [client 127.0.0.1:48726] mod_wsgi (pid=11598): Exception occurred processing WSGI script '/var/www/visched/app/visched.wsgi'.
[Mon Sep 08 13:47:43.255300 2014] [:error] [pid 11598] [client 127.0.0.1:48726] Traceback (most recent call last):
[Mon Sep 08 13:47:43.255323 2014] [:error] [pid 11598] [client 127.0.0.1:48726]   File "/var/www/visched/app/visched.wsgi", line 12, in application
[Mon Sep 08 13:47:43.255390 2014] [:error] [pid 11598] [client 127.0.0.1:48726]     from visched import config
[Mon Sep 08 13:47:43.255409 2014] [:error] [pid 11598] [client 127.0.0.1:48726] ImportError: No module named visched
[Mon Sep 08 14:00:10.937157 2014] [:info] [pid 18511] [client 127.0.0.1:48851] mod_wsgi (pid=18511, process='', application='visched.local'): Loading WSGI script '/var/www/visched/app/visched.wsgi'.
[Mon Sep 08 14:00:11.037290 2014] [:error] [pid 18511] [client 127.0.0.1:48851] mod_wsgi (pid=18511): Exception occurred processing WSGI script '/var/www/visched/app/visched.wsgi'.
[Mon Sep 08 14:00:11.037455 2014] [:error] [pid 18511] [client 127.0.0.1:48851] Traceback (most recent call last):
[Mon Sep 08 14:00:11.037537 2014] [:error] [pid 18511] [client 127.0.0.1:48851]   File "/var/www/visched/app/visched.wsgi", line 12, in application
[Mon Sep 08 14:00:11.037750 2014] [:error] [pid 18511] [client 127.0.0.1:48851]     from visched import config
[Mon Sep 08 14:00:11.037815 2014] [:error] [pid 18511] [client 127.0.0.1:48851] ImportError: No module named visched
[Mon Sep 08 14:06:51.999896 2014] [:info] [pid 18517] [client 127.0.0.1:48949] mod_wsgi (pid=18517, process='', application='visched.local'): Loading WSGI script '/var/www/visched/app/visched.wsgi'.
[Mon Sep 08 14:06:52.094835 2014] [:error] [pid 18517] [client 127.0.0.1:48949] mod_wsgi (pid=18517): Exception occurred processing WSGI script '/var/www/visched/app/visched.wsgi'.
[Mon Sep 08 14:06:52.094934 2014] [:error] [pid 18517] [client 127.0.0.1:48949] Traceback (most recent call last):
[Mon Sep 08 14:06:52.094965 2014] [:error] [pid 18517] [client 127.0.0.1:48949]   File "/var/www/visched/app/visched.wsgi", line 12, in application
[Mon Sep 08 14:06:52.095056 2014] [:error] [pid 18517] [client 127.0.0.1:48949]     from visched import config
[Mon Sep 08 14:06:52.095080 2014] [:error] [pid 18517] [client 127.0.0.1:48949] ImportError: No module named visched
[Mon Sep 08 14:08:43.133118 2014] [:info] [pid 18745] [client 127.0.0.1:48955] mod_wsgi (pid=18745, process='', application='visched.local'): Loading WSGI script '/var/www/visched/app/visched.wsgi'.
[Mon Sep 08 14:08:43.230900 2014] [:error] [pid 18745] [client 127.0.0.1:48955] mod_wsgi (pid=18745): Exception occurred processing WSGI script '/var/www/visched/app/visched.wsgi'.
[Mon Sep 08 14:08:43.231042 2014] [:error] [pid 18745] [client 127.0.0.1:48955] Traceback (most recent call last):
[Mon Sep 08 14:08:43.231140 2014] [:error] [pid 18745] [client 127.0.0.1:48955]   File "/var/www/visched/app/visched.wsgi", line 12, in application
[Mon Sep 08 14:08:43.231344 2014] [:error] [pid 18745] [client 127.0.0.1:48955]     from visched import config
[Mon Sep 08 14:08:43.231406 2014] [:error] [pid 18745] [client 127.0.0.1:48955] ImportError: No module named visched
[Mon Sep 08 14:39:12.579363 2014] [:info] [pid 18744] [client 127.0.0.1:49018] mod_wsgi (pid=18744, process='', application='visched.local'): Loading WSGI script '/var/www/visched/app/visched.wsgi'.
[Mon Sep 08 14:39:12.669232 2014] [:error] [pid 18744] [client 127.0.0.1:49018] mod_wsgi (pid=18744): Exception occurred processing WSGI script '/var/www/visched/app/visched.wsgi'.
[Mon Sep 08 14:39:12.669295 2014] [:error] [pid 18744] [client 127.0.0.1:49018] Traceback (most recent call last):
[Mon Sep 08 14:39:12.669318 2014] [:error] [pid 18744] [client 127.0.0.1:49018]   File "/var/www/visched/app/visched.wsgi", line 12, in application
[Mon Sep 08 14:39:12.669385 2014] [:error] [pid 18744] [client 127.0.0.1:49018]     from visched import config
[Mon Sep 08 14:39:12.669404 2014] [:error] [pid 18744] [client 127.0.0.1:49018] ImportError: No module named visched
[Mon Sep 08 14:45:17.128332 2014] [:info] [pid 19087] [client 127.0.0.1:49041] mod_wsgi (pid=19087, process='', application='visched.local'): Loading WSGI script '/var/www/visched/app/visched.wsgi'.
[Mon Sep 08 14:45:17.262525 2014] [:error] [pid 19087] [client 127.0.0.1:49041] mod_wsgi (pid=19087): Exception occurred processing WSGI script '/var/www/visched/app/visched.wsgi'.
[Mon Sep 08 14:45:17.262575 2014] [:error] [pid 19087] [client 127.0.0.1:49041] Traceback (most recent call last):
[Mon Sep 08 14:45:17.262605 2014] [:error] [pid 19087] [client 127.0.0.1:49041]   File "/var/www/visched/app/visched.wsgi", line 14, in application
[Mon Sep 08 14:45:17.262670 2014] [:error] [pid 19087] [client 127.0.0.1:49041]     import visched.page.handlers
[Mon Sep 08 14:45:17.262680 2014] [:error] [pid 19087] [client 127.0.0.1:49041]   File "/var/www/visched/app/visched/page/__init__.py", line 6, in <module>
[Mon Sep 08 14:45:17.262721 2014] [:error] [pid 19087] [client 127.0.0.1:49041]     from jinja2 import Environment, FileSystemLoader, Template
[Mon Sep 08 14:45:17.262742 2014] [:error] [pid 19087] [client 127.0.0.1:49041] ImportError: No module named jinja2
[Mon Sep 08 14:46:10.898293 2014] [:info] [pid 19168] [client 127.0.0.1:49042] mod_wsgi (pid=19168, process='', application='visched.local'): Loading WSGI script '/var/www/visched/app/visched.wsgi'.
[Mon Sep 08 14:46:11.009751 2014] [:error] [pid 19168] [client 127.0.0.1:49042] mod_wsgi (pid=19168): Exception occurred processing WSGI script '/var/www/visched/app/visched.wsgi'.
[Mon Sep 08 14:46:11.009997 2014] [:error] [pid 19168] [client 127.0.0.1:49042] Traceback (most recent call last):
[Mon Sep 08 14:46:11.010075 2014] [:error] [pid 19168] [client 127.0.0.1:49042]   File "/var/www/visched/app/visched.wsgi", line 14, in application
[Mon Sep 08 14:46:11.010311 2014] [:error] [pid 19168] [client 127.0.0.1:49042]     import visched.page.handlers
[Mon Sep 08 14:46:11.010354 2014] [:error] [pid 19168] [client 127.0.0.1:49042]   File "/var/www/visched/app/visched/page/__init__.py", line 6, in <module>
[Mon Sep 08 14:46:11.010494 2014] [:error] [pid 19168] [client 127.0.0.1:49042]     from jinja2 import Environment, FileSystemLoader, Template
[Mon Sep 08 14:46:11.010514 2014] [:error] [pid 19168] [client 127.0.0.1:49042] ImportError: No module named jinja2
[Mon Sep 08 14:47:34.146250 2014] [:info] [pid 19238] [client 127.0.0.1:49050] mod_wsgi (pid=19238, process='', application='visched.local'): Loading WSGI script '/var/www/visched/app/visched.wsgi'.
[Mon Sep 08 14:47:34.242454 2014] [:error] [pid 19238] [client 127.0.0.1:49050] mod_wsgi (pid=19238): Exception occurred processing WSGI script '/var/www/visched/app/visched.wsgi'.
[Mon Sep 08 14:47:34.242509 2014] [:error] [pid 19238] [client 127.0.0.1:49050] Traceback (most recent call last):
[Mon Sep 08 14:47:34.242545 2014] [:error] [pid 19238] [client 127.0.0.1:49050]   File "/var/www/visched/app/visched.wsgi", line 14, in application
[Mon Sep 08 14:47:34.242601 2014] [:error] [pid 19238] [client 127.0.0.1:49050]     import visched.page.handlers
[Mon Sep 08 14:47:34.242610 2014] [:error] [pid 19238] [client 127.0.0.1:49050]   File "/var/www/visched/app/visched/page/__init__.py", line 6, in <module>
[Mon Sep 08 14:47:34.242653 2014] [:error] [pid 19238] [client 127.0.0.1:49050]     from jinja2 import Environment, FileSystemLoader, Template
[Mon Sep 08 14:47:34.242671 2014] [:error] [pid 19238] [client 127.0.0.1:49050] ImportError: No module named jinja2
[Mon Sep 08 14:48:23.893973 2014] [:info] [pid 19239] [client 127.0.0.1:49059] mod_wsgi (pid=19239, process='', application='visched.local'): Loading WSGI script '/var/www/visched/app/visched.wsgi'.
[Mon Sep 08 14:48:24.140890 2014] [:error] [pid 19239] [client 127.0.0.1:49059] mod_wsgi (pid=19239): Exception occurred processing WSGI script '/var/www/visched/app/visched.wsgi'.
[Mon Sep 08 14:48:24.141140 2014] [:error] [pid 19239] [client 127.0.0.1:49059] Traceback (most recent call last):
[Mon Sep 08 14:48:24.141218 2014] [:error] [pid 19239] [client 127.0.0.1:49059]   File "/var/www/visched/app/visched.wsgi", line 14, in application
[Mon Sep 08 14:48:24.141421 2014] [:error] [pid 19239] [client 127.0.0.1:49059]     import visched.page.handlers
[Mon Sep 08 14:48:24.141461 2014] [:error] [pid 19239] [client 127.0.0.1:49059]   File "/var/www/visched/app/visched/page/__init__.py", line 8, in <module>
[Mon Sep 08 14:48:24.141628 2014] [:error] [pid 19239] [client 127.0.0.1:49059]     import visched.auth
[Mon Sep 08 14:48:24.141665 2014] [:error] [pid 19239] [client 127.0.0.1:49059]   File "/var/www/visched/app/visched/auth.py", line 6, in <module>
[Mon Sep 08 14:48:24.141865 2014] [:error] [pid 19239] [client 127.0.0.1:49059]     import sqlalchemy.orm.exc
[Mon Sep 08 14:48:24.141929 2014] [:error] [pid 19239] [client 127.0.0.1:49059] ImportError: No module named sqlalchemy.orm.exc
[Mon Sep 08 14:50:01.814049 2014] [:info] [pid 19247] [client 127.0.0.1:49076] mod_wsgi (pid=19247, process='', application='visched.local'): Loading WSGI script '/var/www/visched/app/visched.wsgi'.
[Mon Sep 08 14:50:02.101438 2014] [:error] [pid 19247] [client 127.0.0.1:49076] mod_wsgi (pid=19247): Exception occurred processing WSGI script '/var/www/visched/app/visched.wsgi'.
[Mon Sep 08 14:50:02.101538 2014] [:error] [pid 19247] [client 127.0.0.1:49076] Traceback (most recent call last):
[Mon Sep 08 14:50:02.101570 2014] [:error] [pid 19247] [client 127.0.0.1:49076]   File "/var/www/visched/app/visched.wsgi", line 14, in application
[Mon Sep 08 14:50:02.101651 2014] [:error] [pid 19247] [client 127.0.0.1:49076]     import visched.page.handlers
[Mon Sep 08 14:50:02.101662 2014] [:error] [pid 19247] [client 127.0.0.1:49076]   File "/var/www/visched/app/visched/page/__init__.py", line 8, in <module>
[Mon Sep 08 14:50:02.101712 2014] [:error] [pid 19247] [client 127.0.0.1:49076]     import visched.auth
[Mon Sep 08 14:50:02.101722 2014] [:error] [pid 19247] [client 127.0.0.1:49076]   File "/var/www/visched/app/visched/auth.py", line 9, in <module>
[Mon Sep 08 14:50:02.101784 2014] [:error] [pid 19247] [client 127.0.0.1:49076]     import visched.db
[Mon Sep 08 14:50:02.101793 2014] [:error] [pid 19247] [client 127.0.0.1:49076]   File "/var/www/visched/app/visched/db.py", line 17, in <module>
[Mon Sep 08 14:50:02.101822 2014] [:error] [pid 19247] [client 127.0.0.1:49076]     pool_recycle=config.getint('sqlalchemy', 'pool_recycle'))
[Mon Sep 08 14:50:02.101831 2014] [:error] [pid 19247] [client 127.0.0.1:49076]   File "/usr/local/lib/python2.7/dist-packages/sqlalchemy/engine/__init__.py", line 346, in create_engine
[Mon Sep 08 14:50:02.101944 2014] [:error] [pid 19247] [client 127.0.0.1:49076]     return strategy.create(*args, **kwargs)
[Mon Sep 08 14:50:02.101954 2014] [:error] [pid 19247] [client 127.0.0.1:49076]   File "/usr/local/lib/python2.7/dist-packages/sqlalchemy/engine/strategies.py", line 74, in create
[Mon Sep 08 14:50:02.102045 2014] [:error] [pid 19247] [client 127.0.0.1:49076]     dbapi = dialect_cls.dbapi(**dbapi_args)
[Mon Sep 08 14:50:02.102054 2014] [:error] [pid 19247] [client 127.0.0.1:49076]   File "/usr/local/lib/python2.7/dist-packages/sqlalchemy/connectors/mysqldb.py", line 64, in dbapi
[Mon Sep 08 14:50:02.102106 2014] [:error] [pid 19247] [client 127.0.0.1:49076]     return __import__('MySQLdb')
[Mon Sep 08 14:50:02.102122 2014] [:error] [pid 19247] [client 127.0.0.1:49076] ImportError: No module named MySQLdb
[Mon Sep 08 14:53:38.512462 2014] [:info] [pid 19246] [client 127.0.0.1:49180] mod_wsgi (pid=19246, process='', application='visched.local'): Loading WSGI script '/var/www/visched/app/visched.wsgi'.
[Mon Sep 08 14:53:38.853415 2014] [:error] [pid 19246] [client 127.0.0.1:49180] mod_wsgi (pid=19246): Exception occurred processing WSGI script '/var/www/visched/app/visched.wsgi'.
[Mon Sep 08 14:53:38.853547 2014] [:error] [pid 19246] [client 127.0.0.1:49180] Traceback (most recent call last):
[Mon Sep 08 14:53:38.853616 2014] [:error] [pid 19246] [client 127.0.0.1:49180]   File "/var/www/visched/app/visched.wsgi", line 14, in application
[Mon Sep 08 14:53:38.853804 2014] [:error] [pid 19246] [client 127.0.0.1:49180]     import visched.page.handlers
[Mon Sep 08 14:53:38.853844 2014] [:error] [pid 19246] [client 127.0.0.1:49180]   File "/var/www/visched/app/visched/page/handlers.py", line 6, in <module>
[Mon Sep 08 14:53:38.854122 2014] [:error] [pid 19246] [client 127.0.0.1:49180]     import visched.forms
[Mon Sep 08 14:53:38.854159 2014] [:error] [pid 19246] [client 127.0.0.1:49180]   File "/var/www/visched/app/visched/forms.py", line 1, in <module>
[Mon Sep 08 14:53:38.854346 2014] [:error] [pid 19246] [client 127.0.0.1:49180]     from wtforms import Form, TextField, PasswordField, validators, ValidationError
[Mon Sep 08 14:53:38.854414 2014] [:error] [pid 19246] [client 127.0.0.1:49180] ImportError: No module named wtforms
[Mon Sep 08 14:54:21.483910 2014] [:info] [pid 19243] [client 127.0.0.1:49185] mod_wsgi (pid=19243, process='', application='visched.local'): Loading WSGI script '/var/www/visched/app/visched.wsgi'.
[Mon Sep 08 14:54:21.772126 2014] [:error] [pid 19243] [client 127.0.0.1:49185] mod_wsgi (pid=19243): Exception occurred processing WSGI script '/var/www/visched/app/visched.wsgi'.
[Mon Sep 08 14:54:21.772284 2014] [:error] [pid 19243] [client 127.0.0.1:49185] Traceback (most recent call last):
[Mon Sep 08 14:54:21.772353 2014] [:error] [pid 19243] [client 127.0.0.1:49185]   File "/var/www/visched/app/visched.wsgi", line 14, in application
[Mon Sep 08 14:54:21.772576 2014] [:error] [pid 19243] [client 127.0.0.1:49185]     import visched.page.handlers
[Mon Sep 08 14:54:21.772616 2014] [:error] [pid 19243] [client 127.0.0.1:49185]   File "/var/www/visched/app/visched/page/handlers.py", line 7, in <module>
[Mon Sep 08 14:54:21.772914 2014] [:error] [pid 19243] [client 127.0.0.1:49185]     import visched.models
[Mon Sep 08 14:54:21.772953 2014] [:error] [pid 19243] [client 127.0.0.1:49185]   File "/var/www/visched/app/visched/models.py", line 797, in <module>
[Mon Sep 08 14:54:21.773683 2014] [:error] [pid 19243] [client 127.0.0.1:49185]     Base.prepare(visched.db.engine)
[Mon Sep 08 14:54:21.773722 2014] [:error] [pid 19243] [client 127.0.0.1:49185]   File "/usr/local/lib/python2.7/dist-packages/sqlalchemy/ext/declarative/api.py", line 478, in prepare
[Mon Sep 08 14:54:21.774256 2014] [:error] [pid 19243] [client 127.0.0.1:49185]     cls._sa_decl_prepare(thingy.local_table, engine)
[Mon Sep 08 14:54:21.774267 2014] [:error] [pid 19243] [client 127.0.0.1:49185]   File "/usr/local/lib/python2.7/dist-packages/sqlalchemy/ext/declarative/api.py", line 507, in _sa_decl_prepare
[Mon Sep 08 14:54:21.774282 2014] [:error] [pid 19243] [client 127.0.0.1:49185]     cls._reflect_table(local_table, engine)
[Mon Sep 08 14:54:21.774290 2014] [:error] [pid 19243] [client 127.0.0.1:49185]   File "/usr/local/lib/python2.7/dist-packages/sqlalchemy/ext/declarative/api.py", line 517, in _reflect_table
[Mon Sep 08 14:54:21.774314 2014] [:error] [pid 19243] [client 127.0.0.1:49185]     schema=table.schema)
[Mon Sep 08 14:54:21.774322 2014] [:error] [pid 19243] [client 127.0.0.1:49185]   File "/usr/local/lib/python2.7/dist-packages/sqlalchemy/sql/schema.py", line 344, in __new__
[Mon Sep 08 14:54:21.775031 2014] [:error] [pid 19243] [client 127.0.0.1:49185]     table._init_existing(*args, **kw)
[Mon Sep 08 14:54:21.775042 2014] [:error] [pid 19243] [client 127.0.0.1:49185]   File "/usr/local/lib/python2.7/dist-packages/sqlalchemy/sql/schema.py", line 494, in _init_existing
[Mon Sep 08 14:54:21.775057 2014] [:error] [pid 19243] [client 127.0.0.1:49185]     include_columns, exclude_columns)
[Mon Sep 08 14:54:21.775064 2014] [:error] [pid 19243] [client 127.0.0.1:49185]   File "/usr/local/lib/python2.7/dist-packages/sqlalchemy/sql/schema.py", line 439, in _autoload
[Mon Sep 08 14:54:21.775077 2014] [:error] [pid 19243] [client 127.0.0.1:49185]     self, include_columns, exclude_columns
[Mon Sep 08 14:54:21.775085 2014] [:error] [pid 19243] [client 127.0.0.1:49185]   File "/usr/local/lib/python2.7/dist-packages/sqlalchemy/engine/base.py", line 1732, in run_callable
[Mon Sep 08 14:54:21.775471 2014] [:error] [pid 19243] [client 127.0.0.1:49185]     with self.contextual_connect() as conn:
[Mon Sep 08 14:54:21.775481 2014] [:error] [pid 19243] [client 127.0.0.1:49185]   File "/usr/local/lib/python2.7/dist-packages/sqlalchemy/engine/base.py", line 1799, in contextual_connect
[Mon Sep 08 14:54:21.775494 2014] [:error] [pid 19243] [client 127.0.0.1:49185]     self.pool.connect(),
[Mon Sep 08 14:54:21.775502 2014] [:error] [pid 19243] [client 127.0.0.1:49185]   File "/usr/local/lib/python2.7/dist-packages/sqlalchemy/pool.py", line 338, in connect
[Mon Sep 08 14:54:21.775762 2014] [:error] [pid 19243] [client 127.0.0.1:49185]     return _ConnectionFairy._checkout(self)
[Mon Sep 08 14:54:21.775772 2014] [:error] [pid 19243] [client 127.0.0.1:49185]   File "/usr/local/lib/python2.7/dist-packages/sqlalchemy/pool.py", line 641, in _checkout
[Mon Sep 08 14:54:21.775786 2014] [:error] [pid 19243] [client 127.0.0.1:49185]     fairy = _ConnectionRecord.checkout(pool)
[Mon Sep 08 14:54:21.775794 2014] [:error] [pid 19243] [client 127.0.0.1:49185]   File "/usr/local/lib/python2.7/dist-packages/sqlalchemy/pool.py", line 440, in checkout
[Mon Sep 08 14:54:21.775806 2014] [:error] [pid 19243] [client 127.0.0.1:49185]     rec = pool._do_get()
[Mon Sep 08 14:54:21.775814 2014] [:error] [pid 19243] [client 127.0.0.1:49185]   File "/usr/local/lib/python2.7/dist-packages/sqlalchemy/pool.py", line 961, in _do_get
[Mon Sep 08 14:54:21.775825 2014] [:error] [pid 19243] [client 127.0.0.1:49185]     return self._create_connection()
[Mon Sep 08 14:54:21.775833 2014] [:error] [pid 19243] [client 127.0.0.1:49185]   File "/usr/local/lib/python2.7/dist-packages/sqlalchemy/pool.py", line 285, in _create_connection
[Mon Sep 08 14:54:21.775845 2014] [:error] [pid 19243] [client 127.0.0.1:49185]     return _ConnectionRecord(self)
[Mon Sep 08 14:54:21.775852 2014] [:error] [pid 19243] [client 127.0.0.1:49185]   File "/usr/local/lib/python2.7/dist-packages/sqlalchemy/pool.py", line 411, in __init__
[Mon Sep 08 14:54:21.775864 2014] [:error] [pid 19243] [client 127.0.0.1:49185]     self.connection = self.__connect()
[Mon Sep 08 14:54:21.775871 2014] [:error] [pid 19243] [client 127.0.0.1:49185]   File "/usr/local/lib/python2.7/dist-packages/sqlalchemy/pool.py", line 537, in __connect
[Mon Sep 08 14:54:21.775882 2014] [:error] [pid 19243] [client 127.0.0.1:49185]     connection = self.__pool._creator()
[Mon Sep 08 14:54:21.775890 2014] [:error] [pid 19243] [client 127.0.0.1:49185]   File "/usr/local/lib/python2.7/dist-packages/sqlalchemy/engine/strategies.py", line 96, in connect
[Mon Sep 08 14:54:21.775969 2014] [:error] [pid 19243] [client 127.0.0.1:49185]     connection_invalidated=invalidated
[Mon Sep 08 14:54:21.775978 2014] [:error] [pid 19243] [client 127.0.0.1:49185]   File "/usr/local/lib/python2.7/dist-packages/sqlalchemy/util/compat.py", line 199, in raise_from_cause
[Mon Sep 08 14:54:21.776046 2014] [:error] [pid 19243] [client 127.0.0.1:49185]     reraise(type(exception), exception, tb=exc_tb)
[Mon Sep 08 14:54:21.776055 2014] [:error] [pid 19243] [client 127.0.0.1:49185]   File "/usr/local/lib/python2.7/dist-packages/sqlalchemy/engine/strategies.py", line 90, in connect
[Mon Sep 08 14:54:21.776068 2014] [:error] [pid 19243] [client 127.0.0.1:49185]     return dialect.connect(*cargs, **cparams)
[Mon Sep 08 14:54:21.776076 2014] [:error] [pid 19243] [client 127.0.0.1:49185]   File "/usr/local/lib/python2.7/dist-packages/sqlalchemy/engine/default.py", line 377, in connect
[Mon Sep 08 14:54:21.776280 2014] [:error] [pid 19243] [client 127.0.0.1:49185]     return self.dbapi.connect(*cargs, **cparams)
[Mon Sep 08 14:54:21.776289 2014] [:error] [pid 19243] [client 127.0.0.1:49185]   File "/usr/lib/python2.7/dist-packages/MySQLdb/__init__.py", line 81, in Connect
[Mon Sep 08 14:54:21.776340 2014] [:error] [pid 19243] [client 127.0.0.1:49185]     return Connection(*args, **kwargs)
[Mon Sep 08 14:54:21.776350 2014] [:error] [pid 19243] [client 127.0.0.1:49185]   File "/usr/lib/python2.7/dist-packages/MySQLdb/connections.py", line 187, in __init__
[Mon Sep 08 14:54:21.776445 2014] [:error] [pid 19243] [client 127.0.0.1:49185]     super(Connection, self).__init__(*args, **kwargs2)
[Mon Sep 08 14:54:21.776506 2014] [:error] [pid 19243] [client 127.0.0.1:49185] OperationalError: (OperationalError) (1045, "Access denied for user 'visched'@'localhost' (using password: YES)") None None
[Mon Sep 08 15:05:54.763739 2014] [:info] [pid 19244] [client 127.0.0.1:49243] mod_wsgi (pid=19244, process='', application='visched.local'): Loading WSGI script '/var/www/visched/app/visched.wsgi'.
[Mon Sep 08 15:05:55.158155 2014] [:error] [pid 19244] [client 127.0.0.1:49243] mod_wsgi (pid=19244): Exception occurred processing WSGI script '/var/www/visched/app/visched.wsgi'.
[Mon Sep 08 15:05:55.158427 2014] [:error] [pid 19244] [client 127.0.0.1:49243] Traceback (most recent call last):
[Mon Sep 08 15:05:55.158497 2014] [:error] [pid 19244] [client 127.0.0.1:49243]   File "/var/www/visched/app/visched.wsgi", line 14, in application
[Mon Sep 08 15:05:55.158741 2014] [:error] [pid 19244] [client 127.0.0.1:49243]     import visched.page.handlers
[Mon Sep 08 15:05:55.158780 2014] [:error] [pid 19244] [client 127.0.0.1:49243]   File "/var/www/visched/app/visched/page/handlers.py", line 7, in <module>
[Mon Sep 08 15:05:55.159080 2014] [:error] [pid 19244] [client 127.0.0.1:49243]     import visched.models
[Mon Sep 08 15:05:55.159119 2014] [:error] [pid 19244] [client 127.0.0.1:49243]   File "/var/www/visched/app/visched/models.py", line 797, in <module>
[Mon Sep 08 15:05:55.159836 2014] [:error] [pid 19244] [client 127.0.0.1:49243]     Base.prepare(visched.db.engine)
[Mon Sep 08 15:05:55.159876 2014] [:error] [pid 19244] [client 127.0.0.1:49243]   File "/usr/local/lib/python2.7/dist-packages/sqlalchemy/ext/declarative/api.py", line 478, in prepare
[Mon Sep 08 15:05:55.160381 2014] [:error] [pid 19244] [client 127.0.0.1:49243]     cls._sa_decl_prepare(thingy.local_table, engine)
[Mon Sep 08 15:05:55.160420 2014] [:error] [pid 19244] [client 127.0.0.1:49243]   File "/usr/local/lib/python2.7/dist-packages/sqlalchemy/ext/declarative/api.py", line 507, in _sa_decl_prepare
[Mon Sep 08 15:05:55.160480 2014] [:error] [pid 19244] [client 127.0.0.1:49243]     cls._reflect_table(local_table, engine)
[Mon Sep 08 15:05:55.160513 2014] [:error] [pid 19244] [client 127.0.0.1:49243]   File "/usr/local/lib/python2.7/dist-packages/sqlalchemy/ext/declarative/api.py", line 517, in _reflect_table
[Mon Sep 08 15:05:55.160565 2014] [:error] [pid 19244] [client 127.0.0.1:49243]     schema=table.schema)
[Mon Sep 08 15:05:55.160598 2014] [:error] [pid 19244] [client 127.0.0.1:49243]   File "/usr/local/lib/python2.7/dist-packages/sqlalchemy/sql/schema.py", line 344, in __new__
[Mon Sep 08 15:05:55.163411 2014] [:error] [pid 19244] [client 127.0.0.1:49243]     table._init_existing(*args, **kw)
[Mon Sep 08 15:05:55.163482 2014] [:error] [pid 19244] [client 127.0.0.1:49243]   File "/usr/local/lib/python2.7/dist-packages/sqlalchemy/sql/schema.py", line 494, in _init_existing
[Mon Sep 08 15:05:55.163539 2014] [:error] [pid 19244] [client 127.0.0.1:49243]     include_columns, exclude_columns)
[Mon Sep 08 15:05:55.163571 2014] [:error] [pid 19244] [client 127.0.0.1:49243]   File "/usr/local/lib/python2.7/dist-packages/sqlalchemy/sql/schema.py", line 439, in _autoload
[Mon Sep 08 15:05:55.163620 2014] [:error] [pid 19244] [client 127.0.0.1:49243]     self, include_columns, exclude_columns
[Mon Sep 08 15:05:55.163652 2014] [:error] [pid 19244] [client 127.0.0.1:49243]   File "/usr/local/lib/python2.7/dist-packages/sqlalchemy/engine/base.py", line 1732, in run_callable
[Mon Sep 08 15:05:55.165204 2014] [:error] [pid 19244] [client 127.0.0.1:49243]     with self.contextual_connect() as conn:
[Mon Sep 08 15:05:55.165242 2014] [:error] [pid 19244] [client 127.0.0.1:49243]   File "/usr/local/lib/python2.7/dist-packages/sqlalchemy/engine/base.py", line 1799, in contextual_connect
[Mon Sep 08 15:05:55.165294 2014] [:error] [pid 19244] [client 127.0.0.1:49243]     self.pool.connect(),
[Mon Sep 08 15:05:55.165326 2014] [:error] [pid 19244] [client 127.0.0.1:49243]   File "/usr/local/lib/python2.7/dist-packages/sqlalchemy/pool.py", line 338, in connect
[Mon Sep 08 15:05:55.166419 2014] [:error] [pid 19244] [client 127.0.0.1:49243]     return _ConnectionFairy._checkout(self)
[Mon Sep 08 15:05:55.166460 2014] [:error] [pid 19244] [client 127.0.0.1:49243]   File "/usr/local/lib/python2.7/dist-packages/sqlalchemy/pool.py", line 641, in _checkout
[Mon Sep 08 15:05:55.166513 2014] [:error] [pid 19244] [client 127.0.0.1:49243]     fairy = _ConnectionRecord.checkout(pool)
[Mon Sep 08 15:05:55.166544 2014] [:error] [pid 19244] [client 127.0.0.1:49243]   File "/usr/local/lib/python2.7/dist-packages/sqlalchemy/pool.py", line 440, in checkout
[Mon Sep 08 15:05:55.166593 2014] [:error] [pid 19244] [client 127.0.0.1:49243]     rec = pool._do_get()
[Mon Sep 08 15:05:55.166623 2014] [:error] [pid 19244] [client 127.0.0.1:49243]   File "/usr/local/lib/python2.7/dist-packages/sqlalchemy/pool.py", line 961, in _do_get
[Mon Sep 08 15:05:55.166670 2014] [:error] [pid 19244] [client 127.0.0.1:49243]     return self._create_connection()
[Mon Sep 08 15:05:55.166701 2014] [:error] [pid 19244] [client 127.0.0.1:49243]   File "/usr/local/lib/python2.7/dist-packages/sqlalchemy/pool.py", line 285, in _create_connection
[Mon Sep 08 15:05:55.166748 2014] [:error] [pid 19244] [client 127.0.0.1:49243]     return _ConnectionRecord(self)
[Mon Sep 08 15:05:55.166778 2014] [:error] [pid 19244] [client 127.0.0.1:49243]   File "/usr/local/lib/python2.7/dist-packages/sqlalchemy/pool.py", line 411, in __init__
[Mon Sep 08 15:05:55.166825 2014] [:error] [pid 19244] [client 127.0.0.1:49243]     self.connection = self.__connect()
[Mon Sep 08 15:05:55.166855 2014] [:error] [pid 19244] [client 127.0.0.1:49243]   File "/usr/local/lib/python2.7/dist-packages/sqlalchemy/pool.py", line 537, in __connect
[Mon Sep 08 15:05:55.166901 2014] [:error] [pid 19244] [client 127.0.0.1:49243]     connection = self.__pool._creator()
[Mon Sep 08 15:05:55.166932 2014] [:error] [pid 19244] [client 127.0.0.1:49243]   File "/usr/local/lib/python2.7/dist-packages/sqlalchemy/engine/strategies.py", line 96, in connect
[Mon Sep 08 15:05:55.167238 2014] [:error] [pid 19244] [client 127.0.0.1:49243]     connection_invalidated=invalidated
[Mon Sep 08 15:05:55.167274 2014] [:error] [pid 19244] [client 127.0.0.1:49243]   File "/usr/local/lib/python2.7/dist-packages/sqlalchemy/util/compat.py", line 199, in raise_from_cause
[Mon Sep 08 15:05:55.167512 2014] [:error] [pid 19244] [client 127.0.0.1:49243]     reraise(type(exception), exception, tb=exc_tb)
[Mon Sep 08 15:05:55.167548 2014] [:error] [pid 19244] [client 127.0.0.1:49243]   File "/usr/local/lib/python2.7/dist-packages/sqlalchemy/engine/strategies.py", line 90, in connect
[Mon Sep 08 15:05:55.167599 2014] [:error] [pid 19244] [client 127.0.0.1:49243]     return dialect.connect(*cargs, **cparams)
[Mon Sep 08 15:05:55.167648 2014] [:error] [pid 19244] [client 127.0.0.1:49243]   File "/usr/local/lib/python2.7/dist-packages/sqlalchemy/engine/default.py", line 377, in connect
[Mon Sep 08 15:05:55.168532 2014] [:error] [pid 19244] [client 127.0.0.1:49243]     return self.dbapi.connect(*cargs, **cparams)
[Mon Sep 08 15:05:55.168573 2014] [:error] [pid 19244] [client 127.0.0.1:49243]   File "/usr/lib/python2.7/dist-packages/MySQLdb/__init__.py", line 81, in Connect
[Mon Sep 08 15:05:55.168779 2014] [:error] [pid 19244] [client 127.0.0.1:49243]     return Connection(*args, **kwargs)
[Mon Sep 08 15:05:55.168816 2014] [:error] [pid 19244] [client 127.0.0.1:49243]   File "/usr/lib/python2.7/dist-packages/MySQLdb/connections.py", line 187, in __init__
[Mon Sep 08 15:05:55.169189 2014] [:error] [pid 19244] [client 127.0.0.1:49243]     super(Connection, self).__init__(*args, **kwargs2)
[Mon Sep 08 15:05:55.169351 2014] [:error] [pid 19244] [client 127.0.0.1:49243] OperationalError: (OperationalError) (1045, "Access denied for user 'root'@'localhost' (using password: YES)") None None
[Mon Sep 08 15:06:30.045457 2014] [:error] [pid 19238] [client 127.0.0.1:49245] mod_wsgi (pid=19238): Exception occurred processing WSGI script '/var/www/visched/app/visched.wsgi'.
[Mon Sep 08 15:06:30.045559 2014] [:error] [pid 19238] [client 127.0.0.1:49245] Traceback (most recent call last):
[Mon Sep 08 15:06:30.045583 2014] [:error] [pid 19238] [client 127.0.0.1:49245]   File "/var/www/visched/app/visched.wsgi", line 14, in application
[Mon Sep 08 15:06:30.045613 2014] [:error] [pid 19238] [client 127.0.0.1:49245]     import visched.page.handlers
[Mon Sep 08 15:06:30.045622 2014] [:error] [pid 19238] [client 127.0.0.1:49245]   File "/var/www/visched/app/visched/page/handlers.py", line 7, in <module>
[Mon Sep 08 15:06:30.045736 2014] [:error] [pid 19238] [client 127.0.0.1:49245]     import visched.models
[Mon Sep 08 15:06:30.045746 2014] [:error] [pid 19238] [client 127.0.0.1:49245]   File "/var/www/visched/app/visched/models.py", line 797, in <module>
[Mon Sep 08 15:06:30.045933 2014] [:error] [pid 19238] [client 127.0.0.1:49245]     Base.prepare(visched.db.engine)
[Mon Sep 08 15:06:30.045943 2014] [:error] [pid 19238] [client 127.0.0.1:49245]   File "/usr/local/lib/python2.7/dist-packages/sqlalchemy/ext/declarative/api.py", line 478, in prepare
[Mon Sep 08 15:06:30.046077 2014] [:error] [pid 19238] [client 127.0.0.1:49245]     cls._sa_decl_prepare(thingy.local_table, engine)
[Mon Sep 08 15:06:30.046086 2014] [:error] [pid 19238] [client 127.0.0.1:49245]   File "/usr/local/lib/python2.7/dist-packages/sqlalchemy/ext/declarative/api.py", line 507, in _sa_decl_prepare
[Mon Sep 08 15:06:30.046100 2014] [:error] [pid 19238] [client 127.0.0.1:49245]     cls._reflect_table(local_table, engine)
[Mon Sep 08 15:06:30.046108 2014] [:error] [pid 19238] [client 127.0.0.1:49245]   File "/usr/local/lib/python2.7/dist-packages/sqlalchemy/ext/declarative/api.py", line 517, in _reflect_table
[Mon Sep 08 15:06:30.046120 2014] [:error] [pid 19238] [client 127.0.0.1:49245]     schema=table.schema)
[Mon Sep 08 15:06:30.046128 2014] [:error] [pid 19238] [client 127.0.0.1:49245]   File "/usr/local/lib/python2.7/dist-packages/sqlalchemy/sql/schema.py", line 344, in __new__
[Mon Sep 08 15:06:30.046860 2014] [:error] [pid 19238] [client 127.0.0.1:49245]     table._init_existing(*args, **kw)
[Mon Sep 08 15:06:30.046872 2014] [:error] [pid 19238] [client 127.0.0.1:49245]   File "/usr/local/lib/python2.7/dist-packages/sqlalchemy/sql/schema.py", line 494, in _init_existing
[Mon Sep 08 15:06:30.046887 2014] [:error] [pid 19238] [client 127.0.0.1:49245]     include_columns, exclude_columns)
[Mon Sep 08 15:06:30.046895 2014] [:error] [pid 19238] [client 127.0.0.1:49245]   File "/usr/local/lib/python2.7/dist-packages/sqlalchemy/sql/schema.py", line 439, in _autoload
[Mon Sep 08 15:06:30.046908 2014] [:error] [pid 19238] [client 127.0.0.1:49245]     self, include_columns, exclude_columns
[Mon Sep 08 15:06:30.046928 2014] [:error] [pid 19238] [client 127.0.0.1:49245]   File "/usr/local/lib/python2.7/dist-packages/sqlalchemy/engine/base.py", line 1732, in run_callable
[Mon Sep 08 15:06:30.047332 2014] [:error] [pid 19238] [client 127.0.0.1:49245]     with self.contextual_connect() as conn:
[Mon Sep 08 15:06:30.047343 2014] [:error] [pid 19238] [client 127.0.0.1:49245]   File "/usr/local/lib/python2.7/dist-packages/sqlalchemy/engine/base.py", line 1799, in contextual_connect
[Mon Sep 08 15:06:30.047357 2014] [:error] [pid 19238] [client 127.0.0.1:49245]     self.pool.connect(),
[Mon Sep 08 15:06:30.047365 2014] [:error] [pid 19238] [client 127.0.0.1:49245]   File "/usr/local/lib/python2.7/dist-packages/sqlalchemy/pool.py", line 338, in connect
[Mon Sep 08 15:06:30.047631 2014] [:error] [pid 19238] [client 127.0.0.1:49245]     return _ConnectionFairy._checkout(self)
[Mon Sep 08 15:06:30.047642 2014] [:error] [pid 19238] [client 127.0.0.1:49245]   File "/usr/local/lib/python2.7/dist-packages/sqlalchemy/pool.py", line 641, in _checkout
[Mon Sep 08 15:06:30.047655 2014] [:error] [pid 19238] [client 127.0.0.1:49245]     fairy = _ConnectionRecord.checkout(pool)
[Mon Sep 08 15:06:30.047663 2014] [:error] [pid 19238] [client 127.0.0.1:49245]   File "/usr/local/lib/python2.7/dist-packages/sqlalchemy/pool.py", line 440, in checkout
[Mon Sep 08 15:06:30.047674 2014] [:error] [pid 19238] [client 127.0.0.1:49245]     rec = pool._do_get()
[Mon Sep 08 15:06:30.047683 2014] [:error] [pid 19238] [client 127.0.0.1:49245]   File "/usr/local/lib/python2.7/dist-packages/sqlalchemy/pool.py", line 961, in _do_get
[Mon Sep 08 15:06:30.047694 2014] [:error] [pid 19238] [client 127.0.0.1:49245]     return self._create_connection()
[Mon Sep 08 15:06:30.047702 2014] [:error] [pid 19238] [client 127.0.0.1:49245]   File "/usr/local/lib/python2.7/dist-packages/sqlalchemy/pool.py", line 285, in _create_connection
[Mon Sep 08 15:06:30.047713 2014] [:error] [pid 19238] [client 127.0.0.1:49245]     return _ConnectionRecord(self)
[Mon Sep 08 15:06:30.047720 2014] [:error] [pid 19238] [client 127.0.0.1:49245]   File "/usr/local/lib/python2.7/dist-packages/sqlalchemy/pool.py", line 411, in __init__
[Mon Sep 08 15:06:30.047731 2014] [:error] [pid 19238] [client 127.0.0.1:49245]     self.connection = self.__connect()
[Mon Sep 08 15:06:30.047739 2014] [:error] [pid 19238] [client 127.0.0.1:49245]   File "/usr/local/lib/python2.7/dist-packages/sqlalchemy/pool.py", line 537, in __connect
[Mon Sep 08 15:06:30.047750 2014] [:error] [pid 19238] [client 127.0.0.1:49245]     connection = self.__pool._creator()
[Mon Sep 08 15:06:30.047758 2014] [:error] [pid 19238] [client 127.0.0.1:49245]   File "/usr/local/lib/python2.7/dist-packages/sqlalchemy/engine/strategies.py", line 96, in connect
[Mon Sep 08 15:06:30.047839 2014] [:error] [pid 19238] [client 127.0.0.1:49245]     connection_invalidated=invalidated
[Mon Sep 08 15:06:30.047848 2014] [:error] [pid 19238] [client 127.0.0.1:49245]   File "/usr/local/lib/python2.7/dist-packages/sqlalchemy/util/compat.py", line 199, in raise_from_cause
[Mon Sep 08 15:06:30.047911 2014] [:error] [pid 19238] [client 127.0.0.1:49245]     reraise(type(exception), exception, tb=exc_tb)
[Mon Sep 08 15:06:30.047920 2014] [:error] [pid 19238] [client 127.0.0.1:49245]   File "/usr/local/lib/python2.7/dist-packages/sqlalchemy/engine/strategies.py", line 90, in connect
[Mon Sep 08 15:06:30.047933 2014] [:error] [pid 19238] [client 127.0.0.1:49245]     return dialect.connect(*cargs, **cparams)
[Mon Sep 08 15:06:30.047940 2014] [:error] [pid 19238] [client 127.0.0.1:49245]   File "/usr/local/lib/python2.7/dist-packages/sqlalchemy/engine/default.py", line 377, in connect
[Mon Sep 08 15:06:30.048152 2014] [:error] [pid 19238] [client 127.0.0.1:49245]     return self.dbapi.connect(*cargs, **cparams)
[Mon Sep 08 15:06:30.048161 2014] [:error] [pid 19238] [client 127.0.0.1:49245]   File "/usr/lib/python2.7/dist-packages/MySQLdb/__init__.py", line 81, in Connect
[Mon Sep 08 15:06:30.048212 2014] [:error] [pid 19238] [client 127.0.0.1:49245]     return Connection(*args, **kwargs)
[Mon Sep 08 15:06:30.048226 2014] [:error] [pid 19238] [client 127.0.0.1:49245]   File "/usr/lib/python2.7/dist-packages/MySQLdb/connections.py", line 187, in __init__
[Mon Sep 08 15:06:30.048324 2014] [:error] [pid 19238] [client 127.0.0.1:49245]     super(Connection, self).__init__(*args, **kwargs2)
[Mon Sep 08 15:06:30.048389 2014] [:error] [pid 19238] [client 127.0.0.1:49245] OperationalError: (OperationalError) (1045, "Access denied for user 'visched'@'localhost' (using password: YES)") None None
[Mon Sep 08 15:07:25.646636 2014] [:info] [pid 20037] [client 127.0.0.1:49248] mod_wsgi (pid=20037, process='', application='visched.local'): Loading WSGI script '/var/www/visched/app/visched.wsgi'.
[Mon Sep 08 15:07:25.859738 2014] [:error] [pid 20037] [client 127.0.0.1:49248] mod_wsgi (pid=20037): Exception occurred processing WSGI script '/var/www/visched/app/visched.wsgi'.
[Mon Sep 08 15:07:25.859802 2014] [:error] [pid 20037] [client 127.0.0.1:49248] Traceback (most recent call last):
[Mon Sep 08 15:07:25.859826 2014] [:error] [pid 20037] [client 127.0.0.1:49248]   File "/var/www/visched/app/visched.wsgi", line 14, in application
[Mon Sep 08 15:07:25.859906 2014] [:error] [pid 20037] [client 127.0.0.1:49248]     import visched.page.handlers
[Mon Sep 08 15:07:25.859916 2014] [:error] [pid 20037] [client 127.0.0.1:49248]   File "/var/www/visched/app/visched/page/__init__.py", line 8, in <module>
[Mon Sep 08 15:07:25.859958 2014] [:error] [pid 20037] [client 127.0.0.1:49248]     import visched.auth
[Mon Sep 08 15:07:25.859967 2014] [:error] [pid 20037] [client 127.0.0.1:49248]   File "/var/www/visched/app/visched/auth.py", line 9, in <module>
[Mon Sep 08 15:07:25.860022 2014] [:error] [pid 20037] [client 127.0.0.1:49248]     import visched.db
[Mon Sep 08 15:07:25.860031 2014] [:error] [pid 20037] [client 127.0.0.1:49248]   File "/var/www/visched/app/visched/db.py", line 10, in <module>
[Mon Sep 08 15:07:25.860062 2014] [:error] [pid 20037] [client 127.0.0.1:49248]     config.get('mysql', 'password'), \\
[Mon Sep 08 15:07:25.860070 2014] [:error] [pid 20037] [client 127.0.0.1:49248]   File "/usr/lib/python2.7/ConfigParser.py", line 618, in get
[Mon Sep 08 15:07:25.892583 2014] [:error] [pid 20037] [client 127.0.0.1:49248]     raise NoOptionError(option, section)
[Mon Sep 08 15:07:25.892739 2014] [:error] [pid 20037] [client 127.0.0.1:49248] NoOptionError: No option 'password' in section: 'mysql'
[Mon Sep 08 15:09:17.893900 2014] [:info] [pid 20038] [client 127.0.0.1:49250] mod_wsgi (pid=20038, process='', application='visched.local'): Loading WSGI script '/var/www/visched/app/visched.wsgi'.
[Mon Sep 08 15:09:18.100124 2014] [:error] [pid 20038] [client 127.0.0.1:49250] mod_wsgi (pid=20038): Exception occurred processing WSGI script '/var/www/visched/app/visched.wsgi'.
[Mon Sep 08 15:09:18.100201 2014] [:error] [pid 20038] [client 127.0.0.1:49250] Traceback (most recent call last):
[Mon Sep 08 15:09:18.100223 2014] [:error] [pid 20038] [client 127.0.0.1:49250]   File "/var/www/visched/app/visched.wsgi", line 14, in application
[Mon Sep 08 15:09:18.100278 2014] [:error] [pid 20038] [client 127.0.0.1:49250]     import visched.page.handlers
[Mon Sep 08 15:09:18.100288 2014] [:error] [pid 20038] [client 127.0.0.1:49250]   File "/var/www/visched/app/visched/page/__init__.py", line 8, in <module>
[Mon Sep 08 15:09:18.100330 2014] [:error] [pid 20038] [client 127.0.0.1:49250]     import visched.auth
[Mon Sep 08 15:09:18.100339 2014] [:error] [pid 20038] [client 127.0.0.1:49250]   File "/var/www/visched/app/visched/auth.py", line 9, in <module>
[Mon Sep 08 15:09:18.100394 2014] [:error] [pid 20038] [client 127.0.0.1:49250]     import visched.db
[Mon Sep 08 15:09:18.100403 2014] [:error] [pid 20038] [client 127.0.0.1:49250]   File "/var/www/visched/app/visched/db.py", line 10, in <module>
[Mon Sep 08 15:09:18.100434 2014] [:error] [pid 20038] [client 127.0.0.1:49250]     config.get('mysql', 'password'), \\
[Mon Sep 08 15:09:18.100443 2014] [:error] [pid 20038] [client 127.0.0.1:49250]   File "/usr/lib/python2.7/ConfigParser.py", line 618, in get
[Mon Sep 08 15:09:18.100642 2014] [:error] [pid 20038] [client 127.0.0.1:49250]     raise NoOptionError(option, section)
[Mon Sep 08 15:09:18.100663 2014] [:error] [pid 20038] [client 127.0.0.1:49250] NoOptionError: No option 'password' in section: 'mysql'
[Mon Sep 08 15:09:42.843918 2014] [:info] [pid 20039] [client 127.0.0.1:49252] mod_wsgi (pid=20039, process='', application='visched.local'): Loading WSGI script '/var/www/visched/app/visched.wsgi'.
[Mon Sep 08 15:09:43.097255 2014] [:error] [pid 20039] [client 127.0.0.1:49252] mod_wsgi (pid=20039): Exception occurred processing WSGI script '/var/www/visched/app/visched.wsgi'.
[Mon Sep 08 15:09:43.097508 2014] [:error] [pid 20039] [client 127.0.0.1:49252] Traceback (most recent call last):
[Mon Sep 08 15:09:43.097577 2014] [:error] [pid 20039] [client 127.0.0.1:49252]   File "/var/www/visched/app/visched.wsgi", line 14, in application
[Mon Sep 08 15:09:43.097824 2014] [:error] [pid 20039] [client 127.0.0.1:49252]     import visched.page.handlers
[Mon Sep 08 15:09:43.097864 2014] [:error] [pid 20039] [client 127.0.0.1:49252]   File "/var/www/visched/app/visched/page/handlers.py", line 7, in <module>
[Mon Sep 08 15:09:43.098171 2014] [:error] [pid 20039] [client 127.0.0.1:49252]     import visched.models
[Mon Sep 08 15:09:43.098238 2014] [:error] [pid 20039] [client 127.0.0.1:49252]   File "/var/www/visched/app/visched/models.py", line 797, in <module>
[Mon Sep 08 15:09:43.098456 2014] [:error] [pid 20039] [client 127.0.0.1:49252]     Base.prepare(visched.db.engine)
[Mon Sep 08 15:09:43.098466 2014] [:error] [pid 20039] [client 127.0.0.1:49252]   File "/usr/local/lib/python2.7/dist-packages/sqlalchemy/ext/declarative/api.py", line 478, in prepare
[Mon Sep 08 15:09:43.098614 2014] [:error] [pid 20039] [client 127.0.0.1:49252]     cls._sa_decl_prepare(thingy.local_table, engine)
[Mon Sep 08 15:09:43.098624 2014] [:error] [pid 20039] [client 127.0.0.1:49252]   File "/usr/local/lib/python2.7/dist-packages/sqlalchemy/ext/declarative/api.py", line 507, in _sa_decl_prepare
[Mon Sep 08 15:09:43.098642 2014] [:error] [pid 20039] [client 127.0.0.1:49252]     cls._reflect_table(local_table, engine)
[Mon Sep 08 15:09:43.098650 2014] [:error] [pid 20039] [client 127.0.0.1:49252]   File "/usr/local/lib/python2.7/dist-packages/sqlalchemy/ext/declarative/api.py", line 517, in _reflect_table
[Mon Sep 08 15:09:43.098664 2014] [:error] [pid 20039] [client 127.0.0.1:49252]     schema=table.schema)
[Mon Sep 08 15:09:43.098672 2014] [:error] [pid 20039] [client 127.0.0.1:49252]   File "/usr/local/lib/python2.7/dist-packages/sqlalchemy/sql/schema.py", line 344, in __new__
[Mon Sep 08 15:09:43.099458 2014] [:error] [pid 20039] [client 127.0.0.1:49252]     table._init_existing(*args, **kw)
[Mon Sep 08 15:09:43.099470 2014] [:error] [pid 20039] [client 127.0.0.1:49252]   File "/usr/local/lib/python2.7/dist-packages/sqlalchemy/sql/schema.py", line 494, in _init_existing
[Mon Sep 08 15:09:43.099486 2014] [:error] [pid 20039] [client 127.0.0.1:49252]     include_columns, exclude_columns)
[Mon Sep 08 15:09:43.099494 2014] [:error] [pid 20039] [client 127.0.0.1:49252]   File "/usr/local/lib/python2.7/dist-packages/sqlalchemy/sql/schema.py", line 439, in _autoload
[Mon Sep 08 15:09:43.099507 2014] [:error] [pid 20039] [client 127.0.0.1:49252]     self, include_columns, exclude_columns
[Mon Sep 08 15:09:43.099515 2014] [:error] [pid 20039] [client 127.0.0.1:49252]   File "/usr/local/lib/python2.7/dist-packages/sqlalchemy/engine/base.py", line 1732, in run_callable
[Mon Sep 08 15:09:43.099940 2014] [:error] [pid 20039] [client 127.0.0.1:49252]     with self.contextual_connect() as conn:
[Mon Sep 08 15:09:43.099952 2014] [:error] [pid 20039] [client 127.0.0.1:49252]   File "/usr/local/lib/python2.7/dist-packages/sqlalchemy/engine/base.py", line 1799, in contextual_connect
[Mon Sep 08 15:09:43.099986 2014] [:error] [pid 20039] [client 127.0.0.1:49252]     self.pool.connect(),
[Mon Sep 08 15:09:43.099997 2014] [:error] [pid 20039] [client 127.0.0.1:49252]   File "/usr/local/lib/python2.7/dist-packages/sqlalchemy/pool.py", line 338, in connect
[Mon Sep 08 15:09:43.100313 2014] [:error] [pid 20039] [client 127.0.0.1:49252]     return _ConnectionFairy._checkout(self)
[Mon Sep 08 15:09:43.100324 2014] [:error] [pid 20039] [client 127.0.0.1:49252]   File "/usr/local/lib/python2.7/dist-packages/sqlalchemy/pool.py", line 641, in _checkout
[Mon Sep 08 15:09:43.100339 2014] [:error] [pid 20039] [client 127.0.0.1:49252]     fairy = _ConnectionRecord.checkout(pool)
[Mon Sep 08 15:09:43.100347 2014] [:error] [pid 20039] [client 127.0.0.1:49252]   File "/usr/local/lib/python2.7/dist-packages/sqlalchemy/pool.py", line 440, in checkout
[Mon Sep 08 15:09:43.100359 2014] [:error] [pid 20039] [client 127.0.0.1:49252]     rec = pool._do_get()
[Mon Sep 08 15:09:43.100368 2014] [:error] [pid 20039] [client 127.0.0.1:49252]   File "/usr/local/lib/python2.7/dist-packages/sqlalchemy/pool.py", line 961, in _do_get
[Mon Sep 08 15:09:43.100380 2014] [:error] [pid 20039] [client 127.0.0.1:49252]     return self._create_connection()
[Mon Sep 08 15:09:43.100388 2014] [:error] [pid 20039] [client 127.0.0.1:49252]   File "/usr/local/lib/python2.7/dist-packages/sqlalchemy/pool.py", line 285, in _create_connection
[Mon Sep 08 15:09:43.100400 2014] [:error] [pid 20039] [client 127.0.0.1:49252]     return _ConnectionRecord(self)
[Mon Sep 08 15:09:43.100409 2014] [:error] [pid 20039] [client 127.0.0.1:49252]   File "/usr/local/lib/python2.7/dist-packages/sqlalchemy/pool.py", line 411, in __init__
[Mon Sep 08 15:09:43.100420 2014] [:error] [pid 20039] [client 127.0.0.1:49252]     self.connection = self.__connect()
[Mon Sep 08 15:09:43.100429 2014] [:error] [pid 20039] [client 127.0.0.1:49252]   File "/usr/local/lib/python2.7/dist-packages/sqlalchemy/pool.py", line 537, in __connect
[Mon Sep 08 15:09:43.100440 2014] [:error] [pid 20039] [client 127.0.0.1:49252]     connection = self.__pool._creator()
[Mon Sep 08 15:09:43.100448 2014] [:error] [pid 20039] [client 127.0.0.1:49252]   File "/usr/local/lib/python2.7/dist-packages/sqlalchemy/engine/strategies.py", line 96, in connect
[Mon Sep 08 15:09:43.100543 2014] [:error] [pid 20039] [client 127.0.0.1:49252]     connection_invalidated=invalidated
[Mon Sep 08 15:09:43.100553 2014] [:error] [pid 20039] [client 127.0.0.1:49252]   File "/usr/local/lib/python2.7/dist-packages/sqlalchemy/util/compat.py", line 199, in raise_from_cause
[Mon Sep 08 15:09:43.100619 2014] [:error] [pid 20039] [client 127.0.0.1:49252]     reraise(type(exception), exception, tb=exc_tb)
[Mon Sep 08 15:09:43.100628 2014] [:error] [pid 20039] [client 127.0.0.1:49252]   File "/usr/local/lib/python2.7/dist-packages/sqlalchemy/engine/strategies.py", line 90, in connect
[Mon Sep 08 15:09:43.100642 2014] [:error] [pid 20039] [client 127.0.0.1:49252]     return dialect.connect(*cargs, **cparams)
[Mon Sep 08 15:09:43.100651 2014] [:error] [pid 20039] [client 127.0.0.1:49252]   File "/usr/local/lib/python2.7/dist-packages/sqlalchemy/engine/default.py", line 377, in connect
[Mon Sep 08 15:09:43.100881 2014] [:error] [pid 20039] [client 127.0.0.1:49252]     return self.dbapi.connect(*cargs, **cparams)
[Mon Sep 08 15:09:43.100892 2014] [:error] [pid 20039] [client 127.0.0.1:49252]   File "/usr/lib/python2.7/dist-packages/MySQLdb/__init__.py", line 81, in Connect
[Mon Sep 08 15:09:43.100950 2014] [:error] [pid 20039] [client 127.0.0.1:49252]     return Connection(*args, **kwargs)
[Mon Sep 08 15:09:43.100960 2014] [:error] [pid 20039] [client 127.0.0.1:49252]   File "/usr/lib/python2.7/dist-packages/MySQLdb/connections.py", line 187, in __init__
[Mon Sep 08 15:09:43.101064 2014] [:error] [pid 20039] [client 127.0.0.1:49252]     super(Connection, self).__init__(*args, **kwargs2)
[Mon Sep 08 15:09:43.101148 2014] [:error] [pid 20039] [client 127.0.0.1:49252] OperationalError: (OperationalError) (1045, "Access denied for user 'root'@'localhost' (using password: YES)") None None
[Mon Sep 08 15:11:11.845739 2014] [:info] [pid 20205] [client 127.0.0.1:49255] mod_wsgi (pid=20205, process='', application='visched.local'): Loading WSGI script '/var/www/visched/app/visched.wsgi'.
[Mon Sep 08 15:11:12.060374 2014] [:error] [pid 20205] [client 127.0.0.1:49255] mod_wsgi (pid=20205): Exception occurred processing WSGI script '/var/www/visched/app/visched.wsgi'.
[Mon Sep 08 15:11:12.060449 2014] [:error] [pid 20205] [client 127.0.0.1:49255] Traceback (most recent call last):
[Mon Sep 08 15:11:12.060474 2014] [:error] [pid 20205] [client 127.0.0.1:49255]   File "/var/www/visched/app/visched.wsgi", line 14, in application
[Mon Sep 08 15:11:12.060531 2014] [:error] [pid 20205] [client 127.0.0.1:49255]     import visched.page.handlers
[Mon Sep 08 15:11:12.060541 2014] [:error] [pid 20205] [client 127.0.0.1:49255]   File "/var/www/visched/app/visched/page/__init__.py", line 8, in <module>
[Mon Sep 08 15:11:12.060583 2014] [:error] [pid 20205] [client 127.0.0.1:49255]     import visched.auth
[Mon Sep 08 15:11:12.060592 2014] [:error] [pid 20205] [client 127.0.0.1:49255]   File "/var/www/visched/app/visched/auth.py", line 9, in <module>
[Mon Sep 08 15:11:12.060649 2014] [:error] [pid 20205] [client 127.0.0.1:49255]     import visched.db
[Mon Sep 08 15:11:12.060657 2014] [:error] [pid 20205] [client 127.0.0.1:49255]   File "/var/www/visched/app/visched/db.py", line 10, in <module>
[Mon Sep 08 15:11:12.060688 2014] [:error] [pid 20205] [client 127.0.0.1:49255]     config.get('mysql', 'password'), \\
[Mon Sep 08 15:11:12.060696 2014] [:error] [pid 20205] [client 127.0.0.1:49255]   File "/usr/lib/python2.7/ConfigParser.py", line 618, in get
[Mon Sep 08 15:11:12.060879 2014] [:error] [pid 20205] [client 127.0.0.1:49255]     raise NoOptionError(option, section)
[Mon Sep 08 15:11:12.060900 2014] [:error] [pid 20205] [client 127.0.0.1:49255] NoOptionError: No option 'password' in section: 'mysql'
[Mon Sep 08 15:14:15.068769 2014] [:info] [pid 20380] [client 127.0.0.1:49308] mod_wsgi (pid=20380, process='', application='visched.local'): Loading WSGI script '/var/www/visched/app/visched.wsgi'.
[Mon Sep 08 15:14:15.325401 2014] [:error] [pid 20380] [client 127.0.0.1:49308] mod_wsgi (pid=20380): Exception occurred processing WSGI script '/var/www/visched/app/visched.wsgi'.
[Mon Sep 08 15:14:15.325463 2014] [:error] [pid 20380] [client 127.0.0.1:49308] Traceback (most recent call last):
[Mon Sep 08 15:14:15.325486 2014] [:error] [pid 20380] [client 127.0.0.1:49308]   File "/var/www/visched/app/visched.wsgi", line 14, in application
[Mon Sep 08 15:14:15.325565 2014] [:error] [pid 20380] [client 127.0.0.1:49308]     import visched.page.handlers
[Mon Sep 08 15:14:15.325575 2014] [:error] [pid 20380] [client 127.0.0.1:49308]   File "/var/www/visched/app/visched/page/handlers.py", line 7, in <module>
[Mon Sep 08 15:14:15.325660 2014] [:error] [pid 20380] [client 127.0.0.1:49308]     import visched.models
[Mon Sep 08 15:14:15.325671 2014] [:error] [pid 20380] [client 127.0.0.1:49308]   File "/var/www/visched/app/visched/models.py", line 797, in <module>
[Mon Sep 08 15:14:15.325865 2014] [:error] [pid 20380] [client 127.0.0.1:49308]     Base.prepare(visched.db.engine)
[Mon Sep 08 15:14:15.325876 2014] [:error] [pid 20380] [client 127.0.0.1:49308]   File "/usr/local/lib/python2.7/dist-packages/sqlalchemy/ext/declarative/api.py", line 478, in prepare
[Mon Sep 08 15:14:15.326006 2014] [:error] [pid 20380] [client 127.0.0.1:49308]     cls._sa_decl_prepare(thingy.local_table, engine)
[Mon Sep 08 15:14:15.326015 2014] [:error] [pid 20380] [client 127.0.0.1:49308]   File "/usr/local/lib/python2.7/dist-packages/sqlalchemy/ext/declarative/api.py", line 507, in _sa_decl_prepare
[Mon Sep 08 15:14:15.326031 2014] [:error] [pid 20380] [client 127.0.0.1:49308]     cls._reflect_table(local_table, engine)
[Mon Sep 08 15:14:15.326039 2014] [:error] [pid 20380] [client 127.0.0.1:49308]   File "/usr/local/lib/python2.7/dist-packages/sqlalchemy/ext/declarative/api.py", line 517, in _reflect_table
[Mon Sep 08 15:14:15.326052 2014] [:error] [pid 20380] [client 127.0.0.1:49308]     schema=table.schema)
[Mon Sep 08 15:14:15.326060 2014] [:error] [pid 20380] [client 127.0.0.1:49308]   File "/usr/local/lib/python2.7/dist-packages/sqlalchemy/sql/schema.py", line 344, in __new__
[Mon Sep 08 15:14:15.326818 2014] [:error] [pid 20380] [client 127.0.0.1:49308]     table._init_existing(*args, **kw)
[Mon Sep 08 15:14:15.326832 2014] [:error] [pid 20380] [client 127.0.0.1:49308]   File "/usr/local/lib/python2.7/dist-packages/sqlalchemy/sql/schema.py", line 494, in _init_existing
[Mon Sep 08 15:14:15.326848 2014] [:error] [pid 20380] [client 127.0.0.1:49308]     include_columns, exclude_columns)
[Mon Sep 08 15:14:15.326856 2014] [:error] [pid 20380] [client 127.0.0.1:49308]   File "/usr/local/lib/python2.7/dist-packages/sqlalchemy/sql/schema.py", line 439, in _autoload
[Mon Sep 08 15:14:15.326869 2014] [:error] [pid 20380] [client 127.0.0.1:49308]     self, include_columns, exclude_columns
[Mon Sep 08 15:14:15.326877 2014] [:error] [pid 20380] [client 127.0.0.1:49308]   File "/usr/local/lib/python2.7/dist-packages/sqlalchemy/engine/base.py", line 1732, in run_callable
[Mon Sep 08 15:14:15.327277 2014] [:error] [pid 20380] [client 127.0.0.1:49308]     with self.contextual_connect() as conn:
[Mon Sep 08 15:14:15.327287 2014] [:error] [pid 20380] [client 127.0.0.1:49308]   File "/usr/local/lib/python2.7/dist-packages/sqlalchemy/engine/base.py", line 1799, in contextual_connect
[Mon Sep 08 15:14:15.327301 2014] [:error] [pid 20380] [client 127.0.0.1:49308]     self.pool.connect(),
[Mon Sep 08 15:14:15.327309 2014] [:error] [pid 20380] [client 127.0.0.1:49308]   File "/usr/local/lib/python2.7/dist-packages/sqlalchemy/pool.py", line 338, in connect
[Mon Sep 08 15:14:15.327582 2014] [:error] [pid 20380] [client 127.0.0.1:49308]     return _ConnectionFairy._checkout(self)
[Mon Sep 08 15:14:15.327592 2014] [:error] [pid 20380] [client 127.0.0.1:49308]   File "/usr/local/lib/python2.7/dist-packages/sqlalchemy/pool.py", line 641, in _checkout
[Mon Sep 08 15:14:15.327606 2014] [:error] [pid 20380] [client 127.0.0.1:49308]     fairy = _ConnectionRecord.checkout(pool)
[Mon Sep 08 15:14:15.327614 2014] [:error] [pid 20380] [client 127.0.0.1:49308]   File "/usr/local/lib/python2.7/dist-packages/sqlalchemy/pool.py", line 440, in checkout
[Mon Sep 08 15:14:15.327626 2014] [:error] [pid 20380] [client 127.0.0.1:49308]     rec = pool._do_get()
[Mon Sep 08 15:14:15.327634 2014] [:error] [pid 20380] [client 127.0.0.1:49308]   File "/usr/local/lib/python2.7/dist-packages/sqlalchemy/pool.py", line 961, in _do_get
[Mon Sep 08 15:14:15.327645 2014] [:error] [pid 20380] [client 127.0.0.1:49308]     return self._create_connection()
[Mon Sep 08 15:14:15.327653 2014] [:error] [pid 20380] [client 127.0.0.1:49308]   File "/usr/local/lib/python2.7/dist-packages/sqlalchemy/pool.py", line 285, in _create_connection
[Mon Sep 08 15:14:15.327664 2014] [:error] [pid 20380] [client 127.0.0.1:49308]     return _ConnectionRecord(self)
[Mon Sep 08 15:14:15.327672 2014] [:error] [pid 20380] [client 127.0.0.1:49308]   File "/usr/local/lib/python2.7/dist-packages/sqlalchemy/pool.py", line 411, in __init__
[Mon Sep 08 15:14:15.327683 2014] [:error] [pid 20380] [client 127.0.0.1:49308]     self.connection = self.__connect()
[Mon Sep 08 15:14:15.327691 2014] [:error] [pid 20380] [client 127.0.0.1:49308]   File "/usr/local/lib/python2.7/dist-packages/sqlalchemy/pool.py", line 537, in __connect
[Mon Sep 08 15:14:15.327702 2014] [:error] [pid 20380] [client 127.0.0.1:49308]     connection = self.__pool._creator()
[Mon Sep 08 15:14:15.327710 2014] [:error] [pid 20380] [client 127.0.0.1:49308]   File "/usr/local/lib/python2.7/dist-packages/sqlalchemy/engine/strategies.py", line 96, in connect
[Mon Sep 08 15:14:15.327792 2014] [:error] [pid 20380] [client 127.0.0.1:49308]     connection_invalidated=invalidated
[Mon Sep 08 15:14:15.327802 2014] [:error] [pid 20380] [client 127.0.0.1:49308]   File "/usr/local/lib/python2.7/dist-packages/sqlalchemy/util/compat.py", line 199, in raise_from_cause
[Mon Sep 08 15:14:15.327863 2014] [:error] [pid 20380] [client 127.0.0.1:49308]     reraise(type(exception), exception, tb=exc_tb)
[Mon Sep 08 15:14:15.327872 2014] [:error] [pid 20380] [client 127.0.0.1:49308]   File "/usr/local/lib/python2.7/dist-packages/sqlalchemy/engine/strategies.py", line 90, in connect
[Mon Sep 08 15:14:15.327894 2014] [:error] [pid 20380] [client 127.0.0.1:49308]     return dialect.connect(*cargs, **cparams)
[Mon Sep 08 15:14:15.327903 2014] [:error] [pid 20380] [client 127.0.0.1:49308]   File "/usr/local/lib/python2.7/dist-packages/sqlalchemy/engine/default.py", line 377, in connect
[Mon Sep 08 15:14:15.328114 2014] [:error] [pid 20380] [client 127.0.0.1:49308]     return self.dbapi.connect(*cargs, **cparams)
[Mon Sep 08 15:14:15.328125 2014] [:error] [pid 20380] [client 127.0.0.1:49308]   File "/usr/lib/python2.7/dist-packages/MySQLdb/__init__.py", line 81, in Connect
[Mon Sep 08 15:14:15.328176 2014] [:error] [pid 20380] [client 127.0.0.1:49308]     return Connection(*args, **kwargs)
[Mon Sep 08 15:14:15.328185 2014] [:error] [pid 20380] [client 127.0.0.1:49308]   File "/usr/lib/python2.7/dist-packages/MySQLdb/connections.py", line 187, in __init__
[Mon Sep 08 15:14:15.328282 2014] [:error] [pid 20380] [client 127.0.0.1:49308]     super(Connection, self).__init__(*args, **kwargs2)
[Mon Sep 08 15:14:15.328344 2014] [:error] [pid 20380] [client 127.0.0.1:49308] OperationalError: (OperationalError) (1045, "Access denied for user 'root'@'localhost' (using password: YES)") None None
[Mon Sep 08 15:15:43.601228 2014] [:info] [pid 20381] [client 127.0.0.1:49342] mod_wsgi (pid=20381, process='', application='visched.local'): Loading WSGI script '/var/www/visched/app/visched.wsgi'.
[Mon Sep 08 15:15:43.852296 2014] [:error] [pid 20381] [client 127.0.0.1:49342] mod_wsgi (pid=20381): Exception occurred processing WSGI script '/var/www/visched/app/visched.wsgi'.
[Mon Sep 08 15:15:43.852429 2014] [:error] [pid 20381] [client 127.0.0.1:49342] Traceback (most recent call last):
[Mon Sep 08 15:15:43.852506 2014] [:error] [pid 20381] [client 127.0.0.1:49342]   File "/var/www/visched/app/visched.wsgi", line 14, in application
[Mon Sep 08 15:15:43.852723 2014] [:error] [pid 20381] [client 127.0.0.1:49342]     import visched.page.handlers
[Mon Sep 08 15:15:43.852763 2014] [:error] [pid 20381] [client 127.0.0.1:49342]   File "/var/www/visched/app/visched/page/handlers.py", line 7, in <module>
[Mon Sep 08 15:15:43.853061 2014] [:error] [pid 20381] [client 127.0.0.1:49342]     import visched.models
[Mon Sep 08 15:15:43.853099 2014] [:error] [pid 20381] [client 127.0.0.1:49342]   File "/var/www/visched/app/visched/models.py", line 797, in <module>
[Mon Sep 08 15:15:43.853834 2014] [:error] [pid 20381] [client 127.0.0.1:49342]     Base.prepare(visched.db.engine)
[Mon Sep 08 15:15:43.853875 2014] [:error] [pid 20381] [client 127.0.0.1:49342]   File "/usr/local/lib/python2.7/dist-packages/sqlalchemy/ext/declarative/api.py", line 478, in prepare
[Mon Sep 08 15:15:43.854281 2014] [:error] [pid 20381] [client 127.0.0.1:49342]     cls._sa_decl_prepare(thingy.local_table, engine)
[Mon Sep 08 15:15:43.854292 2014] [:error] [pid 20381] [client 127.0.0.1:49342]   File "/usr/local/lib/python2.7/dist-packages/sqlalchemy/ext/declarative/api.py", line 507, in _sa_decl_prepare
[Mon Sep 08 15:15:43.854307 2014] [:error] [pid 20381] [client 127.0.0.1:49342]     cls._reflect_table(local_table, engine)
[Mon Sep 08 15:15:43.854316 2014] [:error] [pid 20381] [client 127.0.0.1:49342]   File "/usr/local/lib/python2.7/dist-packages/sqlalchemy/ext/declarative/api.py", line 517, in _reflect_table
[Mon Sep 08 15:15:43.854329 2014] [:error] [pid 20381] [client 127.0.0.1:49342]     schema=table.schema)
[Mon Sep 08 15:15:43.854337 2014] [:error] [pid 20381] [client 127.0.0.1:49342]   File "/usr/local/lib/python2.7/dist-packages/sqlalchemy/sql/schema.py", line 344, in __new__
[Mon Sep 08 15:15:43.855052 2014] [:error] [pid 20381] [client 127.0.0.1:49342]     table._init_existing(*args, **kw)
[Mon Sep 08 15:15:43.855064 2014] [:error] [pid 20381] [client 127.0.0.1:49342]   File "/usr/local/lib/python2.7/dist-packages/sqlalchemy/sql/schema.py", line 494, in _init_existing
[Mon Sep 08 15:15:43.855079 2014] [:error] [pid 20381] [client 127.0.0.1:49342]     include_columns, exclude_columns)
[Mon Sep 08 15:15:43.855098 2014] [:error] [pid 20381] [client 127.0.0.1:49342]   File "/usr/local/lib/python2.7/dist-packages/sqlalchemy/sql/schema.py", line 439, in _autoload
[Mon Sep 08 15:15:43.855110 2014] [:error] [pid 20381] [client 127.0.0.1:49342]     self, include_columns, exclude_columns
[Mon Sep 08 15:15:43.855118 2014] [:error] [pid 20381] [client 127.0.0.1:49342]   File "/usr/local/lib/python2.7/dist-packages/sqlalchemy/engine/base.py", line 1732, in run_callable
[Mon Sep 08 15:15:43.855526 2014] [:error] [pid 20381] [client 127.0.0.1:49342]     with self.contextual_connect() as conn:
[Mon Sep 08 15:15:43.855536 2014] [:error] [pid 20381] [client 127.0.0.1:49342]   File "/usr/local/lib/python2.7/dist-packages/sqlalchemy/engine/base.py", line 1799, in contextual_connect
[Mon Sep 08 15:15:43.855549 2014] [:error] [pid 20381] [client 127.0.0.1:49342]     self.pool.connect(),
[Mon Sep 08 15:15:43.855557 2014] [:error] [pid 20381] [client 127.0.0.1:49342]   File "/usr/local/lib/python2.7/dist-packages/sqlalchemy/pool.py", line 338, in connect
[Mon Sep 08 15:15:43.855823 2014] [:error] [pid 20381] [client 127.0.0.1:49342]     return _ConnectionFairy._checkout(self)
[Mon Sep 08 15:15:43.855833 2014] [:error] [pid 20381] [client 127.0.0.1:49342]   File "/usr/local/lib/python2.7/dist-packages/sqlalchemy/pool.py", line 641, in _checkout
[Mon Sep 08 15:15:43.855847 2014] [:error] [pid 20381] [client 127.0.0.1:49342]     fairy = _ConnectionRecord.checkout(pool)
[Mon Sep 08 15:15:43.855855 2014] [:error] [pid 20381] [client 127.0.0.1:49342]   File "/usr/local/lib/python2.7/dist-packages/sqlalchemy/pool.py", line 440, in checkout
[Mon Sep 08 15:15:43.855867 2014] [:error] [pid 20381] [client 127.0.0.1:49342]     rec = pool._do_get()
[Mon Sep 08 15:15:43.855875 2014] [:error] [pid 20381] [client 127.0.0.1:49342]   File "/usr/local/lib/python2.7/dist-packages/sqlalchemy/pool.py", line 961, in _do_get
[Mon Sep 08 15:15:43.855887 2014] [:error] [pid 20381] [client 127.0.0.1:49342]     return self._create_connection()
[Mon Sep 08 15:15:43.855894 2014] [:error] [pid 20381] [client 127.0.0.1:49342]   File "/usr/local/lib/python2.7/dist-packages/sqlalchemy/pool.py", line 285, in _create_connection
[Mon Sep 08 15:15:43.855906 2014] [:error] [pid 20381] [client 127.0.0.1:49342]     return _ConnectionRecord(self)
[Mon Sep 08 15:15:43.855915 2014] [:error] [pid 20381] [client 127.0.0.1:49342]   File "/usr/local/lib/python2.7/dist-packages/sqlalchemy/pool.py", line 411, in __init__
[Mon Sep 08 15:15:43.855926 2014] [:error] [pid 20381] [client 127.0.0.1:49342]     self.connection = self.__connect()
[Mon Sep 08 15:15:43.855934 2014] [:error] [pid 20381] [client 127.0.0.1:49342]   File "/usr/local/lib/python2.7/dist-packages/sqlalchemy/pool.py", line 537, in __connect
[Mon Sep 08 15:15:43.855945 2014] [:error] [pid 20381] [client 127.0.0.1:49342]     connection = self.__pool._creator()
[Mon Sep 08 15:15:43.855953 2014] [:error] [pid 20381] [client 127.0.0.1:49342]   File "/usr/local/lib/python2.7/dist-packages/sqlalchemy/engine/strategies.py", line 96, in connect
[Mon Sep 08 15:15:43.856052 2014] [:error] [pid 20381] [client 127.0.0.1:49342]     connection_invalidated=invalidated
[Mon Sep 08 15:15:43.856061 2014] [:error] [pid 20381] [client 127.0.0.1:49342]   File "/usr/local/lib/python2.7/dist-packages/sqlalchemy/util/compat.py", line 199, in raise_from_cause
[Mon Sep 08 15:15:43.856123 2014] [:error] [pid 20381] [client 127.0.0.1:49342]     reraise(type(exception), exception, tb=exc_tb)
[Mon Sep 08 15:15:43.856132 2014] [:error] [pid 20381] [client 127.0.0.1:49342]   File "/usr/local/lib/python2.7/dist-packages/sqlalchemy/engine/strategies.py", line 90, in connect
[Mon Sep 08 15:15:43.856144 2014] [:error] [pid 20381] [client 127.0.0.1:49342]     return dialect.connect(*cargs, **cparams)
[Mon Sep 08 15:15:43.856152 2014] [:error] [pid 20381] [client 127.0.0.1:49342]   File "/usr/local/lib/python2.7/dist-packages/sqlalchemy/engine/default.py", line 377, in connect
[Mon Sep 08 15:15:43.856373 2014] [:error] [pid 20381] [client 127.0.0.1:49342]     return self.dbapi.connect(*cargs, **cparams)
[Mon Sep 08 15:15:43.856383 2014] [:error] [pid 20381] [client 127.0.0.1:49342]   File "/usr/lib/python2.7/dist-packages/MySQLdb/__init__.py", line 81, in Connect
[Mon Sep 08 15:15:43.856435 2014] [:error] [pid 20381] [client 127.0.0.1:49342]     return Connection(*args, **kwargs)
[Mon Sep 08 15:15:43.856444 2014] [:error] [pid 20381] [client 127.0.0.1:49342]   File "/usr/lib/python2.7/dist-packages/MySQLdb/connections.py", line 187, in __init__
[Mon Sep 08 15:15:43.856539 2014] [:error] [pid 20381] [client 127.0.0.1:49342]     super(Connection, self).__init__(*args, **kwargs2)
[Mon Sep 08 15:15:43.856601 2014] [:error] [pid 20381] [client 127.0.0.1:49342] OperationalError: (OperationalError) (1045, "Access denied for user 'root'@'localhost' (using password: YES)") None None
[Mon Sep 08 15:15:52.522013 2014] [:info] [pid 20507] [client 127.0.0.1:49344] mod_wsgi (pid=20507, process='', application='visched.local'): Loading WSGI script '/var/www/visched/app/visched.wsgi'.
[Mon Sep 08 15:15:52.764275 2014] [:error] [pid 20507] [client 127.0.0.1:49344] mod_wsgi (pid=20507): Exception occurred processing WSGI script '/var/www/visched/app/visched.wsgi'.
[Mon Sep 08 15:15:52.764443 2014] [:error] [pid 20507] [client 127.0.0.1:49344] Traceback (most recent call last):
[Mon Sep 08 15:15:52.764513 2014] [:error] [pid 20507] [client 127.0.0.1:49344]   File "/var/www/visched/app/visched.wsgi", line 14, in application
[Mon Sep 08 15:15:52.764752 2014] [:error] [pid 20507] [client 127.0.0.1:49344]     import visched.page.handlers
[Mon Sep 08 15:15:52.764791 2014] [:error] [pid 20507] [client 127.0.0.1:49344]   File "/var/www/visched/app/visched/page/handlers.py", line 7, in <module>
[Mon Sep 08 15:15:52.765095 2014] [:error] [pid 20507] [client 127.0.0.1:49344]     import visched.models
[Mon Sep 08 15:15:52.765130 2014] [:error] [pid 20507] [client 127.0.0.1:49344]   File "/var/www/visched/app/visched/models.py", line 797, in <module>
[Mon Sep 08 15:15:52.765871 2014] [:error] [pid 20507] [client 127.0.0.1:49344]     Base.prepare(visched.db.engine)
[Mon Sep 08 15:15:52.765910 2014] [:error] [pid 20507] [client 127.0.0.1:49344]   File "/usr/local/lib/python2.7/dist-packages/sqlalchemy/ext/declarative/api.py", line 478, in prepare
[Mon Sep 08 15:15:52.766481 2014] [:error] [pid 20507] [client 127.0.0.1:49344]     cls._sa_decl_prepare(thingy.local_table, engine)
[Mon Sep 08 15:15:52.766521 2014] [:error] [pid 20507] [client 127.0.0.1:49344]   File "/usr/local/lib/python2.7/dist-packages/sqlalchemy/ext/declarative/api.py", line 507, in _sa_decl_prepare
[Mon Sep 08 15:15:52.766581 2014] [:error] [pid 20507] [client 127.0.0.1:49344]     cls._reflect_table(local_table, engine)
[Mon Sep 08 15:15:52.766613 2014] [:error] [pid 20507] [client 127.0.0.1:49344]   File "/usr/local/lib/python2.7/dist-packages/sqlalchemy/ext/declarative/api.py", line 517, in _reflect_table
[Mon Sep 08 15:15:52.766663 2014] [:error] [pid 20507] [client 127.0.0.1:49344]     schema=table.schema)
[Mon Sep 08 15:15:52.766694 2014] [:error] [pid 20507] [client 127.0.0.1:49344]   File "/usr/local/lib/python2.7/dist-packages/sqlalchemy/sql/schema.py", line 344, in __new__
[Mon Sep 08 15:15:52.769516 2014] [:error] [pid 20507] [client 127.0.0.1:49344]     table._init_existing(*args, **kw)
[Mon Sep 08 15:15:52.769558 2014] [:error] [pid 20507] [client 127.0.0.1:49344]   File "/usr/local/lib/python2.7/dist-packages/sqlalchemy/sql/schema.py", line 494, in _init_existing
[Mon Sep 08 15:15:52.769614 2014] [:error] [pid 20507] [client 127.0.0.1:49344]     include_columns, exclude_columns)
[Mon Sep 08 15:15:52.769645 2014] [:error] [pid 20507] [client 127.0.0.1:49344]   File "/usr/local/lib/python2.7/dist-packages/sqlalchemy/sql/schema.py", line 439, in _autoload
[Mon Sep 08 15:15:52.769695 2014] [:error] [pid 20507] [client 127.0.0.1:49344]     self, include_columns, exclude_columns
[Mon Sep 08 15:15:52.769725 2014] [:error] [pid 20507] [client 127.0.0.1:49344]   File "/usr/local/lib/python2.7/dist-packages/sqlalchemy/engine/base.py", line 1732, in run_callable
[Mon Sep 08 15:15:52.770528 2014] [:error] [pid 20507] [client 127.0.0.1:49344]     with self.contextual_connect() as conn:
[Mon Sep 08 15:15:52.770540 2014] [:error] [pid 20507] [client 127.0.0.1:49344]   File "/usr/local/lib/python2.7/dist-packages/sqlalchemy/engine/base.py", line 1799, in contextual_connect
[Mon Sep 08 15:15:52.770553 2014] [:error] [pid 20507] [client 127.0.0.1:49344]     self.pool.connect(),
[Mon Sep 08 15:15:52.770562 2014] [:error] [pid 20507] [client 127.0.0.1:49344]   File "/usr/local/lib/python2.7/dist-packages/sqlalchemy/pool.py", line 338, in connect
[Mon Sep 08 15:15:52.770827 2014] [:error] [pid 20507] [client 127.0.0.1:49344]     return _ConnectionFairy._checkout(self)
[Mon Sep 08 15:15:52.770838 2014] [:error] [pid 20507] [client 127.0.0.1:49344]   File "/usr/local/lib/python2.7/dist-packages/sqlalchemy/pool.py", line 641, in _checkout
[Mon Sep 08 15:15:52.770851 2014] [:error] [pid 20507] [client 127.0.0.1:49344]     fairy = _ConnectionRecord.checkout(pool)
[Mon Sep 08 15:15:52.770858 2014] [:error] [pid 20507] [client 127.0.0.1:49344]   File "/usr/local/lib/python2.7/dist-packages/sqlalchemy/pool.py", line 440, in checkout
[Mon Sep 08 15:15:52.770870 2014] [:error] [pid 20507] [client 127.0.0.1:49344]     rec = pool._do_get()
[Mon Sep 08 15:15:52.770878 2014] [:error] [pid 20507] [client 127.0.0.1:49344]   File "/usr/local/lib/python2.7/dist-packages/sqlalchemy/pool.py", line 961, in _do_get
[Mon Sep 08 15:15:52.770889 2014] [:error] [pid 20507] [client 127.0.0.1:49344]     return self._create_connection()
[Mon Sep 08 15:15:52.770897 2014] [:error] [pid 20507] [client 127.0.0.1:49344]   File "/usr/local/lib/python2.7/dist-packages/sqlalchemy/pool.py", line 285, in _create_connection
[Mon Sep 08 15:15:52.770908 2014] [:error] [pid 20507] [client 127.0.0.1:49344]     return _ConnectionRecord(self)
[Mon Sep 08 15:15:52.770915 2014] [:error] [pid 20507] [client 127.0.0.1:49344]   File "/usr/local/lib/python2.7/dist-packages/sqlalchemy/pool.py", line 411, in __init__
[Mon Sep 08 15:15:52.770926 2014] [:error] [pid 20507] [client 127.0.0.1:49344]     self.connection = self.__connect()
[Mon Sep 08 15:15:52.770934 2014] [:error] [pid 20507] [client 127.0.0.1:49344]   File "/usr/local/lib/python2.7/dist-packages/sqlalchemy/pool.py", line 537, in __connect
[Mon Sep 08 15:15:52.770945 2014] [:error] [pid 20507] [client 127.0.0.1:49344]     connection = self.__pool._creator()
[Mon Sep 08 15:15:52.770953 2014] [:error] [pid 20507] [client 127.0.0.1:49344]   File "/usr/local/lib/python2.7/dist-packages/sqlalchemy/engine/strategies.py", line 96, in connect
[Mon Sep 08 15:15:52.771035 2014] [:error] [pid 20507] [client 127.0.0.1:49344]     connection_invalidated=invalidated
[Mon Sep 08 15:15:52.771045 2014] [:error] [pid 20507] [client 127.0.0.1:49344]   File "/usr/local/lib/python2.7/dist-packages/sqlalchemy/util/compat.py", line 199, in raise_from_cause
[Mon Sep 08 15:15:52.771106 2014] [:error] [pid 20507] [client 127.0.0.1:49344]     reraise(type(exception), exception, tb=exc_tb)
[Mon Sep 08 15:15:52.771114 2014] [:error] [pid 20507] [client 127.0.0.1:49344]   File "/usr/local/lib/python2.7/dist-packages/sqlalchemy/engine/strategies.py", line 90, in connect
[Mon Sep 08 15:15:52.771128 2014] [:error] [pid 20507] [client 127.0.0.1:49344]     return dialect.connect(*cargs, **cparams)
[Mon Sep 08 15:15:52.771136 2014] [:error] [pid 20507] [client 127.0.0.1:49344]   File "/usr/local/lib/python2.7/dist-packages/sqlalchemy/engine/default.py", line 377, in connect
[Mon Sep 08 15:15:52.771347 2014] [:error] [pid 20507] [client 127.0.0.1:49344]     return self.dbapi.connect(*cargs, **cparams)
[Mon Sep 08 15:15:52.771357 2014] [:error] [pid 20507] [client 127.0.0.1:49344]   File "/usr/lib/python2.7/dist-packages/MySQLdb/__init__.py", line 81, in Connect
[Mon Sep 08 15:15:52.771408 2014] [:error] [pid 20507] [client 127.0.0.1:49344]     return Connection(*args, **kwargs)
[Mon Sep 08 15:15:52.771417 2014] [:error] [pid 20507] [client 127.0.0.1:49344]   File "/usr/lib/python2.7/dist-packages/MySQLdb/connections.py", line 187, in __init__
[Mon Sep 08 15:15:52.771521 2014] [:error] [pid 20507] [client 127.0.0.1:49344]     super(Connection, self).__init__(*args, **kwargs2)
[Mon Sep 08 15:15:52.771584 2014] [:error] [pid 20507] [client 127.0.0.1:49344] OperationalError: (OperationalError) (1045, "Access denied for user 'root'@'localhost' (using password: YES)") None None
[Mon Sep 08 15:39:23.641370 2014] [:info] [pid 20502] [client 127.0.0.1:49562] mod_wsgi (pid=20502, process='', application='visched.local'): Loading WSGI script '/var/www/visched/app/visched.wsgi'.
[Mon Sep 08 15:39:23.910649 2014] [:error] [pid 20502] [client 127.0.0.1:49562] mod_wsgi (pid=20502): Exception occurred processing WSGI script '/var/www/visched/app/visched.wsgi'.
[Mon Sep 08 15:39:23.910770 2014] [:error] [pid 20502] [client 127.0.0.1:49562] Traceback (most recent call last):
[Mon Sep 08 15:39:23.910798 2014] [:error] [pid 20502] [client 127.0.0.1:49562]   File "/var/www/visched/app/visched.wsgi", line 14, in application
[Mon Sep 08 15:39:23.910900 2014] [:error] [pid 20502] [client 127.0.0.1:49562]     import visched.page.handlers
[Mon Sep 08 15:39:23.910911 2014] [:error] [pid 20502] [client 127.0.0.1:49562]   File "/var/www/visched/app/visched/page/handlers.py", line 7, in <module>
[Mon Sep 08 15:39:23.911002 2014] [:error] [pid 20502] [client 127.0.0.1:49562]     import visched.models
[Mon Sep 08 15:39:23.911011 2014] [:error] [pid 20502] [client 127.0.0.1:49562]   File "/var/www/visched/app/visched/models.py", line 797, in <module>
[Mon Sep 08 15:39:23.911220 2014] [:error] [pid 20502] [client 127.0.0.1:49562]     Base.prepare(visched.db.engine)
[Mon Sep 08 15:39:23.911230 2014] [:error] [pid 20502] [client 127.0.0.1:49562]   File "/usr/local/lib/python2.7/dist-packages/sqlalchemy/ext/declarative/api.py", line 478, in prepare
[Mon Sep 08 15:39:23.911362 2014] [:error] [pid 20502] [client 127.0.0.1:49562]     cls._sa_decl_prepare(thingy.local_table, engine)
[Mon Sep 08 15:39:23.911371 2014] [:error] [pid 20502] [client 127.0.0.1:49562]   File "/usr/local/lib/python2.7/dist-packages/sqlalchemy/ext/declarative/api.py", line 507, in _sa_decl_prepare
[Mon Sep 08 15:39:23.911387 2014] [:error] [pid 20502] [client 127.0.0.1:49562]     cls._reflect_table(local_table, engine)
[Mon Sep 08 15:39:23.911395 2014] [:error] [pid 20502] [client 127.0.0.1:49562]   File "/usr/local/lib/python2.7/dist-packages/sqlalchemy/ext/declarative/api.py", line 517, in _reflect_table
[Mon Sep 08 15:39:23.911407 2014] [:error] [pid 20502] [client 127.0.0.1:49562]     schema=table.schema)
[Mon Sep 08 15:39:23.911415 2014] [:error] [pid 20502] [client 127.0.0.1:49562]   File "/usr/local/lib/python2.7/dist-packages/sqlalchemy/sql/schema.py", line 344, in __new__
[Mon Sep 08 15:39:23.912130 2014] [:error] [pid 20502] [client 127.0.0.1:49562]     table._init_existing(*args, **kw)
[Mon Sep 08 15:39:23.912143 2014] [:error] [pid 20502] [client 127.0.0.1:49562]   File "/usr/local/lib/python2.7/dist-packages/sqlalchemy/sql/schema.py", line 494, in _init_existing
[Mon Sep 08 15:39:23.912158 2014] [:error] [pid 20502] [client 127.0.0.1:49562]     include_columns, exclude_columns)
[Mon Sep 08 15:39:23.912167 2014] [:error] [pid 20502] [client 127.0.0.1:49562]   File "/usr/local/lib/python2.7/dist-packages/sqlalchemy/sql/schema.py", line 439, in _autoload
[Mon Sep 08 15:39:23.912179 2014] [:error] [pid 20502] [client 127.0.0.1:49562]     self, include_columns, exclude_columns
[Mon Sep 08 15:39:23.912187 2014] [:error] [pid 20502] [client 127.0.0.1:49562]   File "/usr/local/lib/python2.7/dist-packages/sqlalchemy/engine/base.py", line 1732, in run_callable
[Mon Sep 08 15:39:23.912585 2014] [:error] [pid 20502] [client 127.0.0.1:49562]     with self.contextual_connect() as conn:
[Mon Sep 08 15:39:23.912595 2014] [:error] [pid 20502] [client 127.0.0.1:49562]   File "/usr/local/lib/python2.7/dist-packages/sqlalchemy/engine/base.py", line 1799, in contextual_connect
[Mon Sep 08 15:39:23.912609 2014] [:error] [pid 20502] [client 127.0.0.1:49562]     self.pool.connect(),
[Mon Sep 08 15:39:23.912628 2014] [:error] [pid 20502] [client 127.0.0.1:49562]   File "/usr/local/lib/python2.7/dist-packages/sqlalchemy/pool.py", line 338, in connect
[Mon Sep 08 15:39:23.912898 2014] [:error] [pid 20502] [client 127.0.0.1:49562]     return _ConnectionFairy._checkout(self)
[Mon Sep 08 15:39:23.912908 2014] [:error] [pid 20502] [client 127.0.0.1:49562]   File "/usr/local/lib/python2.7/dist-packages/sqlalchemy/pool.py", line 641, in _checkout
[Mon Sep 08 15:39:23.912921 2014] [:error] [pid 20502] [client 127.0.0.1:49562]     fairy = _ConnectionRecord.checkout(pool)
[Mon Sep 08 15:39:23.912929 2014] [:error] [pid 20502] [client 127.0.0.1:49562]   File "/usr/local/lib/python2.7/dist-packages/sqlalchemy/pool.py", line 440, in checkout
[Mon Sep 08 15:39:23.912940 2014] [:error] [pid 20502] [client 127.0.0.1:49562]     rec = pool._do_get()
[Mon Sep 08 15:39:23.912948 2014] [:error] [pid 20502] [client 127.0.0.1:49562]   File "/usr/local/lib/python2.7/dist-packages/sqlalchemy/pool.py", line 961, in _do_get
[Mon Sep 08 15:39:23.912960 2014] [:error] [pid 20502] [client 127.0.0.1:49562]     return self._create_connection()
[Mon Sep 08 15:39:23.912967 2014] [:error] [pid 20502] [client 127.0.0.1:49562]   File "/usr/local/lib/python2.7/dist-packages/sqlalchemy/pool.py", line 285, in _create_connection
[Mon Sep 08 15:39:23.912978 2014] [:error] [pid 20502] [client 127.0.0.1:49562]     return _ConnectionRecord(self)
[Mon Sep 08 15:39:23.912985 2014] [:error] [pid 20502] [client 127.0.0.1:49562]   File "/usr/local/lib/python2.7/dist-packages/sqlalchemy/pool.py", line 411, in __init__
[Mon Sep 08 15:39:23.912997 2014] [:error] [pid 20502] [client 127.0.0.1:49562]     self.connection = self.__connect()
[Mon Sep 08 15:39:23.913004 2014] [:error] [pid 20502] [client 127.0.0.1:49562]   File "/usr/local/lib/python2.7/dist-packages/sqlalchemy/pool.py", line 537, in __connect
[Mon Sep 08 15:39:23.913015 2014] [:error] [pid 20502] [client 127.0.0.1:49562]     connection = self.__pool._creator()
[Mon Sep 08 15:39:23.913023 2014] [:error] [pid 20502] [client 127.0.0.1:49562]   File "/usr/local/lib/python2.7/dist-packages/sqlalchemy/engine/strategies.py", line 96, in connect
[Mon Sep 08 15:39:23.913121 2014] [:error] [pid 20502] [client 127.0.0.1:49562]     connection_invalidated=invalidated
[Mon Sep 08 15:39:23.913130 2014] [:error] [pid 20502] [client 127.0.0.1:49562]   File "/usr/local/lib/python2.7/dist-packages/sqlalchemy/util/compat.py", line 199, in raise_from_cause
[Mon Sep 08 15:39:23.913194 2014] [:error] [pid 20502] [client 127.0.0.1:49562]     reraise(type(exception), exception, tb=exc_tb)
[Mon Sep 08 15:39:23.913202 2014] [:error] [pid 20502] [client 127.0.0.1:49562]   File "/usr/local/lib/python2.7/dist-packages/sqlalchemy/engine/strategies.py", line 90, in connect
[Mon Sep 08 15:39:23.913215 2014] [:error] [pid 20502] [client 127.0.0.1:49562]     return dialect.connect(*cargs, **cparams)
[Mon Sep 08 15:39:23.913223 2014] [:error] [pid 20502] [client 127.0.0.1:49562]   File "/usr/local/lib/python2.7/dist-packages/sqlalchemy/engine/default.py", line 377, in connect
[Mon Sep 08 15:39:23.913437 2014] [:error] [pid 20502] [client 127.0.0.1:49562]     return self.dbapi.connect(*cargs, **cparams)
[Mon Sep 08 15:39:23.913446 2014] [:error] [pid 20502] [client 127.0.0.1:49562]   File "/usr/lib/python2.7/dist-packages/MySQLdb/__init__.py", line 81, in Connect
[Mon Sep 08 15:39:23.913497 2014] [:error] [pid 20502] [client 127.0.0.1:49562]     return Connection(*args, **kwargs)
[Mon Sep 08 15:39:23.913506 2014] [:error] [pid 20502] [client 127.0.0.1:49562]   File "/usr/lib/python2.7/dist-packages/MySQLdb/connections.py", line 187, in __init__
[Mon Sep 08 15:39:23.913608 2014] [:error] [pid 20502] [client 127.0.0.1:49562]     super(Connection, self).__init__(*args, **kwargs2)
[Mon Sep 08 15:39:23.913673 2014] [:error] [pid 20502] [client 127.0.0.1:49562] OperationalError: (OperationalError) (1045, "Access denied for user 'root'@'localhost' (using password: YES)") None None
[Mon Sep 08 15:40:46.605574 2014] [:info] [pid 21188] [client 127.0.0.1:49571] mod_wsgi (pid=21188, process='', application='visched.local'): Loading WSGI script '/var/www/visched/app/visched.wsgi'.
[Mon Sep 08 15:40:46.838830 2014] [:error] [pid 21188] [client 127.0.0.1:49571] mod_wsgi (pid=21188): Exception occurred processing WSGI script '/var/www/visched/app/visched.wsgi'.
[Mon Sep 08 15:40:46.838924 2014] [:error] [pid 21188] [client 127.0.0.1:49571] Traceback (most recent call last):
[Mon Sep 08 15:40:46.838955 2014] [:error] [pid 21188] [client 127.0.0.1:49571]   File "/var/www/visched/app/visched.wsgi", line 14, in application
[Mon Sep 08 15:40:46.839066 2014] [:error] [pid 21188] [client 127.0.0.1:49571]     import visched.page.handlers
[Mon Sep 08 15:40:46.839077 2014] [:error] [pid 21188] [client 127.0.0.1:49571]   File "/var/www/visched/app/visched/page/handlers.py", line 7, in <module>
[Mon Sep 08 15:40:46.839174 2014] [:error] [pid 21188] [client 127.0.0.1:49571]     import visched.models
[Mon Sep 08 15:40:46.839184 2014] [:error] [pid 21188] [client 127.0.0.1:49571]   File "/var/www/visched/app/visched/models.py", line 797, in <module>
[Mon Sep 08 15:40:46.839396 2014] [:error] [pid 21188] [client 127.0.0.1:49571]     Base.prepare(visched.db.engine)
[Mon Sep 08 15:40:46.839406 2014] [:error] [pid 21188] [client 127.0.0.1:49571]   File "/usr/local/lib/python2.7/dist-packages/sqlalchemy/ext/declarative/api.py", line 478, in prepare
[Mon Sep 08 15:40:46.839548 2014] [:error] [pid 21188] [client 127.0.0.1:49571]     cls._sa_decl_prepare(thingy.local_table, engine)
[Mon Sep 08 15:40:46.839558 2014] [:error] [pid 21188] [client 127.0.0.1:49571]   File "/usr/local/lib/python2.7/dist-packages/sqlalchemy/ext/declarative/api.py", line 507, in _sa_decl_prepare
[Mon Sep 08 15:40:46.839574 2014] [:error] [pid 21188] [client 127.0.0.1:49571]     cls._reflect_table(local_table, engine)
[Mon Sep 08 15:40:46.839583 2014] [:error] [pid 21188] [client 127.0.0.1:49571]   File "/usr/local/lib/python2.7/dist-packages/sqlalchemy/ext/declarative/api.py", line 517, in _reflect_table
[Mon Sep 08 15:40:46.839595 2014] [:error] [pid 21188] [client 127.0.0.1:49571]     schema=table.schema)
[Mon Sep 08 15:40:46.839604 2014] [:error] [pid 21188] [client 127.0.0.1:49571]   File "/usr/local/lib/python2.7/dist-packages/sqlalchemy/sql/schema.py", line 344, in __new__
[Mon Sep 08 15:40:46.840392 2014] [:error] [pid 21188] [client 127.0.0.1:49571]     table._init_existing(*args, **kw)
[Mon Sep 08 15:40:46.840410 2014] [:error] [pid 21188] [client 127.0.0.1:49571]   File "/usr/local/lib/python2.7/dist-packages/sqlalchemy/sql/schema.py", line 494, in _init_existing
[Mon Sep 08 15:40:46.840428 2014] [:error] [pid 21188] [client 127.0.0.1:49571]     include_columns, exclude_columns)
[Mon Sep 08 15:40:46.840436 2014] [:error] [pid 21188] [client 127.0.0.1:49571]   File "/usr/local/lib/python2.7/dist-packages/sqlalchemy/sql/schema.py", line 439, in _autoload
[Mon Sep 08 15:40:46.840449 2014] [:error] [pid 21188] [client 127.0.0.1:49571]     self, include_columns, exclude_columns
[Mon Sep 08 15:40:46.840457 2014] [:error] [pid 21188] [client 127.0.0.1:49571]   File "/usr/local/lib/python2.7/dist-packages/sqlalchemy/engine/base.py", line 1732, in run_callable
[Mon Sep 08 15:40:46.840891 2014] [:error] [pid 21188] [client 127.0.0.1:49571]     with self.contextual_connect() as conn:
[Mon Sep 08 15:40:46.840904 2014] [:error] [pid 21188] [client 127.0.0.1:49571]   File "/usr/local/lib/python2.7/dist-packages/sqlalchemy/engine/base.py", line 1799, in contextual_connect
[Mon Sep 08 15:40:46.840919 2014] [:error] [pid 21188] [client 127.0.0.1:49571]     self.pool.connect(),
[Mon Sep 08 15:40:46.840928 2014] [:error] [pid 21188] [client 127.0.0.1:49571]   File "/usr/local/lib/python2.7/dist-packages/sqlalchemy/pool.py", line 338, in connect
[Mon Sep 08 15:40:46.841225 2014] [:error] [pid 21188] [client 127.0.0.1:49571]     return _ConnectionFairy._checkout(self)
[Mon Sep 08 15:40:46.841235 2014] [:error] [pid 21188] [client 127.0.0.1:49571]   File "/usr/local/lib/python2.7/dist-packages/sqlalchemy/pool.py", line 641, in _checkout
[Mon Sep 08 15:40:46.841262 2014] [:error] [pid 21188] [client 127.0.0.1:49571]     fairy = _ConnectionRecord.checkout(pool)
[Mon Sep 08 15:40:46.841271 2014] [:error] [pid 21188] [client 127.0.0.1:49571]   File "/usr/local/lib/python2.7/dist-packages/sqlalchemy/pool.py", line 440, in checkout
[Mon Sep 08 15:40:46.841283 2014] [:error] [pid 21188] [client 127.0.0.1:49571]     rec = pool._do_get()
[Mon Sep 08 15:40:46.841291 2014] [:error] [pid 21188] [client 127.0.0.1:49571]   File "/usr/local/lib/python2.7/dist-packages/sqlalchemy/pool.py", line 961, in _do_get
[Mon Sep 08 15:40:46.841303 2014] [:error] [pid 21188] [client 127.0.0.1:49571]     return self._create_connection()
[Mon Sep 08 15:40:46.841310 2014] [:error] [pid 21188] [client 127.0.0.1:49571]   File "/usr/local/lib/python2.7/dist-packages/sqlalchemy/pool.py", line 285, in _create_connection
[Mon Sep 08 15:40:46.841321 2014] [:error] [pid 21188] [client 127.0.0.1:49571]     return _ConnectionRecord(self)
[Mon Sep 08 15:40:46.841329 2014] [:error] [pid 21188] [client 127.0.0.1:49571]   File "/usr/local/lib/python2.7/dist-packages/sqlalchemy/pool.py", line 411, in __init__
[Mon Sep 08 15:40:46.841340 2014] [:error] [pid 21188] [client 127.0.0.1:49571]     self.connection = self.__connect()
[Mon Sep 08 15:40:46.841349 2014] [:error] [pid 21188] [client 127.0.0.1:49571]   File "/usr/local/lib/python2.7/dist-packages/sqlalchemy/pool.py", line 537, in __connect
[Mon Sep 08 15:40:46.841360 2014] [:error] [pid 21188] [client 127.0.0.1:49571]     connection = self.__pool._creator()
[Mon Sep 08 15:40:46.841367 2014] [:error] [pid 21188] [client 127.0.0.1:49571]   File "/usr/local/lib/python2.7/dist-packages/sqlalchemy/engine/strategies.py", line 96, in connect
[Mon Sep 08 15:40:46.841447 2014] [:error] [pid 21188] [client 127.0.0.1:49571]     connection_invalidated=invalidated
[Mon Sep 08 15:40:46.841457 2014] [:error] [pid 21188] [client 127.0.0.1:49571]   File "/usr/local/lib/python2.7/dist-packages/sqlalchemy/util/compat.py", line 199, in raise_from_cause
[Mon Sep 08 15:40:46.841517 2014] [:error] [pid 21188] [client 127.0.0.1:49571]     reraise(type(exception), exception, tb=exc_tb)
[Mon Sep 08 15:40:46.841526 2014] [:error] [pid 21188] [client 127.0.0.1:49571]   File "/usr/local/lib/python2.7/dist-packages/sqlalchemy/engine/strategies.py", line 90, in connect
[Mon Sep 08 15:40:46.841538 2014] [:error] [pid 21188] [client 127.0.0.1:49571]     return dialect.connect(*cargs, **cparams)
[Mon Sep 08 15:40:46.841546 2014] [:error] [pid 21188] [client 127.0.0.1:49571]   File "/usr/local/lib/python2.7/dist-packages/sqlalchemy/engine/default.py", line 377, in connect
[Mon Sep 08 15:40:46.841759 2014] [:error] [pid 21188] [client 127.0.0.1:49571]     return self.dbapi.connect(*cargs, **cparams)
[Mon Sep 08 15:40:46.841769 2014] [:error] [pid 21188] [client 127.0.0.1:49571]   File "/usr/lib/python2.7/dist-packages/MySQLdb/__init__.py", line 81, in Connect
[Mon Sep 08 15:40:46.841819 2014] [:error] [pid 21188] [client 127.0.0.1:49571]     return Connection(*args, **kwargs)
[Mon Sep 08 15:40:46.841828 2014] [:error] [pid 21188] [client 127.0.0.1:49571]   File "/usr/lib/python2.7/dist-packages/MySQLdb/connections.py", line 187, in __init__
[Mon Sep 08 15:40:46.841922 2014] [:error] [pid 21188] [client 127.0.0.1:49571]     super(Connection, self).__init__(*args, **kwargs2)
[Mon Sep 08 15:40:46.841983 2014] [:error] [pid 21188] [client 127.0.0.1:49571] OperationalError: (OperationalError) (1045, "Access denied for user 'root'@'localhost' (using password: YES)") None None
[Mon Sep 08 15:42:43.915527 2014] [:info] [pid 21194] [client 127.0.0.1:49588] mod_wsgi (pid=21194, process='', application='visched.local'): Loading WSGI script '/var/www/visched/app/visched.wsgi'.
[Mon Sep 08 15:43:13.527700 2014] [:info] [pid 21193] [client 127.0.0.1:49592] mod_wsgi (pid=21193, process='', application='visched.local'): Loading WSGI script '/var/www/visched/app/visched.wsgi'., referer: http://www.visched.local/
[Mon Sep 08 15:46:24.110487 2014] [:info] [pid 21192] [client 127.0.0.1:49627] mod_wsgi (pid=21192, process='', application='visched.local'): Loading WSGI script '/var/www/visched/app/visched.wsgi'., referer: http://www.visched.local/
[Mon Sep 08 15:46:24.916798 2014] [:info] [pid 21190] [client 127.0.0.1:49631] mod_wsgi (pid=21190, process='', application='visched.local'): Loading WSGI script '/var/www/visched/app/visched.wsgi'., referer: http://www.visched.local/app
[Mon Sep 08 15:46:24.920574 2014] [:info] [pid 21195] [client 127.0.0.1:49629] mod_wsgi (pid=21195, process='', application='visched.local'): Loading WSGI script '/var/www/visched/app/visched.wsgi'., referer: http://www.visched.local/app
[Mon Sep 08 15:46:24.923336 2014] [:info] [pid 21196] [client 127.0.0.1:49630] mod_wsgi (pid=21196, process='', application='visched.local'): Loading WSGI script '/var/www/visched/app/visched.wsgi'., referer: http://www.visched.local/app
[Mon Sep 08 15:46:24.928291 2014] [:info] [pid 21189] [client 127.0.0.1:49628] mod_wsgi (pid=21189, process='', application='visched.local'): Loading WSGI script '/var/www/visched/app/visched.wsgi'., referer: http://www.visched.local/app
[Mon Sep 08 15:46:31.446088 2014] [:info] [pid 21189] [client 127.0.0.1:49628] mod_wsgi (pid=21189, process='', application='visched.local'): Loading WSGI script '/var/www/visched/app/api.wsgi'., referer: http://www.visched.local/app
[Mon Sep 08 15:46:31.495236 2014] [:info] [pid 21195] [client 127.0.0.1:49629] mod_wsgi (pid=21195, process='', application='visched.local'): Loading WSGI script '/var/www/visched/app/api.wsgi'., referer: http://www.visched.local/app
[Mon Sep 08 15:46:46.223100 2014] [:info] [pid 21194] [client 127.0.0.1:49636] mod_wsgi (pid=21194, process='', application='visched.local'): Loading WSGI script '/var/www/visched/app/api.wsgi'., referer: http://www.visched.local/app
[Mon Sep 08 15:46:46.405659 2014] [:error] [pid 21194] [client 127.0.0.1:49636] mod_wsgi (pid=21194): Exception occurred processing WSGI script '/var/www/visched/app/api.wsgi'., referer: http://www.visched.local/app
[Mon Sep 08 15:46:46.405755 2014] [:error] [pid 21194] [client 127.0.0.1:49636] Traceback (most recent call last):, referer: http://www.visched.local/app
[Mon Sep 08 15:46:46.405777 2014] [:error] [pid 21194] [client 127.0.0.1:49636]   File "/var/www/visched/app/api.wsgi", line 107, in application, referer: http://www.visched.local/app
[Mon Sep 08 15:46:46.405904 2014] [:error] [pid 21194] [client 127.0.0.1:49636]     return _session_wrapped_app(environ, start_response), referer: http://www.visched.local/app
[Mon Sep 08 15:46:46.405915 2014] [:error] [pid 21194] [client 127.0.0.1:49636]   File "/usr/local/lib/python2.7/dist-packages/beaker/middleware.py", line 155, in __call__, referer: http://www.visched.local/app
[Mon Sep 08 15:46:46.405989 2014] [:error] [pid 21194] [client 127.0.0.1:49636]     return self.wrap_app(environ, session_start_response), referer: http://www.visched.local/app
[Mon Sep 08 15:46:46.405998 2014] [:error] [pid 21194] [client 127.0.0.1:49636]   File "/var/www/visched/ext/prestans/prestans/rest.py", line 642, in __call__, referer: http://www.visched.local/app
[Mon Sep 08 15:46:46.406231 2014] [:error] [pid 21194] [client 127.0.0.1:49636]     rest_handler.post(*current_request_args), referer: http://www.visched.local/app
[Mon Sep 08 15:46:46.406244 2014] [:error] [pid 21194] [client 127.0.0.1:49636]   File "/var/www/visched/ext/prestans/prestans/auth.py", line 88, in secure_http_method_handler, referer: http://www.visched.local/app
[Mon Sep 08 15:46:46.406305 2014] [:error] [pid 21194] [client 127.0.0.1:49636]     http_method_handler(self, *args), referer: http://www.visched.local/app
[Mon Sep 08 15:46:46.406316 2014] [:error] [pid 21194] [client 127.0.0.1:49636]   File "/var/www/visched/app/visched/rest/handlers/wine_rep_scheduling.py", line 1003, in post, referer: http://www.visched.local/app
[Mon Sep 08 15:46:46.406687 2014] [:error] [pid 21194] [client 127.0.0.1:49636]     self.db_session.refresh(target_week), referer: http://www.visched.local/app
[Mon Sep 08 15:46:46.406720 2014] [:error] [pid 21194] [client 127.0.0.1:49636]   File "/usr/local/lib/python2.7/dist-packages/sqlalchemy/orm/session.py", line 1251, in refresh, referer: http://www.visched.local/app
[Mon Sep 08 15:46:46.407262 2014] [:error] [pid 21194] [client 127.0.0.1:49636]     self._expire_state(state, attribute_names), referer: http://www.visched.local/app
[Mon Sep 08 15:46:46.407274 2014] [:error] [pid 21194] [client 127.0.0.1:49636]   File "/usr/local/lib/python2.7/dist-packages/sqlalchemy/orm/session.py", line 1337, in _expire_state, referer: http://www.visched.local/app
[Mon Sep 08 15:46:46.407293 2014] [:error] [pid 21194] [client 127.0.0.1:49636]     self._validate_persistent(state), referer: http://www.visched.local/app
[Mon Sep 08 15:46:46.407301 2014] [:error] [pid 21194] [client 127.0.0.1:49636]   File "/usr/local/lib/python2.7/dist-packages/sqlalchemy/orm/session.py", line 1719, in _validate_persistent, referer: http://www.visched.local/app
[Mon Sep 08 15:46:46.407315 2014] [:error] [pid 21194] [client 127.0.0.1:49636]     state_str(state)), referer: http://www.visched.local/app
[Mon Sep 08 15:46:46.407336 2014] [:error] [pid 21194] [client 127.0.0.1:49636] InvalidRequestError: Instance '<WineRepWeek at 0xb961adcc>' is not persistent within this Session, referer: http://www.visched.local/app
[Mon Sep 08 16:09:26.353845 2014] [:info] [pid 21191] [client 127.0.0.1:50100] mod_wsgi (pid=21191, process='', application='visched.local'): Loading WSGI script '/var/www/visched/app/visched.wsgi'.
[Mon Sep 08 16:09:32.885127 2014] [:info] [pid 21397] [client 127.0.0.1:50102] mod_wsgi (pid=21397, process='', application='visched.local'): Loading WSGI script '/var/www/visched/app/visched.wsgi'., referer: http://www.visched.local/app
[Mon Sep 08 16:09:32.903226 2014] [:error] [pid 21188] [client 127.0.0.1:50104] mod_wsgi (pid=21188): Exception occurred processing WSGI script '/var/www/visched/app/visched.wsgi'., referer: http://www.visched.local/app
[Mon Sep 08 16:09:32.903347 2014] [:error] [pid 21188] [client 127.0.0.1:50104] Traceback (most recent call last):, referer: http://www.visched.local/app
[Mon Sep 08 16:09:32.903370 2014] [:error] [pid 21188] [client 127.0.0.1:50104]   File "/var/www/visched/app/visched.wsgi", line 14, in application, referer: http://www.visched.local/app
[Mon Sep 08 16:09:32.903402 2014] [:error] [pid 21188] [client 127.0.0.1:50104]     import visched.page.handlers, referer: http://www.visched.local/app
[Mon Sep 08 16:09:32.903411 2014] [:error] [pid 21188] [client 127.0.0.1:50104]   File "/var/www/visched/app/visched/page/handlers.py", line 7, in <module>, referer: http://www.visched.local/app
[Mon Sep 08 16:09:32.903428 2014] [:error] [pid 21188] [client 127.0.0.1:50104]     import visched.models, referer: http://www.visched.local/app
[Mon Sep 08 16:09:32.903436 2014] [:error] [pid 21188] [client 127.0.0.1:50104]   File "/var/www/visched/app/visched/models.py", line 797, in <module>, referer: http://www.visched.local/app
[Mon Sep 08 16:09:32.903451 2014] [:error] [pid 21188] [client 127.0.0.1:50104]     Base.prepare(visched.db.engine), referer: http://www.visched.local/app
[Mon Sep 08 16:09:32.903461 2014] [:error] [pid 21188] [client 127.0.0.1:50104]   File "/usr/local/lib/python2.7/dist-packages/sqlalchemy/ext/declarative/api.py", line 478, in prepare, referer: http://www.visched.local/app
[Mon Sep 08 16:09:32.903482 2014] [:error] [pid 21188] [client 127.0.0.1:50104]     cls._sa_decl_prepare(thingy.local_table, engine), referer: http://www.visched.local/app
[Mon Sep 08 16:09:32.903491 2014] [:error] [pid 21188] [client 127.0.0.1:50104]   File "/usr/local/lib/python2.7/dist-packages/sqlalchemy/ext/declarative/api.py", line 507, in _sa_decl_prepare, referer: http://www.visched.local/app
[Mon Sep 08 16:09:32.903504 2014] [:error] [pid 21188] [client 127.0.0.1:50104]     cls._reflect_table(local_table, engine), referer: http://www.visched.local/app
[Mon Sep 08 16:09:32.903513 2014] [:error] [pid 21188] [client 127.0.0.1:50104]   File "/usr/local/lib/python2.7/dist-packages/sqlalchemy/ext/declarative/api.py", line 517, in _reflect_table, referer: http://www.visched.local/app
[Mon Sep 08 16:09:32.903544 2014] [:error] [pid 21188] [client 127.0.0.1:50104]     schema=table.schema), referer: http://www.visched.local/app
[Mon Sep 08 16:09:32.903552 2014] [:error] [pid 21188] [client 127.0.0.1:50104]   File "/usr/local/lib/python2.7/dist-packages/sqlalchemy/sql/schema.py", line 344, in __new__, referer: http://www.visched.local/app
[Mon Sep 08 16:09:32.903566 2014] [:error] [pid 21188] [client 127.0.0.1:50104]     table._init_existing(*args, **kw), referer: http://www.visched.local/app
[Mon Sep 08 16:09:32.903574 2014] [:error] [pid 21188] [client 127.0.0.1:50104]   File "/usr/local/lib/python2.7/dist-packages/sqlalchemy/sql/schema.py", line 494, in _init_existing, referer: http://www.visched.local/app
[Mon Sep 08 16:09:32.903587 2014] [:error] [pid 21188] [client 127.0.0.1:50104]     include_columns, exclude_columns), referer: http://www.visched.local/app
[Mon Sep 08 16:09:32.903595 2014] [:error] [pid 21188] [client 127.0.0.1:50104]   File "/usr/local/lib/python2.7/dist-packages/sqlalchemy/sql/schema.py", line 439, in _autoload, referer: http://www.visched.local/app
[Mon Sep 08 16:09:32.903608 2014] [:error] [pid 21188] [client 127.0.0.1:50104]     self, include_columns, exclude_columns, referer: http://www.visched.local/app
[Mon Sep 08 16:09:32.903615 2014] [:error] [pid 21188] [client 127.0.0.1:50104]   File "/usr/local/lib/python2.7/dist-packages/sqlalchemy/engine/base.py", line 1732, in run_callable, referer: http://www.visched.local/app
[Mon Sep 08 16:09:32.903629 2014] [:error] [pid 21188] [client 127.0.0.1:50104]     with self.contextual_connect() as conn:, referer: http://www.visched.local/app
[Mon Sep 08 16:09:32.903637 2014] [:error] [pid 21188] [client 127.0.0.1:50104]   File "/usr/local/lib/python2.7/dist-packages/sqlalchemy/engine/base.py", line 1799, in contextual_connect, referer: http://www.visched.local/app
[Mon Sep 08 16:09:32.903650 2014] [:error] [pid 21188] [client 127.0.0.1:50104]     self.pool.connect(),, referer: http://www.visched.local/app
[Mon Sep 08 16:09:32.903659 2014] [:error] [pid 21188] [client 127.0.0.1:50104]   File "/usr/local/lib/python2.7/dist-packages/sqlalchemy/pool.py", line 338, in connect, referer: http://www.visched.local/app
[Mon Sep 08 16:09:32.903672 2014] [:error] [pid 21188] [client 127.0.0.1:50104]     return _ConnectionFairy._checkout(self), referer: http://www.visched.local/app
[Mon Sep 08 16:09:32.903680 2014] [:error] [pid 21188] [client 127.0.0.1:50104]   File "/usr/local/lib/python2.7/dist-packages/sqlalchemy/pool.py", line 641, in _checkout, referer: http://www.visched.local/app
[Mon Sep 08 16:09:32.903692 2014] [:error] [pid 21188] [client 127.0.0.1:50104]     fairy = _ConnectionRecord.checkout(pool), referer: http://www.visched.local/app
[Mon Sep 08 16:09:32.903700 2014] [:error] [pid 21188] [client 127.0.0.1:50104]   File "/usr/local/lib/python2.7/dist-packages/sqlalchemy/pool.py", line 440, in checkout, referer: http://www.visched.local/app
[Mon Sep 08 16:09:32.903712 2014] [:error] [pid 21188] [client 127.0.0.1:50104]     rec = pool._do_get(), referer: http://www.visched.local/app
[Mon Sep 08 16:09:32.903720 2014] [:error] [pid 21188] [client 127.0.0.1:50104]   File "/usr/local/lib/python2.7/dist-packages/sqlalchemy/pool.py", line 961, in _do_get, referer: http://www.visched.local/app
[Mon Sep 08 16:09:32.903731 2014] [:error] [pid 21188] [client 127.0.0.1:50104]     return self._create_connection(), referer: http://www.visched.local/app
[Mon Sep 08 16:09:32.903739 2014] [:error] [pid 21188] [client 127.0.0.1:50104]   File "/usr/local/lib/python2.7/dist-packages/sqlalchemy/pool.py", line 285, in _create_connection, referer: http://www.visched.local/app
[Mon Sep 08 16:09:32.903751 2014] [:error] [pid 21188] [client 127.0.0.1:50104]     return _ConnectionRecord(self), referer: http://www.visched.local/app
[Mon Sep 08 16:09:32.903759 2014] [:error] [pid 21188] [client 127.0.0.1:50104]   File "/usr/local/lib/python2.7/dist-packages/sqlalchemy/pool.py", line 411, in __init__, referer: http://www.visched.local/app
[Mon Sep 08 16:09:32.903778 2014] [:error] [pid 21188] [client 127.0.0.1:50104]     self.connection = self.__connect(), referer: http://www.visched.local/app
[Mon Sep 08 16:09:32.903787 2014] [:error] [pid 21188] [client 127.0.0.1:50104]   File "/usr/local/lib/python2.7/dist-packages/sqlalchemy/pool.py", line 537, in __connect, referer: http://www.visched.local/app
[Mon Sep 08 16:09:32.903799 2014] [:error] [pid 21188] [client 127.0.0.1:50104]     connection = self.__pool._creator(), referer: http://www.visched.local/app
[Mon Sep 08 16:09:32.903807 2014] [:error] [pid 21188] [client 127.0.0.1:50104]   File "/usr/local/lib/python2.7/dist-packages/sqlalchemy/engine/strategies.py", line 96, in connect, referer: http://www.visched.local/app
[Mon Sep 08 16:09:32.903820 2014] [:error] [pid 21188] [client 127.0.0.1:50104]     connection_invalidated=invalidated, referer: http://www.visched.local/app
[Mon Sep 08 16:09:32.903828 2014] [:error] [pid 21188] [client 127.0.0.1:50104]   File "/usr/local/lib/python2.7/dist-packages/sqlalchemy/util/compat.py", line 199, in raise_from_cause, referer: http://www.visched.local/app
[Mon Sep 08 16:09:32.903842 2014] [:error] [pid 21188] [client 127.0.0.1:50104]     reraise(type(exception), exception, tb=exc_tb), referer: http://www.visched.local/app
[Mon Sep 08 16:09:32.903850 2014] [:error] [pid 21188] [client 127.0.0.1:50104]   File "/usr/local/lib/python2.7/dist-packages/sqlalchemy/engine/strategies.py", line 90, in connect, referer: http://www.visched.local/app
[Mon Sep 08 16:09:32.903862 2014] [:error] [pid 21188] [client 127.0.0.1:50104]     return dialect.connect(*cargs, **cparams), referer: http://www.visched.local/app
[Mon Sep 08 16:09:32.903871 2014] [:error] [pid 21188] [client 127.0.0.1:50104]   File "/usr/local/lib/python2.7/dist-packages/sqlalchemy/engine/default.py", line 377, in connect, referer: http://www.visched.local/app
[Mon Sep 08 16:09:32.903884 2014] [:error] [pid 21188] [client 127.0.0.1:50104]     return self.dbapi.connect(*cargs, **cparams), referer: http://www.visched.local/app
[Mon Sep 08 16:09:32.903893 2014] [:error] [pid 21188] [client 127.0.0.1:50104]   File "/usr/lib/python2.7/dist-packages/MySQLdb/__init__.py", line 81, in Connect, referer: http://www.visched.local/app
[Mon Sep 08 16:09:32.903911 2014] [:error] [pid 21188] [client 127.0.0.1:50104]     return Connection(*args, **kwargs), referer: http://www.visched.local/app
[Mon Sep 08 16:09:32.903920 2014] [:error] [pid 21188] [client 127.0.0.1:50104]   File "/usr/lib/python2.7/dist-packages/MySQLdb/connections.py", line 187, in __init__, referer: http://www.visched.local/app
[Mon Sep 08 16:09:32.903934 2014] [:error] [pid 21188] [client 127.0.0.1:50104]     super(Connection, self).__init__(*args, **kwargs2), referer: http://www.visched.local/app
[Mon Sep 08 16:09:32.903974 2014] [:error] [pid 21188] [client 127.0.0.1:50104] OperationalError: (OperationalError) (1045, "Access denied for user 'root'@'localhost' (using password: YES)") None None, referer: http://www.visched.local/app
[Mon Sep 08 16:14:14.256156 2014] [:info] [pid 22194] [client 127.0.0.1:50345] mod_wsgi (pid=22194, process='', application='visched.local'): Loading WSGI script '/var/www/visched/app/visched.wsgi'., referer: http://www.visched.local/app
[Mon Sep 08 16:14:14.279536 2014] [:error] [pid 21188] [client 127.0.0.1:50343] mod_wsgi (pid=21188): Exception occurred processing WSGI script '/var/www/visched/app/visched.wsgi'., referer: http://www.visched.local/app
[Mon Sep 08 16:14:14.279632 2014] [:error] [pid 21188] [client 127.0.0.1:50343] Traceback (most recent call last):, referer: http://www.visched.local/app
[Mon Sep 08 16:14:14.279662 2014] [:error] [pid 21188] [client 127.0.0.1:50343]   File "/var/www/visched/app/visched.wsgi", line 14, in application, referer: http://www.visched.local/app
[Mon Sep 08 16:14:14.279709 2014] [:error] [pid 21188] [client 127.0.0.1:50343]     import visched.page.handlers, referer: http://www.visched.local/app
[Mon Sep 08 16:14:14.279738 2014] [:error] [pid 21188] [client 127.0.0.1:50343]   File "/var/www/visched/app/visched/page/handlers.py", line 7, in <module>, referer: http://www.visched.local/app
[Mon Sep 08 16:14:14.279756 2014] [:error] [pid 21188] [client 127.0.0.1:50343]     import visched.models, referer: http://www.visched.local/app
[Mon Sep 08 16:14:14.279765 2014] [:error] [pid 21188] [client 127.0.0.1:50343]   File "/var/www/visched/app/visched/models.py", line 797, in <module>, referer: http://www.visched.local/app
[Mon Sep 08 16:14:14.279780 2014] [:error] [pid 21188] [client 127.0.0.1:50343]     Base.prepare(visched.db.engine), referer: http://www.visched.local/app
[Mon Sep 08 16:14:14.279789 2014] [:error] [pid 21188] [client 127.0.0.1:50343]   File "/usr/local/lib/python2.7/dist-packages/sqlalchemy/ext/declarative/api.py", line 478, in prepare, referer: http://www.visched.local/app
[Mon Sep 08 16:14:14.279807 2014] [:error] [pid 21188] [client 127.0.0.1:50343]     cls._sa_decl_prepare(thingy.local_table, engine), referer: http://www.visched.local/app
[Mon Sep 08 16:14:14.279815 2014] [:error] [pid 21188] [client 127.0.0.1:50343]   File "/usr/local/lib/python2.7/dist-packages/sqlalchemy/ext/declarative/api.py", line 507, in _sa_decl_prepare, referer: http://www.visched.local/app
[Mon Sep 08 16:14:14.279828 2014] [:error] [pid 21188] [client 127.0.0.1:50343]     cls._reflect_table(local_table, engine), referer: http://www.visched.local/app
[Mon Sep 08 16:14:14.279836 2014] [:error] [pid 21188] [client 127.0.0.1:50343]   File "/usr/local/lib/python2.7/dist-packages/sqlalchemy/ext/declarative/api.py", line 517, in _reflect_table, referer: http://www.visched.local/app
[Mon Sep 08 16:14:14.279848 2014] [:error] [pid 21188] [client 127.0.0.1:50343]     schema=table.schema), referer: http://www.visched.local/app
[Mon Sep 08 16:14:14.279857 2014] [:error] [pid 21188] [client 127.0.0.1:50343]   File "/usr/local/lib/python2.7/dist-packages/sqlalchemy/sql/schema.py", line 344, in __new__, referer: http://www.visched.local/app
[Mon Sep 08 16:14:14.279871 2014] [:error] [pid 21188] [client 127.0.0.1:50343]     table._init_existing(*args, **kw), referer: http://www.visched.local/app
[Mon Sep 08 16:14:14.279881 2014] [:error] [pid 21188] [client 127.0.0.1:50343]   File "/usr/local/lib/python2.7/dist-packages/sqlalchemy/sql/schema.py", line 494, in _init_existing, referer: http://www.visched.local/app
[Mon Sep 08 16:14:14.279893 2014] [:error] [pid 21188] [client 127.0.0.1:50343]     include_columns, exclude_columns), referer: http://www.visched.local/app
[Mon Sep 08 16:14:14.279901 2014] [:error] [pid 21188] [client 127.0.0.1:50343]   File "/usr/local/lib/python2.7/dist-packages/sqlalchemy/sql/schema.py", line 439, in _autoload, referer: http://www.visched.local/app
[Mon Sep 08 16:14:14.279913 2014] [:error] [pid 21188] [client 127.0.0.1:50343]     self, include_columns, exclude_columns, referer: http://www.visched.local/app
[Mon Sep 08 16:14:14.279922 2014] [:error] [pid 21188] [client 127.0.0.1:50343]   File "/usr/local/lib/python2.7/dist-packages/sqlalchemy/engine/base.py", line 1732, in run_callable, referer: http://www.visched.local/app
[Mon Sep 08 16:14:14.279936 2014] [:error] [pid 21188] [client 127.0.0.1:50343]     with self.contextual_connect() as conn:, referer: http://www.visched.local/app
[Mon Sep 08 16:14:14.279945 2014] [:error] [pid 21188] [client 127.0.0.1:50343]   File "/usr/local/lib/python2.7/dist-packages/sqlalchemy/engine/base.py", line 1799, in contextual_connect, referer: http://www.visched.local/app
[Mon Sep 08 16:14:14.279957 2014] [:error] [pid 21188] [client 127.0.0.1:50343]     self.pool.connect(),, referer: http://www.visched.local/app
[Mon Sep 08 16:14:14.279967 2014] [:error] [pid 21188] [client 127.0.0.1:50343]   File "/usr/local/lib/python2.7/dist-packages/sqlalchemy/pool.py", line 338, in connect, referer: http://www.visched.local/app
[Mon Sep 08 16:14:14.279980 2014] [:error] [pid 21188] [client 127.0.0.1:50343]     return _ConnectionFairy._checkout(self), referer: http://www.visched.local/app
[Mon Sep 08 16:14:14.279994 2014] [:error] [pid 21188] [client 127.0.0.1:50343]   File "/usr/local/lib/python2.7/dist-packages/sqlalchemy/pool.py", line 641, in _checkout, referer: http://www.visched.local/app
[Mon Sep 08 16:14:14.280007 2014] [:error] [pid 21188] [client 127.0.0.1:50343]     fairy = _ConnectionRecord.checkout(pool), referer: http://www.visched.local/app
[Mon Sep 08 16:14:14.280015 2014] [:error] [pid 21188] [client 127.0.0.1:50343]   File "/usr/local/lib/python2.7/dist-packages/sqlalchemy/pool.py", line 440, in checkout, referer: http://www.visched.local/app
[Mon Sep 08 16:14:14.280027 2014] [:error] [pid 21188] [client 127.0.0.1:50343]     rec = pool._do_get(), referer: http://www.visched.local/app
[Mon Sep 08 16:14:14.280035 2014] [:error] [pid 21188] [client 127.0.0.1:50343]   File "/usr/local/lib/python2.7/dist-packages/sqlalchemy/pool.py", line 961, in _do_get, referer: http://www.visched.local/app
[Mon Sep 08 16:14:14.280046 2014] [:error] [pid 21188] [client 127.0.0.1:50343]     return self._create_connection(), referer: http://www.visched.local/app
[Mon Sep 08 16:14:14.280054 2014] [:error] [pid 21188] [client 127.0.0.1:50343]   File "/usr/local/lib/python2.7/dist-packages/sqlalchemy/pool.py", line 285, in _create_connection, referer: http://www.visched.local/app
[Mon Sep 08 16:14:14.280066 2014] [:error] [pid 21188] [client 127.0.0.1:50343]     return _ConnectionRecord(self), referer: http://www.visched.local/app
[Mon Sep 08 16:14:14.280075 2014] [:error] [pid 21188] [client 127.0.0.1:50343]   File "/usr/local/lib/python2.7/dist-packages/sqlalchemy/pool.py", line 411, in __init__, referer: http://www.visched.local/app
[Mon Sep 08 16:14:14.280087 2014] [:error] [pid 21188] [client 127.0.0.1:50343]     self.connection = self.__connect(), referer: http://www.visched.local/app
[Mon Sep 08 16:14:14.280095 2014] [:error] [pid 21188] [client 127.0.0.1:50343]   File "/usr/local/lib/python2.7/dist-packages/sqlalchemy/pool.py", line 537, in __connect, referer: http://www.visched.local/app
[Mon Sep 08 16:14:14.280107 2014] [:error] [pid 21188] [client 127.0.0.1:50343]     connection = self.__pool._creator(), referer: http://www.visched.local/app
[Mon Sep 08 16:14:14.280116 2014] [:error] [pid 21188] [client 127.0.0.1:50343]   File "/usr/local/lib/python2.7/dist-packages/sqlalchemy/engine/strategies.py", line 96, in connect, referer: http://www.visched.local/app
[Mon Sep 08 16:14:14.280130 2014] [:error] [pid 21188] [client 127.0.0.1:50343]     connection_invalidated=invalidated, referer: http://www.visched.local/app
[Mon Sep 08 16:14:14.281283 2014] [:error] [pid 21188] [client 127.0.0.1:50343]   File "/usr/local/lib/python2.7/dist-packages/sqlalchemy/util/compat.py", line 199, in raise_from_cause, referer: http://www.visched.local/app
[Mon Sep 08 16:14:14.281413 2014] [:error] [pid 21188] [client 127.0.0.1:50343]     reraise(type(exception), exception, tb=exc_tb), referer: http://www.visched.local/app
[Mon Sep 08 16:14:14.281438 2014] [:error] [pid 21188] [client 127.0.0.1:50343]   File "/usr/local/lib/python2.7/dist-packages/sqlalchemy/engine/strategies.py", line 90, in connect, referer: http://www.visched.local/app
[Mon Sep 08 16:14:14.281454 2014] [:error] [pid 21188] [client 127.0.0.1:50343]     return dialect.connect(*cargs, **cparams), referer: http://www.visched.local/app
[Mon Sep 08 16:14:14.281464 2014] [:error] [pid 21188] [client 127.0.0.1:50343]   File "/usr/local/lib/python2.7/dist-packages/sqlalchemy/engine/default.py", line 377, in connect, referer: http://www.visched.local/app
[Mon Sep 08 16:14:14.281479 2014] [:error] [pid 21188] [client 127.0.0.1:50343]     return self.dbapi.connect(*cargs, **cparams), referer: http://www.visched.local/app
[Mon Sep 08 16:14:14.281489 2014] [:error] [pid 21188] [client 127.0.0.1:50343]   File "/usr/lib/python2.7/dist-packages/MySQLdb/__init__.py", line 81, in Connect, referer: http://www.visched.local/app
[Mon Sep 08 16:14:14.281513 2014] [:error] [pid 21188] [client 127.0.0.1:50343]     return Connection(*args, **kwargs), referer: http://www.visched.local/app
[Mon Sep 08 16:14:14.281542 2014] [:error] [pid 21188] [client 127.0.0.1:50343]   File "/usr/lib/python2.7/dist-packages/MySQLdb/connections.py", line 187, in __init__, referer: http://www.visched.local/app
[Mon Sep 08 16:14:14.281559 2014] [:error] [pid 21188] [client 127.0.0.1:50343]     super(Connection, self).__init__(*args, **kwargs2), referer: http://www.visched.local/app
[Mon Sep 08 16:14:14.281700 2014] [:error] [pid 21188] [client 127.0.0.1:50343] OperationalError: (OperationalError) (1045, "Access denied for user 'root'@'localhost' (using password: YES)") None None, referer: http://www.visched.local/app
[Mon Sep 08 16:19:08.477588 2014] [:info] [pid 22526] [client 127.0.0.1:50431] mod_wsgi (pid=22526, process='', application='visched.local'): Loading WSGI script '/var/www/visched/app/visched.wsgi'., referer: http://www.visched.local/
[Mon Sep 08 16:19:09.165404 2014] [:info] [pid 22535] [client 127.0.0.1:50432] mod_wsgi (pid=22535, process='', application='visched.local'): Loading WSGI script '/var/www/visched/app/visched.wsgi'., referer: http://www.visched.local/app
[Mon Sep 08 16:19:09.213030 2014] [:info] [pid 22534] [client 127.0.0.1:50433] mod_wsgi (pid=22534, process='', application='visched.local'): Loading WSGI script '/var/www/visched/app/visched.wsgi'., referer: http://www.visched.local/app
[Mon Sep 08 16:19:09.224194 2014] [:info] [pid 22533] [client 127.0.0.1:50435] mod_wsgi (pid=22533, process='', application='visched.local'): Loading WSGI script '/var/www/visched/app/visched.wsgi'., referer: http://www.visched.local/app
[Mon Sep 08 16:19:09.224992 2014] [:info] [pid 22528] [client 127.0.0.1:50434] mod_wsgi (pid=22528, process='', application='visched.local'): Loading WSGI script '/var/www/visched/app/visched.wsgi'., referer: http://www.visched.local/app
[Mon Sep 08 16:19:14.535010 2014] [:info] [pid 22527] [client 127.0.0.1:50436] mod_wsgi (pid=22527, process='', application='visched.local'): Loading WSGI script '/var/www/visched/app/api.wsgi'., referer: http://www.visched.local/app
[Mon Sep 08 16:19:14.535876 2014] [:info] [pid 22528] [client 127.0.0.1:50434] mod_wsgi (pid=22528, process='', application='visched.local'): Loading WSGI script '/var/www/visched/app/api.wsgi'., referer: http://www.visched.local/app
[Mon Sep 08 16:37:25.511039 2014] [:info] [pid 22529] [client 127.0.0.1:50940] mod_wsgi (pid=22529, process='', application='visched.local'): Loading WSGI script '/var/www/visched/app/visched.wsgi'.
[Mon Sep 08 16:37:30.773037 2014] [:info] [pid 22534] [client 127.0.0.1:50945] mod_wsgi (pid=22534, process='', application='visched.local'): Loading WSGI script '/var/www/visched/app/api.wsgi'., referer: http://www.visched.local/app
[Mon Sep 08 16:37:30.790309 2014] [:info] [pid 22529] [client 127.0.0.1:50940] mod_wsgi (pid=22529, process='', application='visched.local'): Loading WSGI script '/var/www/visched/app/api.wsgi'., referer: http://www.visched.local/app
[Mon Sep 08 17:05:25.736144 2014] [:info] [pid 22526] [client 127.0.0.1:51596] mod_wsgi (pid=22526, process='', application='visched.local'): Loading WSGI script '/var/www/visched/app/api.wsgi'., referer: http://www.visched.local/app
[Mon Sep 08 17:05:25.852127 2014] [:error] [pid 22526] [client 127.0.0.1:51596] mod_wsgi (pid=22526): Exception occurred processing WSGI script '/var/www/visched/app/api.wsgi'., referer: http://www.visched.local/app
[Mon Sep 08 17:05:25.852223 2014] [:error] [pid 22526] [client 127.0.0.1:51596] Traceback (most recent call last):, referer: http://www.visched.local/app
[Mon Sep 08 17:05:25.852260 2014] [:error] [pid 22526] [client 127.0.0.1:51596]   File "/var/www/visched/app/api.wsgi", line 107, in application, referer: http://www.visched.local/app
[Mon Sep 08 17:05:25.852431 2014] [:error] [pid 22526] [client 127.0.0.1:51596]     return _session_wrapped_app(environ, start_response), referer: http://www.visched.local/app
[Mon Sep 08 17:05:25.852448 2014] [:error] [pid 22526] [client 127.0.0.1:51596]   File "/usr/local/lib/python2.7/dist-packages/beaker/middleware.py", line 155, in __call__, referer: http://www.visched.local/app
[Mon Sep 08 17:05:25.852573 2014] [:error] [pid 22526] [client 127.0.0.1:51596]     return self.wrap_app(environ, session_start_response), referer: http://www.visched.local/app
[Mon Sep 08 17:05:25.852588 2014] [:error] [pid 22526] [client 127.0.0.1:51596]   File "/var/www/visched/ext/prestans/prestans/rest.py", line 651, in __call__, referer: http://www.visched.local/app
[Mon Sep 08 17:05:25.852887 2014] [:error] [pid 22526] [client 127.0.0.1:51596]     rest_handler.put(*current_request_args), referer: http://www.visched.local/app
[Mon Sep 08 17:05:25.852902 2014] [:error] [pid 22526] [client 127.0.0.1:51596]   File "/var/www/visched/ext/prestans/prestans/auth.py", line 88, in secure_http_method_handler, referer: http://www.visched.local/app
[Mon Sep 08 17:05:25.852989 2014] [:error] [pid 22526] [client 127.0.0.1:51596]     http_method_handler(self, *args), referer: http://www.visched.local/app
[Mon Sep 08 17:05:25.853003 2014] [:error] [pid 22526] [client 127.0.0.1:51596]   File "/var/www/visched/app/visched/rest/handlers/wine_rep_scheduling.py", line 1140, in put, referer: http://www.visched.local/app
[Mon Sep 08 17:05:25.853520 2014] [:error] [pid 22526] [client 127.0.0.1:51596]     self.calculate_times_for_week(wine_type_group.wine_rep_week), referer: http://www.visched.local/app
[Mon Sep 08 17:05:25.853536 2014] [:error] [pid 22526] [client 127.0.0.1:51596]   File "/usr/local/lib/python2.7/dist-packages/sqlalchemy/orm/attributes.py", line 239, in __get__, referer: http://www.visched.local/app
[Mon Sep 08 17:05:25.854034 2014] [:error] [pid 22526] [client 127.0.0.1:51596]     return self.impl.get(instance_state(instance), dict_), referer: http://www.visched.local/app
[Mon Sep 08 17:05:25.854049 2014] [:error] [pid 22526] [client 127.0.0.1:51596]   File "/usr/local/lib/python2.7/dist-packages/sqlalchemy/orm/attributes.py", line 591, in get, referer: http://www.visched.local/app
[Mon Sep 08 17:05:25.854075 2014] [:error] [pid 22526] [client 127.0.0.1:51596]     value = self.callable_(state, passive), referer: http://www.visched.local/app
[Mon Sep 08 17:05:25.854088 2014] [:error] [pid 22526] [client 127.0.0.1:51596]   File "/usr/local/lib/python2.7/dist-packages/sqlalchemy/orm/strategies.py", line 534, in _load_for_state, referer: http://www.visched.local/app
[Mon Sep 08 17:05:25.855259 2014] [:error] [pid 22526] [client 127.0.0.1:51596]     return self._emit_lazyload(session, state, ident_key, passive), referer: http://www.visched.local/app
[Mon Sep 08 17:05:25.855304 2014] [:error] [pid 22526] [client 127.0.0.1:51596]   File "<string>", line 1, in <lambda>, referer: http://www.visched.local/app
[Mon Sep 08 17:05:25.855349 2014] [:error] [pid 22526] [client 127.0.0.1:51596]   File "/usr/local/lib/python2.7/dist-packages/sqlalchemy/orm/strategies.py", line 579, in _emit_lazyload, referer: http://www.visched.local/app
[Mon Sep 08 17:05:25.855405 2014] [:error] [pid 22526] [client 127.0.0.1:51596]     return loading.load_on_ident(q, ident_key), referer: http://www.visched.local/app
[Mon Sep 08 17:05:25.855437 2014] [:error] [pid 22526] [client 127.0.0.1:51596]   File "/usr/local/lib/python2.7/dist-packages/sqlalchemy/orm/loading.py", line 231, in load_on_ident, referer: http://www.visched.local/app
[Mon Sep 08 17:05:25.856002 2014] [:error] [pid 22526] [client 127.0.0.1:51596]     return q.one(), referer: http://www.visched.local/app
[Mon Sep 08 17:05:25.856040 2014] [:error] [pid 22526] [client 127.0.0.1:51596]   File "/usr/local/lib/python2.7/dist-packages/sqlalchemy/orm/query.py", line 2369, in one, referer: http://www.visched.local/app
[Mon Sep 08 17:05:25.858873 2014] [:error] [pid 22526] [client 127.0.0.1:51596]     ret = list(self), referer: http://www.visched.local/app
[Mon Sep 08 17:05:25.858915 2014] [:error] [pid 22526] [client 127.0.0.1:51596]   File "/usr/local/lib/python2.7/dist-packages/sqlalchemy/orm/query.py", line 2411, in __iter__, referer: http://www.visched.local/app
[Mon Sep 08 17:05:25.858972 2014] [:error] [pid 22526] [client 127.0.0.1:51596]     self.session._autoflush(), referer: http://www.visched.local/app
[Mon Sep 08 17:05:25.859027 2014] [:error] [pid 22526] [client 127.0.0.1:51596]   File "/usr/local/lib/python2.7/dist-packages/sqlalchemy/orm/session.py", line 1208, in _autoflush, referer: http://www.visched.local/app
[Mon Sep 08 17:05:25.861140 2014] [:error] [pid 22526] [client 127.0.0.1:51596]     util.raise_from_cause(e), referer: http://www.visched.local/app
[Mon Sep 08 17:05:25.861179 2014] [:error] [pid 22526] [client 127.0.0.1:51596]   File "/usr/local/lib/python2.7/dist-packages/sqlalchemy/util/compat.py", line 199, in raise_from_cause, referer: http://www.visched.local/app
[Mon Sep 08 17:05:25.861418 2014] [:error] [pid 22526] [client 127.0.0.1:51596]     reraise(type(exception), exception, tb=exc_tb), referer: http://www.visched.local/app
[Mon Sep 08 17:05:25.861453 2014] [:error] [pid 22526] [client 127.0.0.1:51596]   File "/usr/local/lib/python2.7/dist-packages/sqlalchemy/orm/session.py", line 1198, in _autoflush, referer: http://www.visched.local/app
[Mon Sep 08 17:05:25.861505 2014] [:error] [pid 22526] [client 127.0.0.1:51596]     self.flush(), referer: http://www.visched.local/app
[Mon Sep 08 17:05:25.861537 2014] [:error] [pid 22526] [client 127.0.0.1:51596]   File "/usr/local/lib/python2.7/dist-packages/sqlalchemy/orm/session.py", line 1919, in flush, referer: http://www.visched.local/app
[Mon Sep 08 17:05:25.861586 2014] [:error] [pid 22526] [client 127.0.0.1:51596]     self._flush(objects), referer: http://www.visched.local/app
[Mon Sep 08 17:05:25.861618 2014] [:error] [pid 22526] [client 127.0.0.1:51596]   File "/usr/local/lib/python2.7/dist-packages/sqlalchemy/orm/session.py", line 2037, in _flush, referer: http://www.visched.local/app
[Mon Sep 08 17:05:25.861668 2014] [:error] [pid 22526] [client 127.0.0.1:51596]     transaction.rollback(_capture_exception=True), referer: http://www.visched.local/app
[Mon Sep 08 17:05:25.861700 2014] [:error] [pid 22526] [client 127.0.0.1:51596]   File "/usr/local/lib/python2.7/dist-packages/sqlalchemy/util/langhelpers.py", line 60, in __exit__, referer: http://www.visched.local/app
[Mon Sep 08 17:05:25.862732 2014] [:error] [pid 22526] [client 127.0.0.1:51596]     compat.reraise(exc_type, exc_value, exc_tb), referer: http://www.visched.local/app
[Mon Sep 08 17:05:25.862787 2014] [:error] [pid 22526] [client 127.0.0.1:51596]   File "/usr/local/lib/python2.7/dist-packages/sqlalchemy/orm/session.py", line 2001, in _flush, referer: http://www.visched.local/app
[Mon Sep 08 17:05:25.862843 2014] [:error] [pid 22526] [client 127.0.0.1:51596]     flush_context.execute(), referer: http://www.visched.local/app
[Mon Sep 08 17:05:25.862876 2014] [:error] [pid 22526] [client 127.0.0.1:51596]   File "/usr/local/lib/python2.7/dist-packages/sqlalchemy/orm/unitofwork.py", line 372, in execute, referer: http://www.visched.local/app
[Mon Sep 08 17:05:25.863489 2014] [:error] [pid 22526] [client 127.0.0.1:51596]     rec.execute(self), referer: http://www.visched.local/app
[Mon Sep 08 17:05:25.863526 2014] [:error] [pid 22526] [client 127.0.0.1:51596]   File "/usr/local/lib/python2.7/dist-packages/sqlalchemy/orm/unitofwork.py", line 526, in execute, referer: http://www.visched.local/app
[Mon Sep 08 17:05:25.863579 2014] [:error] [pid 22526] [client 127.0.0.1:51596]     uow, referer: http://www.visched.local/app
[Mon Sep 08 17:05:25.863610 2014] [:error] [pid 22526] [client 127.0.0.1:51596]   File "/usr/local/lib/python2.7/dist-packages/sqlalchemy/orm/persistence.py", line 65, in save_obj, referer: http://www.visched.local/app
[Mon Sep 08 17:05:25.864595 2014] [:error] [pid 22526] [client 127.0.0.1:51596]     mapper, table, insert), referer: http://www.visched.local/app
[Mon Sep 08 17:05:25.864632 2014] [:error] [pid 22526] [client 127.0.0.1:51596]   File "/usr/local/lib/python2.7/dist-packages/sqlalchemy/orm/persistence.py", line 602, in _emit_insert_statements, referer: http://www.visched.local/app
[Mon Sep 08 17:05:25.864687 2014] [:error] [pid 22526] [client 127.0.0.1:51596]     execute(statement, params), referer: http://www.visched.local/app
[Mon Sep 08 17:05:25.864737 2014] [:error] [pid 22526] [client 127.0.0.1:51596]   File "/usr/local/lib/python2.7/dist-packages/sqlalchemy/engine/base.py", line 729, in execute, referer: http://www.visched.local/app
[Mon Sep 08 17:05:25.866396 2014] [:error] [pid 22526] [client 127.0.0.1:51596]     return meth(self, multiparams, params), referer: http://www.visched.local/app
[Mon Sep 08 17:05:25.866439 2014] [:error] [pid 22526] [client 127.0.0.1:51596]   File "/usr/local/lib/python2.7/dist-packages/sqlalchemy/sql/elements.py", line 321, in _execute_on_connection, referer: http://www.visched.local/app
[Mon Sep 08 17:05:25.867193 2014] [:error] [pid 22526] [client 127.0.0.1:51596]     return connection._execute_clauseelement(self, multiparams, params), referer: http://www.visched.local/app
[Mon Sep 08 17:05:25.867205 2014] [:error] [pid 22526] [client 127.0.0.1:51596]   File "/usr/local/lib/python2.7/dist-packages/sqlalchemy/engine/base.py", line 826, in _execute_clauseelement, referer: http://www.visched.local/app
[Mon Sep 08 17:05:25.867225 2014] [:error] [pid 22526] [client 127.0.0.1:51596]     compiled_sql, distilled_params, referer: http://www.visched.local/app
[Mon Sep 08 17:05:25.867235 2014] [:error] [pid 22526] [client 127.0.0.1:51596]   File "/usr/local/lib/python2.7/dist-packages/sqlalchemy/engine/base.py", line 958, in _execute_context, referer: http://www.visched.local/app
[Mon Sep 08 17:05:25.867247 2014] [:error] [pid 22526] [client 127.0.0.1:51596]     context), referer: http://www.visched.local/app
[Mon Sep 08 17:05:25.867256 2014] [:error] [pid 22526] [client 127.0.0.1:51596]   File "/usr/local/lib/python2.7/dist-packages/sqlalchemy/engine/base.py", line 1160, in _handle_dbapi_exception, referer: http://www.visched.local/app
[Mon Sep 08 17:05:25.867268 2014] [:error] [pid 22526] [client 127.0.0.1:51596]     exc_info, referer: http://www.visched.local/app
[Mon Sep 08 17:05:25.867276 2014] [:error] [pid 22526] [client 127.0.0.1:51596]   File "/usr/local/lib/python2.7/dist-packages/sqlalchemy/util/compat.py", line 199, in raise_from_cause, referer: http://www.visched.local/app
[Mon Sep 08 17:05:25.867290 2014] [:error] [pid 22526] [client 127.0.0.1:51596]     reraise(type(exception), exception, tb=exc_tb), referer: http://www.visched.local/app
[Mon Sep 08 17:05:25.867298 2014] [:error] [pid 22526] [client 127.0.0.1:51596]   File "/usr/local/lib/python2.7/dist-packages/sqlalchemy/engine/base.py", line 951, in _execute_context, referer: http://www.visched.local/app
[Mon Sep 08 17:05:25.867310 2014] [:error] [pid 22526] [client 127.0.0.1:51596]     context), referer: http://www.visched.local/app
[Mon Sep 08 17:05:25.867318 2014] [:error] [pid 22526] [client 127.0.0.1:51596]   File "/usr/local/lib/python2.7/dist-packages/sqlalchemy/engine/default.py", line 436, in do_execute, referer: http://www.visched.local/app
[Mon Sep 08 17:05:25.867544 2014] [:error] [pid 22526] [client 127.0.0.1:51596]     cursor.execute(statement, parameters), referer: http://www.visched.local/app
[Mon Sep 08 17:05:25.867555 2014] [:error] [pid 22526] [client 127.0.0.1:51596]   File "/usr/lib/python2.7/dist-packages/MySQLdb/cursors.py", line 174, in execute, referer: http://www.visched.local/app
[Mon Sep 08 17:05:25.867690 2014] [:error] [pid 22526] [client 127.0.0.1:51596]     self.errorhandler(self, exc, value), referer: http://www.visched.local/app
[Mon Sep 08 17:05:25.867701 2014] [:error] [pid 22526] [client 127.0.0.1:51596]   File "/usr/lib/python2.7/dist-packages/MySQLdb/connections.py", line 36, in defaulterrorhandler, referer: http://www.visched.local/app
[Mon Sep 08 17:05:25.867803 2014] [:error] [pid 22526] [client 127.0.0.1:51596]     raise errorclass, errorvalue, referer: http://www.visched.local/app
[Mon Sep 08 17:05:25.867890 2014] [:error] [pid 22526] [client 127.0.0.1:51596] OperationalError: (raised as a result of Query-invoked autoflush; consider using a session.no_autoflush block if this flush is occurring prematurely) (OperationalError) (1449, "The user specified as a definer ('root'@'%') does not exist") 'INSERT INTO wine_rep_item (wine_rep_group_id, priority, start_datetime, end_datetime, downtime_description, is_comment, comment_text) VALUES (%s, %s, %s, %s, %s, %s, %s)' (149L, 3L, datetime.datetime(2013, 7, 1, 7, 40), None, None, True, '\\xd0\\xa4\\xd0\\xb4\\xd1\\x84\\xd0\\xba\\xd1\\x8c'), referer: http://www.visched.local/app
[Mon Sep 08 19:15:26.428027 2014] [:info] [pid 22527] [client 127.0.0.1:54798] mod_wsgi (pid=22527, process='', application='visched.local'): Loading WSGI script '/var/www/visched/app/visched.wsgi'.
[Mon Sep 08 19:33:17.114817 2014] [:info] [pid 28630] [client 127.0.0.1:55207] mod_wsgi (pid=28630, process='', application='visched.local'): Loading WSGI script '/var/www/visched/app/visched.wsgi'.
[Mon Sep 08 19:33:18.000860 2014] [:info] [pid 28628] [client 127.0.0.1:55208] mod_wsgi (pid=28628, process='', application='visched.local'): Loading WSGI script '/var/www/visched/app/visched.wsgi'., referer: http://www.visched.local/app
[Mon Sep 08 19:33:18.006013 2014] [:info] [pid 28631] [client 127.0.0.1:55211] mod_wsgi (pid=28631, process='', application='visched.local'): Loading WSGI script '/var/www/visched/app/visched.wsgi'., referer: http://www.visched.local/app
[Mon Sep 08 19:33:18.009539 2014] [:info] [pid 28629] [client 127.0.0.1:55210] mod_wsgi (pid=28629, process='', application='visched.local'): Loading WSGI script '/var/www/visched/app/visched.wsgi'., referer: http://www.visched.local/app
[Mon Sep 08 19:33:18.028813 2014] [:info] [pid 28632] [client 127.0.0.1:55209] mod_wsgi (pid=28632, process='', application='visched.local'): Loading WSGI script '/var/www/visched/app/visched.wsgi'., referer: http://www.visched.local/app
[Mon Sep 08 19:33:23.074610 2014] [:info] [pid 28629] [client 127.0.0.1:55210] mod_wsgi (pid=28629, process='', application='visched.local'): Loading WSGI script '/var/www/visched/app/api.wsgi'., referer: http://www.visched.local/app
[Mon Sep 08 19:33:23.089488 2014] [:info] [pid 28631] [client 127.0.0.1:55211] mod_wsgi (pid=28631, process='', application='visched.local'): Loading WSGI script '/var/www/visched/app/api.wsgi'., referer: http://www.visched.local/app
[Tue Sep 09 12:48:35.014534 2014] [:info] [pid 1143] [client 127.0.0.1:58333] mod_wsgi (pid=1143, process='', application='visched.local'): Loading WSGI script '/var/www/visched/app/visched.wsgi'.
[Tue Sep 09 12:48:35.958787 2014] [:error] [pid 1143] [client 127.0.0.1:58333] mod_wsgi (pid=1143): Exception occurred processing WSGI script '/var/www/visched/app/visched.wsgi'.
[Tue Sep 09 12:48:35.958902 2014] [:error] [pid 1143] [client 127.0.0.1:58333] Traceback (most recent call last):
[Tue Sep 09 12:48:35.958974 2014] [:error] [pid 1143] [client 127.0.0.1:58333]   File "/var/www/visched/app/visched.wsgi", line 12, in application
[Tue Sep 09 12:48:35.959182 2014] [:error] [pid 1143] [client 127.0.0.1:58333]     from visched import config
[Tue Sep 09 12:48:35.959246 2014] [:error] [pid 1143] [client 127.0.0.1:58333] ImportError: No module named visched
[Tue Sep 09 12:49:09.950879 2014] [:info] [pid 4405] [client 127.0.0.1:58339] mod_wsgi (pid=4405, process='', application='visched.local'): Loading WSGI script '/var/www/visched/app/visched.wsgi'.
[Tue Sep 09 12:49:10.048948 2014] [:error] [pid 4405] [client 127.0.0.1:58339] mod_wsgi (pid=4405): Exception occurred processing WSGI script '/var/www/visched/app/visched.wsgi'.
[Tue Sep 09 12:49:10.049082 2014] [:error] [pid 4405] [client 127.0.0.1:58339] Traceback (most recent call last):
[Tue Sep 09 12:49:10.049146 2014] [:error] [pid 4405] [client 127.0.0.1:58339]   File "/var/www/visched/app/visched.wsgi", line 12, in application
[Tue Sep 09 12:49:10.049356 2014] [:error] [pid 4405] [client 127.0.0.1:58339]     from visched import config
[Tue Sep 09 12:49:10.049419 2014] [:error] [pid 4405] [client 127.0.0.1:58339] ImportError: No module named visched
[Tue Sep 09 12:49:13.752423 2014] [:info] [pid 4412] [client 127.0.0.1:58340] mod_wsgi (pid=4412, process='', application='visched.local'): Loading WSGI script '/var/www/visched/app/visched.wsgi'.
[Tue Sep 09 12:49:13.848613 2014] [:error] [pid 4412] [client 127.0.0.1:58340] mod_wsgi (pid=4412): Exception occurred processing WSGI script '/var/www/visched/app/visched.wsgi'.
[Tue Sep 09 12:49:13.848759 2014] [:error] [pid 4412] [client 127.0.0.1:58340] Traceback (most recent call last):
[Tue Sep 09 12:49:13.848829 2014] [:error] [pid 4412] [client 127.0.0.1:58340]   File "/var/www/visched/app/visched.wsgi", line 12, in application
[Tue Sep 09 12:49:13.849049 2014] [:error] [pid 4412] [client 127.0.0.1:58340]     from visched import config
[Tue Sep 09 12:49:13.849114 2014] [:error] [pid 4412] [client 127.0.0.1:58340] ImportError: No module named visched
[Tue Sep 09 12:52:53.656396 2014] [:info] [pid 4794] [client 127.0.0.1:58402] mod_wsgi (pid=4794, process='', application='visched.local'): Loading WSGI script '/var/www/visched/app/visched.wsgi'.
[Tue Sep 09 12:52:53.753408 2014] [:error] [pid 4794] [client 127.0.0.1:58402] mod_wsgi (pid=4794): Exception occurred processing WSGI script '/var/www/visched/app/visched.wsgi'.
[Tue Sep 09 12:52:53.753516 2014] [:error] [pid 4794] [client 127.0.0.1:58402] Traceback (most recent call last):
[Tue Sep 09 12:52:53.753583 2014] [:error] [pid 4794] [client 127.0.0.1:58402]   File "/var/www/visched/app/visched.wsgi", line 12, in application
[Tue Sep 09 12:52:53.753787 2014] [:error] [pid 4794] [client 127.0.0.1:58402]     from visched import config
[Tue Sep 09 12:52:53.753852 2014] [:error] [pid 4794] [client 127.0.0.1:58402] ImportError: No module named visched
[Tue Sep 09 12:57:20.294694 2014] [:info] [pid 5067] [client 127.0.0.1:58409] mod_wsgi (pid=5067, process='', application='visched.local'): Loading WSGI script '/var/www/visched/app/visched.wsgi'.
[Tue Sep 09 12:57:20.391446 2014] [:error] [pid 5067] [client 127.0.0.1:58409] mod_wsgi (pid=5067): Exception occurred processing WSGI script '/var/www/visched/app/visched.wsgi'.
[Tue Sep 09 12:57:20.391555 2014] [:error] [pid 5067] [client 127.0.0.1:58409] Traceback (most recent call last):
[Tue Sep 09 12:57:20.391620 2014] [:error] [pid 5067] [client 127.0.0.1:58409]   File "/var/www/visched/app/visched.wsgi", line 12, in application
[Tue Sep 09 12:57:20.391821 2014] [:error] [pid 5067] [client 127.0.0.1:58409]     from visched import config
[Tue Sep 09 12:57:20.391885 2014] [:error] [pid 5067] [client 127.0.0.1:58409] ImportError: No module named visched
[Tue Sep 09 12:59:53.669077 2014] [:info] [pid 5066] [client 127.0.0.1:58411] mod_wsgi (pid=5066, process='', application='visched.local'): Loading WSGI script '/var/www/visched/app/visched.wsgi'.
[Tue Sep 09 12:59:54.798740 2014] [:error] [pid 5066] [client 127.0.0.1:58411] mod_wsgi (pid=5066): Exception occurred processing WSGI script '/var/www/visched/app/visched.wsgi'.
[Tue Sep 09 12:59:54.798870 2014] [:error] [pid 5066] [client 127.0.0.1:58411] Traceback (most recent call last):
[Tue Sep 09 12:59:54.798928 2014] [:error] [pid 5066] [client 127.0.0.1:58411]   File "/var/www/visched/app/visched.wsgi", line 14, in application
[Tue Sep 09 12:59:54.799156 2014] [:error] [pid 5066] [client 127.0.0.1:58411]     import visched.page.handlers
[Tue Sep 09 12:59:54.799194 2014] [:error] [pid 5066] [client 127.0.0.1:58411]   File "/var/www/visched/app/visched/page/handlers.py", line 7, in <module>
[Tue Sep 09 12:59:54.799545 2014] [:error] [pid 5066] [client 127.0.0.1:58411]     import visched.models
[Tue Sep 09 12:59:54.799580 2014] [:error] [pid 5066] [client 127.0.0.1:58411]   File "/var/www/visched/app/visched/models.py", line 797, in <module>
[Tue Sep 09 12:59:54.800308 2014] [:error] [pid 5066] [client 127.0.0.1:58411]     Base.prepare(visched.db.engine)
[Tue Sep 09 12:59:54.800344 2014] [:error] [pid 5066] [client 127.0.0.1:58411]   File "/usr/local/lib/python2.7/dist-packages/sqlalchemy/ext/declarative/api.py", line 478, in prepare
[Tue Sep 09 12:59:54.813232 2014] [:error] [pid 5066] [client 127.0.0.1:58411]     cls._sa_decl_prepare(thingy.local_table, engine)
[Tue Sep 09 12:59:54.813326 2014] [:error] [pid 5066] [client 127.0.0.1:58411]   File "/usr/local/lib/python2.7/dist-packages/sqlalchemy/ext/declarative/api.py", line 507, in _sa_decl_prepare
[Tue Sep 09 12:59:54.813440 2014] [:error] [pid 5066] [client 127.0.0.1:58411]     cls._reflect_table(local_table, engine)
[Tue Sep 09 12:59:54.813474 2014] [:error] [pid 5066] [client 127.0.0.1:58411]   File "/usr/local/lib/python2.7/dist-packages/sqlalchemy/ext/declarative/api.py", line 517, in _reflect_table
[Tue Sep 09 12:59:54.813527 2014] [:error] [pid 5066] [client 127.0.0.1:58411]     schema=table.schema)
[Tue Sep 09 12:59:54.813559 2014] [:error] [pid 5066] [client 127.0.0.1:58411]   File "/usr/local/lib/python2.7/dist-packages/sqlalchemy/sql/schema.py", line 344, in __new__
[Tue Sep 09 12:59:54.825950 2014] [:error] [pid 5066] [client 127.0.0.1:58411]     table._init_existing(*args, **kw)
[Tue Sep 09 12:59:54.826065 2014] [:error] [pid 5066] [client 127.0.0.1:58411]   File "/usr/local/lib/python2.7/dist-packages/sqlalchemy/sql/schema.py", line 494, in _init_existing
[Tue Sep 09 12:59:54.826162 2014] [:error] [pid 5066] [client 127.0.0.1:58411]     include_columns, exclude_columns)
[Tue Sep 09 12:59:54.826195 2014] [:error] [pid 5066] [client 127.0.0.1:58411]   File "/usr/local/lib/python2.7/dist-packages/sqlalchemy/sql/schema.py", line 439, in _autoload
[Tue Sep 09 12:59:54.826246 2014] [:error] [pid 5066] [client 127.0.0.1:58411]     self, include_columns, exclude_columns
[Tue Sep 09 12:59:54.826277 2014] [:error] [pid 5066] [client 127.0.0.1:58411]   File "/usr/local/lib/python2.7/dist-packages/sqlalchemy/engine/base.py", line 1732, in run_callable
[Tue Sep 09 12:59:54.831412 2014] [:error] [pid 5066] [client 127.0.0.1:58411]     with self.contextual_connect() as conn:
[Tue Sep 09 12:59:54.831493 2014] [:error] [pid 5066] [client 127.0.0.1:58411]   File "/usr/local/lib/python2.7/dist-packages/sqlalchemy/engine/base.py", line 1799, in contextual_connect
[Tue Sep 09 12:59:54.831574 2014] [:error] [pid 5066] [client 127.0.0.1:58411]     self.pool.connect(),
[Tue Sep 09 12:59:54.831606 2014] [:error] [pid 5066] [client 127.0.0.1:58411]   File "/usr/local/lib/python2.7/dist-packages/sqlalchemy/pool.py", line 338, in connect
[Tue Sep 09 12:59:54.839561 2014] [:error] [pid 5066] [client 127.0.0.1:58411]     return _ConnectionFairy._checkout(self)
[Tue Sep 09 12:59:54.839647 2014] [:error] [pid 5066] [client 127.0.0.1:58411]   File "/usr/local/lib/python2.7/dist-packages/sqlalchemy/pool.py", line 641, in _checkout
[Tue Sep 09 12:59:54.839729 2014] [:error] [pid 5066] [client 127.0.0.1:58411]     fairy = _ConnectionRecord.checkout(pool)
[Tue Sep 09 12:59:54.839759 2014] [:error] [pid 5066] [client 127.0.0.1:58411]   File "/usr/local/lib/python2.7/dist-packages/sqlalchemy/pool.py", line 440, in checkout
[Tue Sep 09 12:59:54.839807 2014] [:error] [pid 5066] [client 127.0.0.1:58411]     rec = pool._do_get()
[Tue Sep 09 12:59:54.839836 2014] [:error] [pid 5066] [client 127.0.0.1:58411]   File "/usr/local/lib/python2.7/dist-packages/sqlalchemy/pool.py", line 961, in _do_get
[Tue Sep 09 12:59:54.839882 2014] [:error] [pid 5066] [client 127.0.0.1:58411]     return self._create_connection()
[Tue Sep 09 12:59:54.839911 2014] [:error] [pid 5066] [client 127.0.0.1:58411]   File "/usr/local/lib/python2.7/dist-packages/sqlalchemy/pool.py", line 285, in _create_connection
[Tue Sep 09 12:59:54.839957 2014] [:error] [pid 5066] [client 127.0.0.1:58411]     return _ConnectionRecord(self)
[Tue Sep 09 12:59:54.839985 2014] [:error] [pid 5066] [client 127.0.0.1:58411]   File "/usr/local/lib/python2.7/dist-packages/sqlalchemy/pool.py", line 411, in __init__
[Tue Sep 09 12:59:54.840029 2014] [:error] [pid 5066] [client 127.0.0.1:58411]     self.connection = self.__connect()
[Tue Sep 09 12:59:54.840058 2014] [:error] [pid 5066] [client 127.0.0.1:58411]   File "/usr/local/lib/python2.7/dist-packages/sqlalchemy/pool.py", line 537, in __connect
[Tue Sep 09 12:59:54.840101 2014] [:error] [pid 5066] [client 127.0.0.1:58411]     connection = self.__pool._creator()
[Tue Sep 09 12:59:54.840131 2014] [:error] [pid 5066] [client 127.0.0.1:58411]   File "/usr/local/lib/python2.7/dist-packages/sqlalchemy/engine/strategies.py", line 96, in connect
[Tue Sep 09 12:59:54.840985 2014] [:error] [pid 5066] [client 127.0.0.1:58411]     connection_invalidated=invalidated
[Tue Sep 09 12:59:54.841063 2014] [:error] [pid 5066] [client 127.0.0.1:58411]   File "/usr/local/lib/python2.7/dist-packages/sqlalchemy/util/compat.py", line 199, in raise_from_cause
[Tue Sep 09 12:59:54.842051 2014] [:error] [pid 5066] [client 127.0.0.1:58411]     reraise(type(exception), exception, tb=exc_tb)
[Tue Sep 09 12:59:54.842129 2014] [:error] [pid 5066] [client 127.0.0.1:58411]   File "/usr/local/lib/python2.7/dist-packages/sqlalchemy/engine/strategies.py", line 90, in connect
[Tue Sep 09 12:59:54.842209 2014] [:error] [pid 5066] [client 127.0.0.1:58411]     return dialect.connect(*cargs, **cparams)
[Tue Sep 09 12:59:54.842239 2014] [:error] [pid 5066] [client 127.0.0.1:58411]   File "/usr/local/lib/python2.7/dist-packages/sqlalchemy/engine/default.py", line 377, in connect
[Tue Sep 09 12:59:54.843614 2014] [:error] [pid 5066] [client 127.0.0.1:58411]     return self.dbapi.connect(*cargs, **cparams)
[Tue Sep 09 12:59:54.843673 2014] [:error] [pid 5066] [client 127.0.0.1:58411]   File "/usr/lib/python2.7/dist-packages/MySQLdb/__init__.py", line 81, in Connect
[Tue Sep 09 12:59:54.857926 2014] [:error] [pid 5066] [client 127.0.0.1:58411]     return Connection(*args, **kwargs)
[Tue Sep 09 12:59:54.858035 2014] [:error] [pid 5066] [client 127.0.0.1:58411]   File "/usr/lib/python2.7/dist-packages/MySQLdb/connections.py", line 187, in __init__
[Tue Sep 09 12:59:54.859197 2014] [:error] [pid 5066] [client 127.0.0.1:58411]     super(Connection, self).__init__(*args, **kwargs2)
[Tue Sep 09 12:59:54.859409 2014] [:error] [pid 5066] [client 127.0.0.1:58411] OperationalError: (OperationalError) (1045, "Access denied for user 'root'@'localhost' (using password: YES)") None None
[Tue Sep 09 13:00:31.707620 2014] [:info] [pid 5069] [client 127.0.0.1:58412] mod_wsgi (pid=5069, process='', application='visched.local'): Loading WSGI script '/var/www/visched/app/visched.wsgi'.
[Tue Sep 09 13:00:31.958949 2014] [:error] [pid 5069] [client 127.0.0.1:58412] mod_wsgi (pid=5069): Exception occurred processing WSGI script '/var/www/visched/app/visched.wsgi'.
[Tue Sep 09 13:00:31.959076 2014] [:error] [pid 5069] [client 127.0.0.1:58412] Traceback (most recent call last):
[Tue Sep 09 13:00:31.959150 2014] [:error] [pid 5069] [client 127.0.0.1:58412]   File "/var/www/visched/app/visched.wsgi", line 14, in application
[Tue Sep 09 13:00:31.959365 2014] [:error] [pid 5069] [client 127.0.0.1:58412]     import visched.page.handlers
[Tue Sep 09 13:00:31.959401 2014] [:error] [pid 5069] [client 127.0.0.1:58412]   File "/var/www/visched/app/visched/page/handlers.py", line 7, in <module>
[Tue Sep 09 13:00:31.959739 2014] [:error] [pid 5069] [client 127.0.0.1:58412]     import visched.models
[Tue Sep 09 13:00:31.959775 2014] [:error] [pid 5069] [client 127.0.0.1:58412]   File "/var/www/visched/app/visched/models.py", line 797, in <module>
[Tue Sep 09 13:00:31.960488 2014] [:error] [pid 5069] [client 127.0.0.1:58412]     Base.prepare(visched.db.engine)
[Tue Sep 09 13:00:31.960524 2014] [:error] [pid 5069] [client 127.0.0.1:58412]   File "/usr/local/lib/python2.7/dist-packages/sqlalchemy/ext/declarative/api.py", line 478, in prepare
[Tue Sep 09 13:00:31.961088 2014] [:error] [pid 5069] [client 127.0.0.1:58412]     cls._sa_decl_prepare(thingy.local_table, engine)
[Tue Sep 09 13:00:31.961128 2014] [:error] [pid 5069] [client 127.0.0.1:58412]   File "/usr/local/lib/python2.7/dist-packages/sqlalchemy/ext/declarative/api.py", line 507, in _sa_decl_prepare
[Tue Sep 09 13:00:31.961186 2014] [:error] [pid 5069] [client 127.0.0.1:58412]     cls._reflect_table(local_table, engine)
[Tue Sep 09 13:00:31.961217 2014] [:error] [pid 5069] [client 127.0.0.1:58412]   File "/usr/local/lib/python2.7/dist-packages/sqlalchemy/ext/declarative/api.py", line 517, in _reflect_table
[Tue Sep 09 13:00:31.961267 2014] [:error] [pid 5069] [client 127.0.0.1:58412]     schema=table.schema)
[Tue Sep 09 13:00:31.961332 2014] [:error] [pid 5069] [client 127.0.0.1:58412]   File "/usr/local/lib/python2.7/dist-packages/sqlalchemy/sql/schema.py", line 344, in __new__
[Tue Sep 09 13:00:31.964138 2014] [:error] [pid 5069] [client 127.0.0.1:58412]     table._init_existing(*args, **kw)
[Tue Sep 09 13:00:31.964175 2014] [:error] [pid 5069] [client 127.0.0.1:58412]   File "/usr/local/lib/python2.7/dist-packages/sqlalchemy/sql/schema.py", line 494, in _init_existing
[Tue Sep 09 13:00:31.964228 2014] [:error] [pid 5069] [client 127.0.0.1:58412]     include_columns, exclude_columns)
[Tue Sep 09 13:00:31.964263 2014] [:error] [pid 5069] [client 127.0.0.1:58412]   File "/usr/local/lib/python2.7/dist-packages/sqlalchemy/sql/schema.py", line 439, in _autoload
[Tue Sep 09 13:00:31.964312 2014] [:error] [pid 5069] [client 127.0.0.1:58412]     self, include_columns, exclude_columns
[Tue Sep 09 13:00:31.964341 2014] [:error] [pid 5069] [client 127.0.0.1:58412]   File "/usr/local/lib/python2.7/dist-packages/sqlalchemy/engine/base.py", line 1732, in run_callable
[Tue Sep 09 13:00:31.965909 2014] [:error] [pid 5069] [client 127.0.0.1:58412]     with self.contextual_connect() as conn:
[Tue Sep 09 13:00:31.965947 2014] [:error] [pid 5069] [client 127.0.0.1:58412]   File "/usr/local/lib/python2.7/dist-packages/sqlalchemy/engine/base.py", line 1799, in contextual_connect
[Tue Sep 09 13:00:31.965997 2014] [:error] [pid 5069] [client 127.0.0.1:58412]     self.pool.connect(),
[Tue Sep 09 13:00:31.966027 2014] [:error] [pid 5069] [client 127.0.0.1:58412]   File "/usr/local/lib/python2.7/dist-packages/sqlalchemy/pool.py", line 338, in connect
[Tue Sep 09 13:00:31.967067 2014] [:error] [pid 5069] [client 127.0.0.1:58412]     return _ConnectionFairy._checkout(self)
[Tue Sep 09 13:00:31.967104 2014] [:error] [pid 5069] [client 127.0.0.1:58412]   File "/usr/local/lib/python2.7/dist-packages/sqlalchemy/pool.py", line 641, in _checkout
[Tue Sep 09 13:00:31.967155 2014] [:error] [pid 5069] [client 127.0.0.1:58412]     fairy = _ConnectionRecord.checkout(pool)
[Tue Sep 09 13:00:31.967184 2014] [:error] [pid 5069] [client 127.0.0.1:58412]   File "/usr/local/lib/python2.7/dist-packages/sqlalchemy/pool.py", line 440, in checkout
[Tue Sep 09 13:00:31.967229 2014] [:error] [pid 5069] [client 127.0.0.1:58412]     rec = pool._do_get()
[Tue Sep 09 13:00:31.967257 2014] [:error] [pid 5069] [client 127.0.0.1:58412]   File "/usr/local/lib/python2.7/dist-packages/sqlalchemy/pool.py", line 961, in _do_get
[Tue Sep 09 13:00:31.967301 2014] [:error] [pid 5069] [client 127.0.0.1:58412]     return self._create_connection()
[Tue Sep 09 13:00:31.967329 2014] [:error] [pid 5069] [client 127.0.0.1:58412]   File "/usr/local/lib/python2.7/dist-packages/sqlalchemy/pool.py", line 285, in _create_connection
[Tue Sep 09 13:00:31.967373 2014] [:error] [pid 5069] [client 127.0.0.1:58412]     return _ConnectionRecord(self)
[Tue Sep 09 13:00:31.967401 2014] [:error] [pid 5069] [client 127.0.0.1:58412]   File "/usr/local/lib/python2.7/dist-packages/sqlalchemy/pool.py", line 411, in __init__
[Tue Sep 09 13:00:31.967445 2014] [:error] [pid 5069] [client 127.0.0.1:58412]     self.connection = self.__connect()
[Tue Sep 09 13:00:31.967473 2014] [:error] [pid 5069] [client 127.0.0.1:58412]   File "/usr/local/lib/python2.7/dist-packages/sqlalchemy/pool.py", line 537, in __connect
[Tue Sep 09 13:00:31.967517 2014] [:error] [pid 5069] [client 127.0.0.1:58412]     connection = self.__pool._creator()
[Tue Sep 09 13:00:31.967545 2014] [:error] [pid 5069] [client 127.0.0.1:58412]   File "/usr/local/lib/python2.7/dist-packages/sqlalchemy/engine/strategies.py", line 96, in connect
[Tue Sep 09 13:00:31.967836 2014] [:error] [pid 5069] [client 127.0.0.1:58412]     connection_invalidated=invalidated
[Tue Sep 09 13:00:31.967869 2014] [:error] [pid 5069] [client 127.0.0.1:58412]   File "/usr/local/lib/python2.7/dist-packages/sqlalchemy/util/compat.py", line 199, in raise_from_cause
[Tue Sep 09 13:00:31.968157 2014] [:error] [pid 5069] [client 127.0.0.1:58412]     reraise(type(exception), exception, tb=exc_tb)
[Tue Sep 09 13:00:31.968216 2014] [:error] [pid 5069] [client 127.0.0.1:58412]   File "/usr/local/lib/python2.7/dist-packages/sqlalchemy/engine/strategies.py", line 90, in connect
[Tue Sep 09 13:00:31.968267 2014] [:error] [pid 5069] [client 127.0.0.1:58412]     return dialect.connect(*cargs, **cparams)
[Tue Sep 09 13:00:31.968304 2014] [:error] [pid 5069] [client 127.0.0.1:58412]   File "/usr/local/lib/python2.7/dist-packages/sqlalchemy/engine/default.py", line 377, in connect
[Tue Sep 09 13:00:31.969163 2014] [:error] [pid 5069] [client 127.0.0.1:58412]     return self.dbapi.connect(*cargs, **cparams)
[Tue Sep 09 13:00:31.969202 2014] [:error] [pid 5069] [client 127.0.0.1:58412]   File "/usr/lib/python2.7/dist-packages/MySQLdb/__init__.py", line 81, in Connect
[Tue Sep 09 13:00:31.969395 2014] [:error] [pid 5069] [client 127.0.0.1:58412]     return Connection(*args, **kwargs)
[Tue Sep 09 13:00:31.969428 2014] [:error] [pid 5069] [client 127.0.0.1:58412]   File "/usr/lib/python2.7/dist-packages/MySQLdb/connections.py", line 187, in __init__
[Tue Sep 09 13:00:31.969800 2014] [:error] [pid 5069] [client 127.0.0.1:58412]     super(Connection, self).__init__(*args, **kwargs2)
[Tue Sep 09 13:00:31.969983 2014] [:error] [pid 5069] [client 127.0.0.1:58412] OperationalError: (OperationalError) (1045, "Access denied for user 'root'@'localhost' (using password: YES)") None None
[Tue Sep 09 13:00:43.550974 2014] [:info] [pid 5240] [client 127.0.0.1:58413] mod_wsgi (pid=5240, process='', application='visched.local'): Loading WSGI script '/var/www/visched/app/visched.wsgi'.
[Tue Sep 09 13:00:43.804622 2014] [:error] [pid 5240] [client 127.0.0.1:58413] mod_wsgi (pid=5240): Exception occurred processing WSGI script '/var/www/visched/app/visched.wsgi'.
[Tue Sep 09 13:00:43.804667 2014] [:error] [pid 5240] [client 127.0.0.1:58413] Traceback (most recent call last):
[Tue Sep 09 13:00:43.804686 2014] [:error] [pid 5240] [client 127.0.0.1:58413]   File "/var/www/visched/app/visched.wsgi", line 14, in application
[Tue Sep 09 13:00:43.804761 2014] [:error] [pid 5240] [client 127.0.0.1:58413]     import visched.page.handlers
[Tue Sep 09 13:00:43.804770 2014] [:error] [pid 5240] [client 127.0.0.1:58413]   File "/var/www/visched/app/visched/page/handlers.py", line 7, in <module>
[Tue Sep 09 13:00:43.804862 2014] [:error] [pid 5240] [client 127.0.0.1:58413]     import visched.models
[Tue Sep 09 13:00:43.804870 2014] [:error] [pid 5240] [client 127.0.0.1:58413]   File "/var/www/visched/app/visched/models.py", line 797, in <module>
[Tue Sep 09 13:00:43.805056 2014] [:error] [pid 5240] [client 127.0.0.1:58413]     Base.prepare(visched.db.engine)
[Tue Sep 09 13:00:43.805064 2014] [:error] [pid 5240] [client 127.0.0.1:58413]   File "/usr/local/lib/python2.7/dist-packages/sqlalchemy/ext/declarative/api.py", line 478, in prepare
[Tue Sep 09 13:00:43.805193 2014] [:error] [pid 5240] [client 127.0.0.1:58413]     cls._sa_decl_prepare(thingy.local_table, engine)
[Tue Sep 09 13:00:43.805202 2014] [:error] [pid 5240] [client 127.0.0.1:58413]   File "/usr/local/lib/python2.7/dist-packages/sqlalchemy/ext/declarative/api.py", line 507, in _sa_decl_prepare
[Tue Sep 09 13:00:43.805217 2014] [:error] [pid 5240] [client 127.0.0.1:58413]     cls._reflect_table(local_table, engine)
[Tue Sep 09 13:00:43.805224 2014] [:error] [pid 5240] [client 127.0.0.1:58413]   File "/usr/local/lib/python2.7/dist-packages/sqlalchemy/ext/declarative/api.py", line 517, in _reflect_table
[Tue Sep 09 13:00:43.805236 2014] [:error] [pid 5240] [client 127.0.0.1:58413]     schema=table.schema)
[Tue Sep 09 13:00:43.805245 2014] [:error] [pid 5240] [client 127.0.0.1:58413]   File "/usr/local/lib/python2.7/dist-packages/sqlalchemy/sql/schema.py", line 344, in __new__
[Tue Sep 09 13:00:43.805945 2014] [:error] [pid 5240] [client 127.0.0.1:58413]     table._init_existing(*args, **kw)
[Tue Sep 09 13:00:43.805955 2014] [:error] [pid 5240] [client 127.0.0.1:58413]   File "/usr/local/lib/python2.7/dist-packages/sqlalchemy/sql/schema.py", line 494, in _init_existing
[Tue Sep 09 13:00:43.805968 2014] [:error] [pid 5240] [client 127.0.0.1:58413]     include_columns, exclude_columns)
[Tue Sep 09 13:00:43.805989 2014] [:error] [pid 5240] [client 127.0.0.1:58413]   File "/usr/local/lib/python2.7/dist-packages/sqlalchemy/sql/schema.py", line 439, in _autoload
[Tue Sep 09 13:00:43.806001 2014] [:error] [pid 5240] [client 127.0.0.1:58413]     self, include_columns, exclude_columns
[Tue Sep 09 13:00:43.806008 2014] [:error] [pid 5240] [client 127.0.0.1:58413]   File "/usr/local/lib/python2.7/dist-packages/sqlalchemy/engine/base.py", line 1732, in run_callable
[Tue Sep 09 13:00:43.806395 2014] [:error] [pid 5240] [client 127.0.0.1:58413]     with self.contextual_connect() as conn:
[Tue Sep 09 13:00:43.806404 2014] [:error] [pid 5240] [client 127.0.0.1:58413]   File "/usr/local/lib/python2.7/dist-packages/sqlalchemy/engine/base.py", line 1799, in contextual_connect
[Tue Sep 09 13:00:43.806416 2014] [:error] [pid 5240] [client 127.0.0.1:58413]     self.pool.connect(),
[Tue Sep 09 13:00:43.806423 2014] [:error] [pid 5240] [client 127.0.0.1:58413]   File "/usr/local/lib/python2.7/dist-packages/sqlalchemy/pool.py", line 338, in connect
[Tue Sep 09 13:00:43.806682 2014] [:error] [pid 5240] [client 127.0.0.1:58413]     return _ConnectionFairy._checkout(self)
[Tue Sep 09 13:00:43.806692 2014] [:error] [pid 5240] [client 127.0.0.1:58413]   File "/usr/local/lib/python2.7/dist-packages/sqlalchemy/pool.py", line 641, in _checkout
[Tue Sep 09 13:00:43.806704 2014] [:error] [pid 5240] [client 127.0.0.1:58413]     fairy = _ConnectionRecord.checkout(pool)
[Tue Sep 09 13:00:43.806711 2014] [:error] [pid 5240] [client 127.0.0.1:58413]   File "/usr/local/lib/python2.7/dist-packages/sqlalchemy/pool.py", line 440, in checkout
[Tue Sep 09 13:00:43.806722 2014] [:error] [pid 5240] [client 127.0.0.1:58413]     rec = pool._do_get()
[Tue Sep 09 13:00:43.806729 2014] [:error] [pid 5240] [client 127.0.0.1:58413]   File "/usr/local/lib/python2.7/dist-packages/sqlalchemy/pool.py", line 961, in _do_get
[Tue Sep 09 13:00:43.806739 2014] [:error] [pid 5240] [client 127.0.0.1:58413]     return self._create_connection()
[Tue Sep 09 13:00:43.806746 2014] [:error] [pid 5240] [client 127.0.0.1:58413]   File "/usr/local/lib/python2.7/dist-packages/sqlalchemy/pool.py", line 285, in _create_connection
[Tue Sep 09 13:00:43.806756 2014] [:error] [pid 5240] [client 127.0.0.1:58413]     return _ConnectionRecord(self)
[Tue Sep 09 13:00:43.806763 2014] [:error] [pid 5240] [client 127.0.0.1:58413]   File "/usr/local/lib/python2.7/dist-packages/sqlalchemy/pool.py", line 411, in __init__
[Tue Sep 09 13:00:43.806773 2014] [:error] [pid 5240] [client 127.0.0.1:58413]     self.connection = self.__connect()
[Tue Sep 09 13:00:43.806780 2014] [:error] [pid 5240] [client 127.0.0.1:58413]   File "/usr/local/lib/python2.7/dist-packages/sqlalchemy/pool.py", line 537, in __connect
[Tue Sep 09 13:00:43.806790 2014] [:error] [pid 5240] [client 127.0.0.1:58413]     connection = self.__pool._creator()
[Tue Sep 09 13:00:43.806797 2014] [:error] [pid 5240] [client 127.0.0.1:58413]   File "/usr/local/lib/python2.7/dist-packages/sqlalchemy/engine/strategies.py", line 96, in connect
[Tue Sep 09 13:00:43.806872 2014] [:error] [pid 5240] [client 127.0.0.1:58413]     connection_invalidated=invalidated
[Tue Sep 09 13:00:43.806880 2014] [:error] [pid 5240] [client 127.0.0.1:58413]   File "/usr/local/lib/python2.7/dist-packages/sqlalchemy/util/compat.py", line 199, in raise_from_cause
[Tue Sep 09 13:00:43.806949 2014] [:error] [pid 5240] [client 127.0.0.1:58413]     reraise(type(exception), exception, tb=exc_tb)
[Tue Sep 09 13:00:43.806957 2014] [:error] [pid 5240] [client 127.0.0.1:58413]   File "/usr/local/lib/python2.7/dist-packages/sqlalchemy/engine/strategies.py", line 90, in connect
[Tue Sep 09 13:00:43.806969 2014] [:error] [pid 5240] [client 127.0.0.1:58413]     return dialect.connect(*cargs, **cparams)
[Tue Sep 09 13:00:43.806979 2014] [:error] [pid 5240] [client 127.0.0.1:58413]   File "/usr/local/lib/python2.7/dist-packages/sqlalchemy/engine/default.py", line 377, in connect
[Tue Sep 09 13:00:43.807187 2014] [:error] [pid 5240] [client 127.0.0.1:58413]     return self.dbapi.connect(*cargs, **cparams)
[Tue Sep 09 13:00:43.807196 2014] [:error] [pid 5240] [client 127.0.0.1:58413]   File "/usr/lib/python2.7/dist-packages/MySQLdb/__init__.py", line 81, in Connect
[Tue Sep 09 13:00:43.807244 2014] [:error] [pid 5240] [client 127.0.0.1:58413]     return Connection(*args, **kwargs)
[Tue Sep 09 13:00:43.807252 2014] [:error] [pid 5240] [client 127.0.0.1:58413]   File "/usr/lib/python2.7/dist-packages/MySQLdb/connections.py", line 187, in __init__
[Tue Sep 09 13:00:43.807344 2014] [:error] [pid 5240] [client 127.0.0.1:58413]     super(Connection, self).__init__(*args, **kwargs2)
[Tue Sep 09 13:00:43.807408 2014] [:error] [pid 5240] [client 127.0.0.1:58413] OperationalError: (OperationalError) (1045, "Access denied for user 'root'@'localhost' (using password: YES)") None None
[Tue Sep 09 13:00:48.410106 2014] [:info] [pid 5239] [client 127.0.0.1:58414] mod_wsgi (pid=5239, process='', application='visched.local'): Loading WSGI script '/var/www/visched/app/visched.wsgi'.
[Tue Sep 09 13:00:48.668145 2014] [:error] [pid 5239] [client 127.0.0.1:58414] mod_wsgi (pid=5239): Exception occurred processing WSGI script '/var/www/visched/app/visched.wsgi'.
[Tue Sep 09 13:00:48.668275 2014] [:error] [pid 5239] [client 127.0.0.1:58414] Traceback (most recent call last):
[Tue Sep 09 13:00:48.668339 2014] [:error] [pid 5239] [client 127.0.0.1:58414]   File "/var/www/visched/app/visched.wsgi", line 14, in application
[Tue Sep 09 13:00:48.668624 2014] [:error] [pid 5239] [client 127.0.0.1:58414]     import visched.page.handlers
[Tue Sep 09 13:00:48.668662 2014] [:error] [pid 5239] [client 127.0.0.1:58414]   File "/var/www/visched/app/visched/page/handlers.py", line 7, in <module>
[Tue Sep 09 13:00:48.669021 2014] [:error] [pid 5239] [client 127.0.0.1:58414]     import visched.models
[Tue Sep 09 13:00:48.669054 2014] [:error] [pid 5239] [client 127.0.0.1:58414]   File "/var/www/visched/app/visched/models.py", line 797, in <module>
[Tue Sep 09 13:00:48.669777 2014] [:error] [pid 5239] [client 127.0.0.1:58414]     Base.prepare(visched.db.engine)
[Tue Sep 09 13:00:48.669810 2014] [:error] [pid 5239] [client 127.0.0.1:58414]   File "/usr/local/lib/python2.7/dist-packages/sqlalchemy/ext/declarative/api.py", line 478, in prepare
[Tue Sep 09 13:00:48.670335 2014] [:error] [pid 5239] [client 127.0.0.1:58414]     cls._sa_decl_prepare(thingy.local_table, engine)
[Tue Sep 09 13:00:48.670370 2014] [:error] [pid 5239] [client 127.0.0.1:58414]   File "/usr/local/lib/python2.7/dist-packages/sqlalchemy/ext/declarative/api.py", line 507, in _sa_decl_prepare
[Tue Sep 09 13:00:48.670426 2014] [:error] [pid 5239] [client 127.0.0.1:58414]     cls._reflect_table(local_table, engine)
[Tue Sep 09 13:00:48.670455 2014] [:error] [pid 5239] [client 127.0.0.1:58414]   File "/usr/local/lib/python2.7/dist-packages/sqlalchemy/ext/declarative/api.py", line 517, in _reflect_table
[Tue Sep 09 13:00:48.670503 2014] [:error] [pid 5239] [client 127.0.0.1:58414]     schema=table.schema)
[Tue Sep 09 13:00:48.670537 2014] [:error] [pid 5239] [client 127.0.0.1:58414]   File "/usr/local/lib/python2.7/dist-packages/sqlalchemy/sql/schema.py", line 344, in __new__
[Tue Sep 09 13:00:48.673374 2014] [:error] [pid 5239] [client 127.0.0.1:58414]     table._init_existing(*args, **kw)
[Tue Sep 09 13:00:48.673413 2014] [:error] [pid 5239] [client 127.0.0.1:58414]   File "/usr/local/lib/python2.7/dist-packages/sqlalchemy/sql/schema.py", line 494, in _init_existing
[Tue Sep 09 13:00:48.673466 2014] [:error] [pid 5239] [client 127.0.0.1:58414]     include_columns, exclude_columns)
[Tue Sep 09 13:00:48.673501 2014] [:error] [pid 5239] [client 127.0.0.1:58414]   File "/usr/local/lib/python2.7/dist-packages/sqlalchemy/sql/schema.py", line 439, in _autoload
[Tue Sep 09 13:00:48.673549 2014] [:error] [pid 5239] [client 127.0.0.1:58414]     self, include_columns, exclude_columns
[Tue Sep 09 13:00:48.673578 2014] [:error] [pid 5239] [client 127.0.0.1:58414]   File "/usr/local/lib/python2.7/dist-packages/sqlalchemy/engine/base.py", line 1732, in run_callable
[Tue Sep 09 13:00:48.675139 2014] [:error] [pid 5239] [client 127.0.0.1:58414]     with self.contextual_connect() as conn:
[Tue Sep 09 13:00:48.675174 2014] [:error] [pid 5239] [client 127.0.0.1:58414]   File "/usr/local/lib/python2.7/dist-packages/sqlalchemy/engine/base.py", line 1799, in contextual_connect
[Tue Sep 09 13:00:48.675224 2014] [:error] [pid 5239] [client 127.0.0.1:58414]     self.pool.connect(),
[Tue Sep 09 13:00:48.675253 2014] [:error] [pid 5239] [client 127.0.0.1:58414]   File "/usr/local/lib/python2.7/dist-packages/sqlalchemy/pool.py", line 338, in connect
[Tue Sep 09 13:00:48.676286 2014] [:error] [pid 5239] [client 127.0.0.1:58414]     return _ConnectionFairy._checkout(self)
[Tue Sep 09 13:00:48.676319 2014] [:error] [pid 5239] [client 127.0.0.1:58414]   File "/usr/local/lib/python2.7/dist-packages/sqlalchemy/pool.py", line 641, in _checkout
[Tue Sep 09 13:00:48.676373 2014] [:error] [pid 5239] [client 127.0.0.1:58414]     fairy = _ConnectionRecord.checkout(pool)
[Tue Sep 09 13:00:48.676402 2014] [:error] [pid 5239] [client 127.0.0.1:58414]   File "/usr/local/lib/python2.7/dist-packages/sqlalchemy/pool.py", line 440, in checkout
[Tue Sep 09 13:00:48.676447 2014] [:error] [pid 5239] [client 127.0.0.1:58414]     rec = pool._do_get()
[Tue Sep 09 13:00:48.676475 2014] [:error] [pid 5239] [client 127.0.0.1:58414]   File "/usr/local/lib/python2.7/dist-packages/sqlalchemy/pool.py", line 961, in _do_get
[Tue Sep 09 13:00:48.676520 2014] [:error] [pid 5239] [client 127.0.0.1:58414]     return self._create_connection()
[Tue Sep 09 13:00:48.676607 2014] [:error] [pid 5239] [client 127.0.0.1:58414]   File "/usr/local/lib/python2.7/dist-packages/sqlalchemy/pool.py", line 285, in _create_connection
[Tue Sep 09 13:00:48.676657 2014] [:error] [pid 5239] [client 127.0.0.1:58414]     return _ConnectionRecord(self)
[Tue Sep 09 13:00:48.676684 2014] [:error] [pid 5239] [client 127.0.0.1:58414]   File "/usr/local/lib/python2.7/dist-packages/sqlalchemy/pool.py", line 411, in __init__
[Tue Sep 09 13:00:48.676728 2014] [:error] [pid 5239] [client 127.0.0.1:58414]     self.connection = self.__connect()
[Tue Sep 09 13:00:48.676754 2014] [:error] [pid 5239] [client 127.0.0.1:58414]   File "/usr/local/lib/python2.7/dist-packages/sqlalchemy/pool.py", line 537, in __connect
[Tue Sep 09 13:00:48.676798 2014] [:error] [pid 5239] [client 127.0.0.1:58414]     connection = self.__pool._creator()
[Tue Sep 09 13:00:48.676825 2014] [:error] [pid 5239] [client 127.0.0.1:58414]   File "/usr/local/lib/python2.7/dist-packages/sqlalchemy/engine/strategies.py", line 96, in connect
[Tue Sep 09 13:00:48.677115 2014] [:error] [pid 5239] [client 127.0.0.1:58414]     connection_invalidated=invalidated
[Tue Sep 09 13:00:48.677146 2014] [:error] [pid 5239] [client 127.0.0.1:58414]   File "/usr/local/lib/python2.7/dist-packages/sqlalchemy/util/compat.py", line 199, in raise_from_cause
[Tue Sep 09 13:00:48.677405 2014] [:error] [pid 5239] [client 127.0.0.1:58414]     reraise(type(exception), exception, tb=exc_tb)
[Tue Sep 09 13:00:48.677437 2014] [:error] [pid 5239] [client 127.0.0.1:58414]   File "/usr/local/lib/python2.7/dist-packages/sqlalchemy/engine/strategies.py", line 90, in connect
[Tue Sep 09 13:00:48.677485 2014] [:error] [pid 5239] [client 127.0.0.1:58414]     return dialect.connect(*cargs, **cparams)
[Tue Sep 09 13:00:48.677520 2014] [:error] [pid 5239] [client 127.0.0.1:58414]   File "/usr/local/lib/python2.7/dist-packages/sqlalchemy/engine/default.py", line 377, in connect
[Tue Sep 09 13:00:48.678331 2014] [:error] [pid 5239] [client 127.0.0.1:58414]     return self.dbapi.connect(*cargs, **cparams)
[Tue Sep 09 13:00:48.678365 2014] [:error] [pid 5239] [client 127.0.0.1:58414]   File "/usr/lib/python2.7/dist-packages/MySQLdb/__init__.py", line 81, in Connect
[Tue Sep 09 13:00:48.678545 2014] [:error] [pid 5239] [client 127.0.0.1:58414]     return Connection(*args, **kwargs)
[Tue Sep 09 13:00:48.678576 2014] [:error] [pid 5239] [client 127.0.0.1:58414]   File "/usr/lib/python2.7/dist-packages/MySQLdb/connections.py", line 187, in __init__
[Tue Sep 09 13:00:48.678954 2014] [:error] [pid 5239] [client 127.0.0.1:58414]     super(Connection, self).__init__(*args, **kwargs2)
[Tue Sep 09 13:00:48.679116 2014] [:error] [pid 5239] [client 127.0.0.1:58414] OperationalError: (OperationalError) (1045, "Access denied for user 'root'@'localhost' (using password: YES)") None None
[Tue Sep 09 13:03:31.781346 2014] [:info] [pid 5247] [client 127.0.0.1:58415] mod_wsgi (pid=5247, process='', application='visched.local'): Loading WSGI script '/var/www/visched/app/visched.wsgi'.
[Tue Sep 09 13:03:32.031535 2014] [:error] [pid 5247] [client 127.0.0.1:58415] mod_wsgi (pid=5247): Exception occurred processing WSGI script '/var/www/visched/app/visched.wsgi'.
[Tue Sep 09 13:03:32.031665 2014] [:error] [pid 5247] [client 127.0.0.1:58415] Traceback (most recent call last):
[Tue Sep 09 13:03:32.031722 2014] [:error] [pid 5247] [client 127.0.0.1:58415]   File "/var/www/visched/app/visched.wsgi", line 14, in application
[Tue Sep 09 13:03:32.031929 2014] [:error] [pid 5247] [client 127.0.0.1:58415]     import visched.page.handlers
[Tue Sep 09 13:03:32.031965 2014] [:error] [pid 5247] [client 127.0.0.1:58415]   File "/var/www/visched/app/visched/page/handlers.py", line 7, in <module>
[Tue Sep 09 13:03:32.032309 2014] [:error] [pid 5247] [client 127.0.0.1:58415]     import visched.models
[Tue Sep 09 13:03:32.032343 2014] [:error] [pid 5247] [client 127.0.0.1:58415]   File "/var/www/visched/app/visched/models.py", line 797, in <module>
[Tue Sep 09 13:03:32.032737 2014] [:error] [pid 5247] [client 127.0.0.1:58415]     Base.prepare(visched.db.engine)
[Tue Sep 09 13:03:32.032747 2014] [:error] [pid 5247] [client 127.0.0.1:58415]   File "/usr/local/lib/python2.7/dist-packages/sqlalchemy/ext/declarative/api.py", line 478, in prepare
[Tue Sep 09 13:03:32.032878 2014] [:error] [pid 5247] [client 127.0.0.1:58415]     cls._sa_decl_prepare(thingy.local_table, engine)
[Tue Sep 09 13:03:32.032887 2014] [:error] [pid 5247] [client 127.0.0.1:58415]   File "/usr/local/lib/python2.7/dist-packages/sqlalchemy/ext/declarative/api.py", line 507, in _sa_decl_prepare
[Tue Sep 09 13:03:32.032903 2014] [:error] [pid 5247] [client 127.0.0.1:58415]     cls._reflect_table(local_table, engine)
[Tue Sep 09 13:03:32.032910 2014] [:error] [pid 5247] [client 127.0.0.1:58415]   File "/usr/local/lib/python2.7/dist-packages/sqlalchemy/ext/declarative/api.py", line 517, in _reflect_table
[Tue Sep 09 13:03:32.032922 2014] [:error] [pid 5247] [client 127.0.0.1:58415]     schema=table.schema)
[Tue Sep 09 13:03:32.032931 2014] [:error] [pid 5247] [client 127.0.0.1:58415]   File "/usr/local/lib/python2.7/dist-packages/sqlalchemy/sql/schema.py", line 344, in __new__
[Tue Sep 09 13:03:32.033641 2014] [:error] [pid 5247] [client 127.0.0.1:58415]     table._init_existing(*args, **kw)
[Tue Sep 09 13:03:32.033651 2014] [:error] [pid 5247] [client 127.0.0.1:58415]   File "/usr/local/lib/python2.7/dist-packages/sqlalchemy/sql/schema.py", line 494, in _init_existing
[Tue Sep 09 13:03:32.033663 2014] [:error] [pid 5247] [client 127.0.0.1:58415]     include_columns, exclude_columns)
[Tue Sep 09 13:03:32.033672 2014] [:error] [pid 5247] [client 127.0.0.1:58415]   File "/usr/local/lib/python2.7/dist-packages/sqlalchemy/sql/schema.py", line 439, in _autoload
[Tue Sep 09 13:03:32.033684 2014] [:error] [pid 5247] [client 127.0.0.1:58415]     self, include_columns, exclude_columns
[Tue Sep 09 13:03:32.033691 2014] [:error] [pid 5247] [client 127.0.0.1:58415]   File "/usr/local/lib/python2.7/dist-packages/sqlalchemy/engine/base.py", line 1732, in run_callable
[Tue Sep 09 13:03:32.034076 2014] [:error] [pid 5247] [client 127.0.0.1:58415]     with self.contextual_connect() as conn:
[Tue Sep 09 13:03:32.034085 2014] [:error] [pid 5247] [client 127.0.0.1:58415]   File "/usr/local/lib/python2.7/dist-packages/sqlalchemy/engine/base.py", line 1799, in contextual_connect
[Tue Sep 09 13:03:32.034098 2014] [:error] [pid 5247] [client 127.0.0.1:58415]     self.pool.connect(),
[Tue Sep 09 13:03:32.034117 2014] [:error] [pid 5247] [client 127.0.0.1:58415]   File "/usr/local/lib/python2.7/dist-packages/sqlalchemy/pool.py", line 338, in connect
[Tue Sep 09 13:03:32.034373 2014] [:error] [pid 5247] [client 127.0.0.1:58415]     return _ConnectionFairy._checkout(self)
[Tue Sep 09 13:03:32.034382 2014] [:error] [pid 5247] [client 127.0.0.1:58415]   File "/usr/local/lib/python2.7/dist-packages/sqlalchemy/pool.py", line 641, in _checkout
[Tue Sep 09 13:03:32.034394 2014] [:error] [pid 5247] [client 127.0.0.1:58415]     fairy = _ConnectionRecord.checkout(pool)
[Tue Sep 09 13:03:32.034402 2014] [:error] [pid 5247] [client 127.0.0.1:58415]   File "/usr/local/lib/python2.7/dist-packages/sqlalchemy/pool.py", line 440, in checkout
[Tue Sep 09 13:03:32.034412 2014] [:error] [pid 5247] [client 127.0.0.1:58415]     rec = pool._do_get()
[Tue Sep 09 13:03:32.034419 2014] [:error] [pid 5247] [client 127.0.0.1:58415]   File "/usr/local/lib/python2.7/dist-packages/sqlalchemy/pool.py", line 961, in _do_get
[Tue Sep 09 13:03:32.034429 2014] [:error] [pid 5247] [client 127.0.0.1:58415]     return self._create_connection()
[Tue Sep 09 13:03:32.034436 2014] [:error] [pid 5247] [client 127.0.0.1:58415]   File "/usr/local/lib/python2.7/dist-packages/sqlalchemy/pool.py", line 285, in _create_connection
[Tue Sep 09 13:03:32.034446 2014] [:error] [pid 5247] [client 127.0.0.1:58415]     return _ConnectionRecord(self)
[Tue Sep 09 13:03:32.034453 2014] [:error] [pid 5247] [client 127.0.0.1:58415]   File "/usr/local/lib/python2.7/dist-packages/sqlalchemy/pool.py", line 411, in __init__
[Tue Sep 09 13:03:32.034464 2014] [:error] [pid 5247] [client 127.0.0.1:58415]     self.connection = self.__connect()
[Tue Sep 09 13:03:32.034470 2014] [:error] [pid 5247] [client 127.0.0.1:58415]   File "/usr/local/lib/python2.7/dist-packages/sqlalchemy/pool.py", line 537, in __connect
[Tue Sep 09 13:03:32.034480 2014] [:error] [pid 5247] [client 127.0.0.1:58415]     connection = self.__pool._creator()
[Tue Sep 09 13:03:32.034487 2014] [:error] [pid 5247] [client 127.0.0.1:58415]   File "/usr/local/lib/python2.7/dist-packages/sqlalchemy/engine/strategies.py", line 96, in connect
[Tue Sep 09 13:03:32.034559 2014] [:error] [pid 5247] [client 127.0.0.1:58415]     connection_invalidated=invalidated
[Tue Sep 09 13:03:32.034568 2014] [:error] [pid 5247] [client 127.0.0.1:58415]   File "/usr/local/lib/python2.7/dist-packages/sqlalchemy/util/compat.py", line 199, in raise_from_cause
[Tue Sep 09 13:03:32.034635 2014] [:error] [pid 5247] [client 127.0.0.1:58415]     reraise(type(exception), exception, tb=exc_tb)
[Tue Sep 09 13:03:32.034643 2014] [:error] [pid 5247] [client 127.0.0.1:58415]   File "/usr/local/lib/python2.7/dist-packages/sqlalchemy/engine/strategies.py", line 90, in connect
[Tue Sep 09 13:03:32.034654 2014] [:error] [pid 5247] [client 127.0.0.1:58415]     return dialect.connect(*cargs, **cparams)
[Tue Sep 09 13:03:32.034664 2014] [:error] [pid 5247] [client 127.0.0.1:58415]   File "/usr/local/lib/python2.7/dist-packages/sqlalchemy/engine/default.py", line 377, in connect
[Tue Sep 09 13:03:32.034864 2014] [:error] [pid 5247] [client 127.0.0.1:58415]     return self.dbapi.connect(*cargs, **cparams)
[Tue Sep 09 13:03:32.034873 2014] [:error] [pid 5247] [client 127.0.0.1:58415]   File "/usr/lib/python2.7/dist-packages/MySQLdb/__init__.py", line 81, in Connect
[Tue Sep 09 13:03:32.034921 2014] [:error] [pid 5247] [client 127.0.0.1:58415]     return Connection(*args, **kwargs)
[Tue Sep 09 13:03:32.034929 2014] [:error] [pid 5247] [client 127.0.0.1:58415]   File "/usr/lib/python2.7/dist-packages/MySQLdb/connections.py", line 187, in __init__
[Tue Sep 09 13:03:32.035021 2014] [:error] [pid 5247] [client 127.0.0.1:58415]     super(Connection, self).__init__(*args, **kwargs2)
[Tue Sep 09 13:03:32.035084 2014] [:error] [pid 5247] [client 127.0.0.1:58415] OperationalError: (OperationalError) (1044, "Access denied for user ''@'localhost' to database 'visched_test'") None None
[Tue Sep 09 13:03:34.560611 2014] [:info] [pid 5246] [client 127.0.0.1:58416] mod_wsgi (pid=5246, process='', application='visched.local'): Loading WSGI script '/var/www/visched/app/visched.wsgi'.
[Tue Sep 09 13:03:34.815439 2014] [:error] [pid 5246] [client 127.0.0.1:58416] mod_wsgi (pid=5246): Exception occurred processing WSGI script '/var/www/visched/app/visched.wsgi'.
[Tue Sep 09 13:03:34.815563 2014] [:error] [pid 5246] [client 127.0.0.1:58416] Traceback (most recent call last):
[Tue Sep 09 13:03:34.815624 2014] [:error] [pid 5246] [client 127.0.0.1:58416]   File "/var/www/visched/app/visched.wsgi", line 14, in application
[Tue Sep 09 13:03:34.815861 2014] [:error] [pid 5246] [client 127.0.0.1:58416]     import visched.page.handlers
[Tue Sep 09 13:03:34.815895 2014] [:error] [pid 5246] [client 127.0.0.1:58416]   File "/var/www/visched/app/visched/page/handlers.py", line 7, in <module>
[Tue Sep 09 13:03:34.816248 2014] [:error] [pid 5246] [client 127.0.0.1:58416]     import visched.models
[Tue Sep 09 13:03:34.816282 2014] [:error] [pid 5246] [client 127.0.0.1:58416]   File "/var/www/visched/app/visched/models.py", line 797, in <module>
[Tue Sep 09 13:03:34.816748 2014] [:error] [pid 5246] [client 127.0.0.1:58416]     Base.prepare(visched.db.engine)
[Tue Sep 09 13:03:34.816758 2014] [:error] [pid 5246] [client 127.0.0.1:58416]   File "/usr/local/lib/python2.7/dist-packages/sqlalchemy/ext/declarative/api.py", line 478, in prepare
[Tue Sep 09 13:03:34.816897 2014] [:error] [pid 5246] [client 127.0.0.1:58416]     cls._sa_decl_prepare(thingy.local_table, engine)
[Tue Sep 09 13:03:34.816906 2014] [:error] [pid 5246] [client 127.0.0.1:58416]   File "/usr/local/lib/python2.7/dist-packages/sqlalchemy/ext/declarative/api.py", line 507, in _sa_decl_prepare
[Tue Sep 09 13:03:34.816922 2014] [:error] [pid 5246] [client 127.0.0.1:58416]     cls._reflect_table(local_table, engine)
[Tue Sep 09 13:03:34.816929 2014] [:error] [pid 5246] [client 127.0.0.1:58416]   File "/usr/local/lib/python2.7/dist-packages/sqlalchemy/ext/declarative/api.py", line 517, in _reflect_table
[Tue Sep 09 13:03:34.816940 2014] [:error] [pid 5246] [client 127.0.0.1:58416]     schema=table.schema)
[Tue Sep 09 13:03:34.816953 2014] [:error] [pid 5246] [client 127.0.0.1:58416]   File "/usr/local/lib/python2.7/dist-packages/sqlalchemy/sql/schema.py", line 344, in __new__
[Tue Sep 09 13:03:34.817705 2014] [:error] [pid 5246] [client 127.0.0.1:58416]     table._init_existing(*args, **kw)
[Tue Sep 09 13:03:34.817717 2014] [:error] [pid 5246] [client 127.0.0.1:58416]   File "/usr/local/lib/python2.7/dist-packages/sqlalchemy/sql/schema.py", line 494, in _init_existing
[Tue Sep 09 13:03:34.817733 2014] [:error] [pid 5246] [client 127.0.0.1:58416]     include_columns, exclude_columns)
[Tue Sep 09 13:03:34.817742 2014] [:error] [pid 5246] [client 127.0.0.1:58416]   File "/usr/local/lib/python2.7/dist-packages/sqlalchemy/sql/schema.py", line 439, in _autoload
[Tue Sep 09 13:03:34.817753 2014] [:error] [pid 5246] [client 127.0.0.1:58416]     self, include_columns, exclude_columns
[Tue Sep 09 13:03:34.817761 2014] [:error] [pid 5246] [client 127.0.0.1:58416]   File "/usr/local/lib/python2.7/dist-packages/sqlalchemy/engine/base.py", line 1732, in run_callable
[Tue Sep 09 13:03:34.818176 2014] [:error] [pid 5246] [client 127.0.0.1:58416]     with self.contextual_connect() as conn:
[Tue Sep 09 13:03:34.818186 2014] [:error] [pid 5246] [client 127.0.0.1:58416]   File "/usr/local/lib/python2.7/dist-packages/sqlalchemy/engine/base.py", line 1799, in contextual_connect
[Tue Sep 09 13:03:34.818199 2014] [:error] [pid 5246] [client 127.0.0.1:58416]     self.pool.connect(),
[Tue Sep 09 13:03:34.818207 2014] [:error] [pid 5246] [client 127.0.0.1:58416]   File "/usr/local/lib/python2.7/dist-packages/sqlalchemy/pool.py", line 338, in connect
[Tue Sep 09 13:03:34.818483 2014] [:error] [pid 5246] [client 127.0.0.1:58416]     return _ConnectionFairy._checkout(self)
[Tue Sep 09 13:03:34.818492 2014] [:error] [pid 5246] [client 127.0.0.1:58416]   File "/usr/local/lib/python2.7/dist-packages/sqlalchemy/pool.py", line 641, in _checkout
[Tue Sep 09 13:03:34.818504 2014] [:error] [pid 5246] [client 127.0.0.1:58416]     fairy = _ConnectionRecord.checkout(pool)
[Tue Sep 09 13:03:34.818529 2014] [:error] [pid 5246] [client 127.0.0.1:58416]   File "/usr/local/lib/python2.7/dist-packages/sqlalchemy/pool.py", line 440, in checkout
[Tue Sep 09 13:03:34.818541 2014] [:error] [pid 5246] [client 127.0.0.1:58416]     rec = pool._do_get()
[Tue Sep 09 13:03:34.818549 2014] [:error] [pid 5246] [client 127.0.0.1:58416]   File "/usr/local/lib/python2.7/dist-packages/sqlalchemy/pool.py", line 961, in _do_get
[Tue Sep 09 13:03:34.818560 2014] [:error] [pid 5246] [client 127.0.0.1:58416]     return self._create_connection()
[Tue Sep 09 13:03:34.818567 2014] [:error] [pid 5246] [client 127.0.0.1:58416]   File "/usr/local/lib/python2.7/dist-packages/sqlalchemy/pool.py", line 285, in _create_connection
[Tue Sep 09 13:03:34.818578 2014] [:error] [pid 5246] [client 127.0.0.1:58416]     return _ConnectionRecord(self)
[Tue Sep 09 13:03:34.818585 2014] [:error] [pid 5246] [client 127.0.0.1:58416]   File "/usr/local/lib/python2.7/dist-packages/sqlalchemy/pool.py", line 411, in __init__
[Tue Sep 09 13:03:34.818595 2014] [:error] [pid 5246] [client 127.0.0.1:58416]     self.connection = self.__connect()
[Tue Sep 09 13:03:34.818602 2014] [:error] [pid 5246] [client 127.0.0.1:58416]   File "/usr/local/lib/python2.7/dist-packages/sqlalchemy/pool.py", line 537, in __connect
[Tue Sep 09 13:03:34.818612 2014] [:error] [pid 5246] [client 127.0.0.1:58416]     connection = self.__pool._creator()
[Tue Sep 09 13:03:34.818619 2014] [:error] [pid 5246] [client 127.0.0.1:58416]   File "/usr/local/lib/python2.7/dist-packages/sqlalchemy/engine/strategies.py", line 96, in connect
[Tue Sep 09 13:03:34.818698 2014] [:error] [pid 5246] [client 127.0.0.1:58416]     connection_invalidated=invalidated
[Tue Sep 09 13:03:34.818708 2014] [:error] [pid 5246] [client 127.0.0.1:58416]   File "/usr/local/lib/python2.7/dist-packages/sqlalchemy/util/compat.py", line 199, in raise_from_cause
[Tue Sep 09 13:03:34.818783 2014] [:error] [pid 5246] [client 127.0.0.1:58416]     reraise(type(exception), exception, tb=exc_tb)
[Tue Sep 09 13:03:34.818790 2014] [:error] [pid 5246] [client 127.0.0.1:58416]   File "/usr/local/lib/python2.7/dist-packages/sqlalchemy/engine/strategies.py", line 90, in connect
[Tue Sep 09 13:03:34.818803 2014] [:error] [pid 5246] [client 127.0.0.1:58416]     return dialect.connect(*cargs, **cparams)
[Tue Sep 09 13:03:34.818813 2014] [:error] [pid 5246] [client 127.0.0.1:58416]   File "/usr/local/lib/python2.7/dist-packages/sqlalchemy/engine/default.py", line 377, in connect
[Tue Sep 09 13:03:34.819033 2014] [:error] [pid 5246] [client 127.0.0.1:58416]     return self.dbapi.connect(*cargs, **cparams)
[Tue Sep 09 13:03:34.819043 2014] [:error] [pid 5246] [client 127.0.0.1:58416]   File "/usr/lib/python2.7/dist-packages/MySQLdb/__init__.py", line 81, in Connect
[Tue Sep 09 13:03:34.819096 2014] [:error] [pid 5246] [client 127.0.0.1:58416]     return Connection(*args, **kwargs)
[Tue Sep 09 13:03:34.819104 2014] [:error] [pid 5246] [client 127.0.0.1:58416]   File "/usr/lib/python2.7/dist-packages/MySQLdb/connections.py", line 187, in __init__
[Tue Sep 09 13:03:34.819202 2014] [:error] [pid 5246] [client 127.0.0.1:58416]     super(Connection, self).__init__(*args, **kwargs2)
[Tue Sep 09 13:03:34.819286 2014] [:error] [pid 5246] [client 127.0.0.1:58416] OperationalError: (OperationalError) (1044, "Access denied for user ''@'localhost' to database 'visched_test'") None None
[Tue Sep 09 13:14:49.300425 2014] [:info] [pid 5465] [client 127.0.0.1:58566] mod_wsgi (pid=5465, process='', application='visched.local'): Loading WSGI script '/var/www/visched/app/visched.wsgi'.
[Tue Sep 09 13:14:58.898810 2014] [:info] [pid 5463] [client 127.0.0.1:58567] mod_wsgi (pid=5463, process='', application='visched.local'): Loading WSGI script '/var/www/visched/app/visched.wsgi'., referer: http://visched.local/
[Tue Sep 09 13:15:06.483962 2014] [:info] [pid 5464] [client 127.0.0.1:58572] mod_wsgi (pid=5464, process='', application='visched.local'): Loading WSGI script '/var/www/visched/app/visched.wsgi'.
[Tue Sep 09 13:17:55.706523 2014] [:info] [pid 5459] [client 127.0.0.1:58670] mod_wsgi (pid=5459, process='', application='visched.local'): Loading WSGI script '/var/www/visched/app/visched.wsgi'., referer: http://www.visched.local/
[Tue Sep 09 13:17:56.651344 2014] [:info] [pid 5457] [client 127.0.0.1:58671] mod_wsgi (pid=5457, process='', application='visched.local'): Loading WSGI script '/var/www/visched/app/visched.wsgi'., referer: http://www.visched.local/app
[Tue Sep 09 13:18:01.363201 2014] [:info] [pid 5464] [client 127.0.0.1:58674] mod_wsgi (pid=5464, process='', application='visched.local'): Loading WSGI script '/var/www/visched/app/api.wsgi'., referer: http://www.visched.local/app
[Tue Sep 09 13:18:01.407269 2014] [:info] [pid 5463] [client 127.0.0.1:58673] mod_wsgi (pid=5463, process='', application='visched.local'): Loading WSGI script '/var/www/visched/app/api.wsgi'., referer: http://www.visched.local/app
[Tue Sep 09 13:18:07.128347 2014] [:info] [pid 5466] [client 127.0.0.1:58682] mod_wsgi (pid=5466, process='', application='visched.local'): Loading WSGI script '/var/www/visched/app/api.wsgi'., referer: http://www.visched.local/app2
[Tue Sep 09 13:22:48.310472 2014] [:info] [pid 7171] [client 127.0.0.1:58731] mod_wsgi (pid=7171, process='', application='visched.local'): Loading WSGI script '/var/www/visched/app/visched.wsgi'.
[Tue Sep 09 13:22:49.012063 2014] [:info] [pid 5462] [client 127.0.0.1:58736] mod_wsgi (pid=5462, process='', application='visched.local'): Loading WSGI script '/var/www/visched/app/visched.wsgi'., referer: http://www.visched.local/app2
[Tue Sep 09 13:22:49.057427 2014] [:info] [pid 5460] [client 127.0.0.1:58734] mod_wsgi (pid=5460, process='', application='visched.local'): Loading WSGI script '/var/www/visched/app/visched.wsgi'., referer: http://www.visched.local/app2
[Tue Sep 09 13:22:52.749347 2014] [:info] [pid 5462] [client 127.0.0.1:58736] mod_wsgi (pid=5462, process='', application='visched.local'): Loading WSGI script '/var/www/visched/app/api.wsgi'., referer: http://www.visched.local/app2
[Tue Sep 09 13:22:53.587892 2014] [:info] [pid 5460] [client 127.0.0.1:58734] mod_wsgi (pid=5460, process='', application='visched.local'): Loading WSGI script '/var/www/visched/app/api.wsgi'., referer: http://www.visched.local/app2
[Tue Sep 09 13:23:28.131358 2014] [:info] [pid 5459] [client 127.0.0.1:58744] mod_wsgi (pid=5459, process='', application='visched.local'): Loading WSGI script '/var/www/visched/app/api.wsgi'., referer: http://www.visched.local/app
[Tue Sep 09 13:27:15.529300 2014] [:info] [pid 5465] [client 127.0.0.1:58769] mod_wsgi (pid=5465, process='', application='visched.local'): Loading WSGI script '/var/www/visched/app/api.wsgi'., referer: http://www.visched.local/app2
[Tue Sep 09 13:28:45.363942 2014] [:info] [pid 7701] [client 127.0.0.1:58796] mod_wsgi (pid=7701, process='', application='visched.local'): Loading WSGI script '/var/www/visched/app/visched.wsgi'.
[Tue Sep 09 13:28:46.524605 2014] [:info] [pid 7701] [client 127.0.0.1:58796] mod_wsgi (pid=7701, process='', application='visched.local'): Loading WSGI script '/var/www/visched/app/api.wsgi'., referer: http://www.visched.local/app2
[Tue Sep 09 13:28:47.349616 2014] [:info] [pid 5461] [client 127.0.0.1:58797] mod_wsgi (pid=5461, process='', application='visched.local'): Loading WSGI script '/var/www/visched/app/api.wsgi'., referer: http://www.visched.local/app2
[Tue Sep 09 13:35:26.254369 2014] [:info] [pid 7721] [client 127.0.0.1:59352] mod_wsgi (pid=7721, process='', application='visched.local'): Loading WSGI script '/var/www/visched/app/api.wsgi'., referer: http://www.visched.local/app
[Tue Sep 09 15:20:32.502180 2014] [:info] [pid 5461] [client 127.0.0.1:35197] mod_wsgi (pid=5461, process='', application='visched.local'): Loading WSGI script '/var/www/visched/app/visched.wsgi'., referer: http://www.visched.local/app2
[Tue Sep 09 17:18:34.836706 2014] [:info] [pid 923] [client 127.0.0.1:36518] mod_wsgi (pid=923, process='', application='visched.local'): Loading WSGI script '/var/www/visched/app/visched.wsgi'., referer: http://www.visched.local/app2
[Tue Sep 09 17:19:35.467891 2014] [:info] [pid 5466] [client 127.0.0.1:36528] mod_wsgi (pid=5466, process='', application='visched.local'): Loading WSGI script '/var/www/visched/app/visched.wsgi'., referer: http://www.visched.local/app2
[Tue Sep 09 17:19:35.504580 2014] [:info] [pid 1133] [client 127.0.0.1:36527] mod_wsgi (pid=1133, process='', application='visched.local'): Loading WSGI script '/var/www/visched/app/visched.wsgi'., referer: http://www.visched.local/app2
[Tue Sep 09 17:19:39.051492 2014] [:info] [pid 1133] [client 127.0.0.1:36527] mod_wsgi (pid=1133, process='', application='visched.local'): Loading WSGI script '/var/www/visched/app/api.wsgi'., referer: http://www.visched.local/app2
[Tue Sep 09 17:20:37.095023 2014] [:info] [pid 1283] [client 127.0.0.1:36533] mod_wsgi (pid=1283, process='', application='visched.local'): Loading WSGI script '/var/www/visched/app/visched.wsgi'., referer: http://www.visched.local/app2
[Tue Sep 09 17:20:40.629361 2014] [:info] [pid 1283] [client 127.0.0.1:36533] mod_wsgi (pid=1283, process='', application='visched.local'): Loading WSGI script '/var/www/visched/app/api.wsgi'., referer: http://www.visched.local/app2
[Tue Sep 09 17:26:40.359899 2014] [:info] [pid 1998] [client 127.0.0.1:36553] mod_wsgi (pid=1998, process='', application='visched.local'): Loading WSGI script '/var/www/visched/app/visched.wsgi'., referer: http://www.visched.local/app2
[Tue Sep 09 17:26:40.364521 2014] [:info] [pid 1311] [client 127.0.0.1:36555] mod_wsgi (pid=1311, process='', application='visched.local'): Loading WSGI script '/var/www/visched/app/visched.wsgi'., referer: http://www.visched.local/app2
[Tue Sep 09 17:26:45.170696 2014] [:info] [pid 1998] [client 127.0.0.1:36553] mod_wsgi (pid=1998, process='', application='visched.local'): Loading WSGI script '/var/www/visched/app/api.wsgi'., referer: http://www.visched.local/app2
[Tue Sep 09 17:28:07.350027 2014] [:info] [pid 923] [client 127.0.0.1:36563] mod_wsgi (pid=923, process='', application='visched.local'): Loading WSGI script '/var/www/visched/app/api.wsgi'., referer: http://www.visched.local/app2
[Tue Sep 09 17:29:33.206509 2014] [:info] [pid 2385] [client 127.0.0.1:36577] mod_wsgi (pid=2385, process='', application='visched.local'): Loading WSGI script '/var/www/visched/app/visched.wsgi'., referer: http://www.visched.local/app2
[Tue Sep 09 17:29:33.222424 2014] [:info] [pid 2609] [client 127.0.0.1:36576] mod_wsgi (pid=2609, process='', application='visched.local'): Loading WSGI script '/var/www/visched/app/visched.wsgi'., referer: http://www.visched.local/app2
[Tue Sep 09 17:29:37.431485 2014] [:info] [pid 2385] [client 127.0.0.1:36577] mod_wsgi (pid=2385, process='', application='visched.local'): Loading WSGI script '/var/www/visched/app/api.wsgi'., referer: http://www.visched.local/app2
[Tue Sep 09 17:30:02.809173 2014] [:info] [pid 2772] [client 127.0.0.1:36583] mod_wsgi (pid=2772, process='', application='visched.local'): Loading WSGI script '/var/www/visched/app/visched.wsgi'., referer: http://www.visched.local/app2
[Tue Sep 09 17:30:06.499779 2014] [:info] [pid 1311] [client 127.0.0.1:36585] mod_wsgi (pid=1311, process='', application='visched.local'): Loading WSGI script '/var/www/visched/app/api.wsgi'., referer: http://www.visched.local/app2
[Tue Sep 09 17:32:39.089116 2014] [:info] [pid 2790] [client 127.0.0.1:36599] mod_wsgi (pid=2790, process='', application='visched.local'): Loading WSGI script '/var/www/visched/app/visched.wsgi'., referer: http://www.visched.local/app2
[Tue Sep 09 17:32:39.111156 2014] [:info] [pid 3017] [client 127.0.0.1:36598] mod_wsgi (pid=3017, process='', application='visched.local'): Loading WSGI script '/var/www/visched/app/visched.wsgi'., referer: http://www.visched.local/app2
[Tue Sep 09 17:32:43.182634 2014] [:info] [pid 2790] [client 127.0.0.1:36599] mod_wsgi (pid=2790, process='', application='visched.local'): Loading WSGI script '/var/www/visched/app/api.wsgi'., referer: http://www.visched.local/app2
[Tue Sep 09 17:32:43.967772 2014] [:info] [pid 3017] [client 127.0.0.1:36598] mod_wsgi (pid=3017, process='', application='visched.local'): Loading WSGI script '/var/www/visched/app/api.wsgi'., referer: http://www.visched.local/app2
[Tue Sep 09 17:32:58.362933 2014] [:info] [pid 3031] [client 127.0.0.1:36605] mod_wsgi (pid=3031, process='', application='visched.local'): Loading WSGI script '/var/www/visched/app/visched.wsgi'., referer: http://www.visched.local/app2
[Tue Sep 09 17:33:02.201346 2014] [:info] [pid 2772] [client 127.0.0.1:36606] mod_wsgi (pid=2772, process='', application='visched.local'): Loading WSGI script '/var/www/visched/app/api.wsgi'., referer: http://www.visched.local/app2
[Tue Sep 09 17:33:02.989444 2014] [:info] [pid 3031] [client 127.0.0.1:36605] mod_wsgi (pid=3031, process='', application='visched.local'): Loading WSGI script '/var/www/visched/app/api.wsgi'., referer: http://www.visched.local/app2
[Tue Sep 09 17:33:44.765036 2014] [:info] [pid 3170] [client 127.0.0.1:36649] mod_wsgi (pid=3170, process='', application='visched.local'): Loading WSGI script '/var/www/visched/app/visched.wsgi'., referer: http://www.visched.local/app2
[Tue Sep 09 17:43:06.160950 2014] [:info] [pid 3188] [client 127.0.0.1:36996] mod_wsgi (pid=3188, process='', application='visched.local'): Loading WSGI script '/var/www/visched/app/visched.wsgi'., referer: http://www.visched.local/app2
[Tue Sep 09 17:43:53.223614 2014] [:info] [pid 4425] [client 127.0.0.1:37005] mod_wsgi (pid=4425, process='', application='visched.local'): Loading WSGI script '/var/www/visched/app/visched.wsgi'., referer: http://www.visched.local/app2
[Tue Sep 09 17:43:56.988483 2014] [:info] [pid 3170] [client 127.0.0.1:37002] mod_wsgi (pid=3170, process='', application='visched.local'): Loading WSGI script '/var/www/visched/app/api.wsgi'., referer: http://www.visched.local/app2
[Tue Sep 09 17:43:57.397992 2014] [:info] [pid 4425] [client 127.0.0.1:37005] mod_wsgi (pid=4425, process='', application='visched.local'): Loading WSGI script '/var/www/visched/app/api.wsgi'., referer: http://www.visched.local/app2
[Tue Sep 09 17:46:26.122766 2014] [:info] [pid 4655] [client 127.0.0.1:37020] mod_wsgi (pid=4655, process='', application='visched.local'): Loading WSGI script '/var/www/visched/app/visched.wsgi'., referer: http://www.visched.local/app2
[Tue Sep 09 17:46:26.142506 2014] [:info] [pid 4446] [client 127.0.0.1:37022] mod_wsgi (pid=4446, process='', application='visched.local'): Loading WSGI script '/var/www/visched/app/visched.wsgi'., referer: http://www.visched.local/app2
[Tue Sep 09 17:46:30.997494 2014] [:info] [pid 4655] [client 127.0.0.1:37020] mod_wsgi (pid=4655, process='', application='visched.local'): Loading WSGI script '/var/www/visched/app/api.wsgi'., referer: http://www.visched.local/app2
[Tue Sep 09 17:46:50.445713 2014] [:info] [pid 4813] [client 127.0.0.1:37027] mod_wsgi (pid=4813, process='', application='visched.local'): Loading WSGI script '/var/www/visched/app/visched.wsgi'., referer: http://www.visched.local/app2
[Tue Sep 09 18:01:32.935915 2014] [:info] [pid 4827] [client 127.0.0.1:37064] mod_wsgi (pid=4827, process='', application='visched.local'): Loading WSGI script '/var/www/visched/app/visched.wsgi'., referer: http://www.visched.local/app2
[Tue Sep 09 18:01:36.519623 2014] [:info] [pid 4827] [client 127.0.0.1:37064] mod_wsgi (pid=4827, process='', application='visched.local'): Loading WSGI script '/var/www/visched/app/api.wsgi'., referer: http://www.visched.local/app2
[Tue Sep 09 18:02:35.526590 2014] [:info] [pid 6378] [client 127.0.0.1:37075] mod_wsgi (pid=6378, process='', application='visched.local'): Loading WSGI script '/var/www/visched/app/visched.wsgi'., referer: http://www.visched.local/app2
[Tue Sep 09 18:03:12.969105 2014] [:info] [pid 4813] [client 127.0.0.1:37085] mod_wsgi (pid=4813, process='', application='visched.local'): Loading WSGI script '/var/www/visched/app/api.wsgi'., referer: http://www.visched.local/app2
[Tue Sep 09 18:06:35.528997 2014] [:info] [pid 6411] [client 127.0.0.1:37107] mod_wsgi (pid=6411, process='', application='visched.local'): Loading WSGI script '/var/www/visched/app/visched.wsgi'., referer: http://www.visched.local/app2
[Tue Sep 09 18:06:35.614221 2014] [:info] [pid 6560] [client 127.0.0.1:37106] mod_wsgi (pid=6560, process='', application='visched.local'): Loading WSGI script '/var/www/visched/app/visched.wsgi'., referer: http://www.visched.local/app2
[Tue Sep 09 18:06:39.434034 2014] [:info] [pid 6411] [client 127.0.0.1:37107] mod_wsgi (pid=6411, process='', application='visched.local'): Loading WSGI script '/var/www/visched/app/api.wsgi'., referer: http://www.visched.local/app2
[Tue Sep 09 18:06:40.310892 2014] [:info] [pid 6560] [client 127.0.0.1:37106] mod_wsgi (pid=6560, process='', application='visched.local'): Loading WSGI script '/var/www/visched/app/api.wsgi'., referer: http://www.visched.local/app2
[Tue Sep 09 19:40:43.141135 2014] [:info] [pid 16118] [client 127.0.0.1:38693] mod_wsgi (pid=16118, process='', application='visched.local'): Loading WSGI script '/var/www/visched/app/visched.wsgi'.
[Tue Sep 09 19:40:49.617425 2014] [:info] [pid 16117] [client 127.0.0.1:38696] mod_wsgi (pid=16117, process='', application='visched.local'): Loading WSGI script '/var/www/visched/app/visched.wsgi'.
[Tue Sep 09 19:40:49.919862 2014] [:info] [pid 16119] [client 127.0.0.1:38697] mod_wsgi (pid=16119, process='', application='visched.local'): Loading WSGI script '/var/www/visched/app/visched.wsgi'.
[Tue Sep 09 19:41:05.140657 2014] [:info] [pid 16126] [client 127.0.0.1:38705] mod_wsgi (pid=16126, process='', application='visched.local'): Loading WSGI script '/var/www/visched/app/visched.wsgi'.
[Tue Sep 09 19:43:27.419373 2014] [:info] [pid 16792] [client 127.0.0.1:33945] mod_wsgi (pid=16792, process='', application='visched.local'): Loading WSGI script '/var/www/visched/app/visched.wsgi'.
[Fri Sep 19 12:08:53.600499 2014] [:error] [pid 1118] [client 127.0.0.1:52825] Target WSGI script not found or unable to stat: /var/www/html/scheduler_components/scheduling_components/app
[Fri Sep 19 12:08:53.771002 2014] [:error] [pid 1118] [client 127.0.0.1:52825] Target WSGI script not found or unable to stat: /var/www/html/scheduler_components/scheduling_components/app
[Fri Sep 19 12:08:55.812803 2014] [:error] [pid 1111] [client 127.0.0.1:52827] Target WSGI script not found or unable to stat: /var/www/html/scheduler_components/scheduling_components/app
[Fri Sep 19 12:08:56.971842 2014] [core:info] [pid 1111] [client 127.0.0.1:52827] AH00128: File does not exist: /var/www/html/scheduler_components/scheduling_components/static/img/favicon.ico
[Fri Sep 19 13:57:10.176336 2014] [:error] [pid 1114] [client 127.0.0.1:54976] Target WSGI script not found or unable to stat: /var/www/html/scheduler_components/scheduling_components/app
[Mon Sep 22 21:19:19.647780 2014] [:error] [pid 4351] [client 127.0.0.1:51788] Target WSGI script not found or unable to stat: /var/www/html/scheduler_components/scheduling_components/app
